Workbook

Sheet 本版更新
A1: R2.00 更新重點
A2: 1 | B2: R2.00：核心條件改為四項 —— ① 21EMA 向上（EMA21 高過前一日同 5 日前）② 9EMA 在 21EMA 上方 ③ 一底高於一底（樞軸底遞升、最後一底 ≤30 日前）④ 形態接近上升三角：25 日重心 ≥0.5、低位斜率 >0、高位平至微升。「回到 9/21EMA」唔再係核心門檻，改為分頁條件。
A3: 2 | B3: 三個分頁（都係第一梯隊嘅子集、引用總表）：a 剛黃金交叉（5 日內金叉）15 隻；b 回到 21EMA（離 EMA21 ≤3% 兼 ≤0.75 ATR 或近 3 日觸及）10 隻；c 回到 9EMA（同樣口徑對 EMA9，離兩條都近就歸較近嗰條）76 隻。總表加咗 a／b／c 三欄 ✓。
A4: 3 | B4: 數據更新至 2026-10-01 收市（192 個交易日，2025-12-26 起；Yahoo 日線由 GitHub Actions 抓取）。
A5: 4 | B5: 合資格 2,791 隻 → C1 573 → C2 542 → C3 322 → C4 第一梯隊 100 隻（大型 26／中型 30／小型 43；平頂上升三角 30 隻）。第二梯隊（差一項）99 隻。
A6: 5 | B6: 排名：綜合分數 = 0.25 趨勢 + 0.25 回調質素 + 0.2 底部結構 + 0.3 三角形（每項 0–100，總表全部係公式）。頭五位：JILL（79）、PPIH（77）、MG（74）、HNGE（74）、TTMI（74）。
A7: 6 | B7: 市況：指數企喺高位、闊度極弱；加息周期中段，長債息 24 年新高、油價 $90 樓上 —— 偏防守，只做高 RS 嘅 9/21EMA 回調（市況頁有指數／ETF／商品／債息嘅 EMA 狀態、合資格股票池闊度、四大力量周期對標同領先指標觀察表）。
A8: 7 | B8: 頁：總表（兩個梯隊）、a 剛黃金交叉、b 回到21EMA、c 回到9EMA、大型股／中型股／小型股（引用總表）、差一項、樞軸底頂、篩選規則、市況、數據核對。所有代號連 TradingView；藍字係量度值、黑字係公式。
A9: 8 | B9: 產出：9EMA-Uptrend_Watchlist_R2.00_claudefable51xhigh_10.02_1658.xlsx（claudefable51xhigh = Claude Fable 5.1，effort xhigh；2026-10-02 16:58 香港時間）。

Sheet 總表
A1: 梯隊 | B1: 排名 | C1: 代號 | D1: 公司 | E1: 交易所 | F1: 板塊 | G1: 行業 | H1: 市值(十億美元) | I1: 市值組 | J1: 收市價 | K1: 前收 | L1: 當日% | M1: 當日高 | N1: 當日低 | O1: 成交量 | P1: 20日均量 | Q1: 量比 | R1: EMA9 | S1: EMA21 | T1: EMA21（5日前） | U1: EMA21 5日斜率% | V1: EMA21 10步上升比例 | W1: 距EMA9% | X1: 距EMA21% | Y1: ATR14 | Z1: ATR14% | AA1: 距EMA9（ATR倍） | AB1: 距EMA21（ATR倍） | AC1: 最接近 | AD1: 近3日低位觸及 | AE1: 9/21狀態 | AF1: a 剛金叉 | AG1: b 回到21EMA | AH1: c 回到9EMA | AI1: 金叉日期 | AJ1: 金叉後日數 | AK1: 連續上升底數目 | AL1: 最後一底日期 | AM1: 最後一底價 | AN1: 上一底價 | AO1: 底較底升% | AP1: 最後一底距今（日） | AQ1: 距最後一底% | AR1: 15日最高收市 | AS1: 距15日高% | AT1: 形態（25日） | AU1: 高位斜率（%/日） | AV1: 低位斜率（%/日） | AW1: 重心（VWAP在25日高低區間位置） | AX1: 重心（收市範圍） | AY1: 頂部觸及次數 | AZ1: 25日最高 | BA1: 25日最低 | BB1: 25日VWAP | BC1: 跌日／升日量比（10日） | BD1: 收市在當日區間位置 | BE1: RS21（對全池中位數）% | BF1: 21日回報% | BG1: 趨勢分數 | BH1: 回調質素 | BI1: 底部結構 | BJ1: 三角形分數 | BK1: 綜合分數 | BL1: 唔過嘅條件 | BM1: 備註
A2: 1 | B2: 1 | C2: JILL | D2: J. Jill Inc. | E2: NYSE | F2: 非必需消費 | G2: Apparel | H2: 0.362 | I2: 小型 | J2: 24.4 | K2: 24.37 | L2: =J2/K2-1 | M2: 24.77 | N2: 24.22 | O2: 390800 | P2: 248770 | Q2: =O2/P2 | R2: 24.1815 | S2: 23.1877 | T2: 22.4388 | U2: =S2/T2-1 | V2: 1 | W2: =J2/R2-1 | X2: =J2/S2-1 | Y2: 0.9668 | Z2: =Y2/J2 | AA2: =(J2-R2)/Y2 | AB2: =(J2-S2)/Y2 | AC2: =IF(ABS(AA2)<=ABS(AB2),"9EMA","21EMA") | AD2: 9EMA | AE2: 持續在上方 | AH2: ✓ | AI2: 2026-05-28 | AJ2: 87 | AK2: 6 | AL2: 2026-09-24 | AM2: 22.86 | AN2: 18.49 | AO2: =IF(ISNUMBER(AN2),AM2/AN2-1,"") | AP2: 5 | AQ2: =IF(ISNUMBER(AM2),J2/AM2-1,"") | AR2: 24.63 | AS2: =J2/AR2-1 | AT2: 上傾收窄（楔形） | AU2: 0.998 | AV2: 1.2793 | AW2: 0.7068 | AX2: 0.7182 | AY2: 5 | AZ2: 25 | BA2: 18.49 | BB2: 23.0913 | BC2: 0.8074 | BD2: =IF(M2=N2,0.5,(J2-N2)/(M2-N2)) | BE2: 30.333 | BF2: 25.579 | BG2: =100*(0.4*MIN(1,MAX(0,((U2*100)-(0.0))/((2.5)-(0.0))))+0.3*MIN(1,MAX(0,((V2)-(0.6))/((1.0)-(0.6))))+0.3*MIN(1,MAX(0,((BE2)-(0.0))/((15.0)-(0.0))))) | BH2: =100*(0.4*MIN(1,MAX(0,((MIN(ABS(AA2),ABS(AB2)))-(0.75))/((0.0)-(0.75))))+0.3*MIN(1,MAX(0,((BC2)-(1.2))/((0.6)-(1.2))))+0.3*BD2) | BI2: =100*(0.5*MIN(1,MAX(0,((AK2)-(1.0))/((4.0)-(1.0))))+0.3*MIN(1,MAX(0,((IF(ISNUMBER(AO2),AO2,0)*100)-(0.0))/((8.0)-(0.0))))+0.2*MIN(1,MAX(0,((IF(ISNUMBER(AP2),AP2,0))-(25.0))/((5.0)-(25.0))))) | BJ2: =100*(0.35*MIN(1,MAX(0,((ABS(AU2))-(0.3))/((0.05)-(0.3))))+0.3*MIN(1,MAX(0,((AV2)-(0.0))/((0.3)-(0.0))))+0.25*MIN(1,MAX(0,((AW2)-(0.4))/((0.7)-(0.4))))+0.1*IF(AY2>=2,1,0.5)) | BK2: =0.25*BG2+0.25*BH2+0.2*BI2+0.3*BJ2 | BL2: 全部通過
A3: 1 | B3: 2 | C3: PPIH | D3: Perma-Pipe International Holdings Inc. | E3: NASDAQ | F3: 工業 | G3: Pollution Control Equipment | H3: 0.252 | I3: 小型 | J3: 31.32 | K3: 30.76 | L3: =J3/K3-1 | M3: 32.09 | N3: 30.5 | O3: 119300 | P3: 97670 | Q3: =O3/P3 | R3: 30.9909 | S3: 30.0983 | T3: 29.3367 | U3: =S3/T3-1 | V3: 1 | W3: =J3/R3-1 | X3: =J3/S3-1 | Y3: 1.0388 | Z3: =Y3/J3 | AA3: =(J3-R3)/Y3 | AB3: =(J3-S3)/Y3 | AC3: =IF(ABS(AA3)<=ABS(AB3),"9EMA","21EMA") | AD3: 9EMA | AE3: 持續在上方 | AH3: ✓ | AI3: 2026-08-10 | AJ3: 37 | AK3: 4 | AL3: 2026-09-23 | AM3: 29.77 | AN3: 26.24 | AO3: =IF(ISNUMBER(AN3),AM3/AN3-1,"") | AP3: 6 | AQ3: =IF(ISNUMBER(AM3),J3/AM3-1,"") | AR3: 31.88 | AS3: =J3/AR3-1 | AT3: 上升通道 | AU3: 0.6924 | AV3: 0.663 | AW3: 0.5652 | AX3: 0.5654 | AY3: 4 | AZ3: 32.19 | BA3: 26.24 | BB3: 29.6027 | BC3: 0.6571 | BD3: =IF(M3=N3,0.5,(J3-N3)/(M3-N3)) | BE3: 20.754 | BF3: 16 | BG3: =100*(0.4*MIN(1,MAX(0,((U3*100)-(0.0))/((2.5)-(0.0))))+0.3*MIN(1,MAX(0,((V3)-(0.6))/((1.0)-(0.6))))+0.3*MIN(1,MAX(0,((BE3)-(0.0))/((15.0)-(0.0))))) | BH3: =100*(0.4*MIN(1,MAX(0,((MIN(ABS(AA3),ABS(AB3)))-(0.75))/((0.0)-(0.75))))+0.3*MIN(1,MAX(0,((BC3)-(1.2))/((0.6)-(1.2))))+0.3*BD3) | BI3: =100*(0.5*MIN(1,MAX(0,((AK3)-(1.0))/((4.0)-(1.0))))+0.3*MIN(1,MAX(0,((IF(ISNUMBER(AO3),AO3,0)*100)-(0.0))/((8.0)-(0.0))))+0.2*MIN(1,MAX(0,((IF(ISNUMBER(AP3),AP3,0))-(25.0))/((5.0)-(25.0))))) | BJ3: =100*(0.35*MIN(1,MAX(0,((ABS(AU3))-(0.3))/((0.05)-(0.3))))+0.3*MIN(1,MAX(0,((AV3)-(0.0))/((0.3)-(0.0))))+0.25*MIN(1,MAX(0,((AW3)-(0.4))/((0.7)-(0.4))))+0.1*IF(AY3>=2,1,0.5)) | BK3: =0.25*BG3+0.25*BH3+0.2*BI3+0.3*BJ3 | BL3: 全部通過
A4: 1 | B4: 3 | C4: MG | D4: Mistras Group Inc | E4: NYSE | F4: 非必需消費 | G4: Military/Government/Technical | H4: 0.671 | I4: 小型 | J4: 20.63 | K4: 21.06 | L4: =J4/K4-1 | M4: 21.37 | N4: 20.5 | O4: 483000 | P4: 513160 | Q4: =O4/P4 | R4: 20.9314 | S4: 20.319 | T4: 19.7914 | U4: =S4/T4-1 | V4: 1 | W4: =J4/R4-1 | X4: =J4/S4-1 | Y4: 0.6681 | Z4: =Y4/J4 | AA4: =(J4-R4)/Y4 | AB4: =(J4-S4)/Y4 | AC4: =IF(ABS(AA4)<=ABS(AB4),"9EMA","21EMA") | AD4: 9EMA | AE4: 持續在上方 | AH4: ✓ | AI4: 2026-08-11 | AJ4: 36 | AK4: 4 | AL4: 2026-09-23 | AM4: 20.51 | AN4: 19.15 | AO4: =IF(ISNUMBER(AN4),AM4/AN4-1,"") | AP4: 6 | AQ4: =IF(ISNUMBER(AM4),J4/AM4-1,"") | AR4: 21.59 | AS4: =J4/AR4-1 | AT4: 上升通道 | AU4: 0.6921 | AV4: 0.7005 | AW4: 0.6205 | AX4: 0.6173 | AY4: 4 | AZ4: 21.77 | BA4: 18.17 | BB4: 20.4037 | BC4: 0.5202 | BD4: =IF(M4=N4,0.5,(J4-N4)/(M4-N4)) | BE4: 15.907 | BF4: 11.153 | BG4: =100*(0.4*MIN(1,MAX(0,((U4*100)-(0.0))/((2.5)-(0.0))))+0.3*MIN(1,MAX(0,((V4)-(0.6))/((1.0)-(0.6))))+0.3*MIN(1,MAX(0,((BE4)-(0.0))/((15.0)-(0.0))))) | BH4: =100*(0.4*MIN(1,MAX(0,((MIN(ABS(AA4),ABS(AB4)))-(0.75))/((0.0)-(0.75))))+0.3*MIN(1,MAX(0,((BC4)-(1.2))/((0.6)-(1.2))))+0.3*BD4) | BI4: =100*(0.5*MIN(1,MAX(0,((AK4)-(1.0))/((4.0)-(1.0))))+0.3*MIN(1,MAX(0,((IF(ISNUMBER(AO4),AO4,0)*100)-(0.0))/((8.0)-(0.0))))+0.2*MIN(1,MAX(0,((IF(ISNUMBER(AP4),AP4,0))-(25.0))/((5.0)-(25.0))))) | BJ4: =100*(0.35*MIN(1,MAX(0,((ABS(AU4))-(0.3))/((0.05)-(0.3))))+0.3*MIN(1,MAX(0,((AV4)-(0.0))/((0.3)-(0.0))))+0.25*MIN(1,MAX(0,((AW4)-(0.4))/((0.7)-(0.4))))+0.1*IF(AY4>=2,1,0.5)) | BK4: =0.25*BG4+0.25*BH4+0.2*BI4+0.3*BJ4 | BL4: 全部通過
A5: 1 | B5: 4 | C5: HNGE | D5: Hinge Health Inc. | E5: NYSE | F5: 科技 | G5: EDP Services | H5: 7.847 | I5: 中型 | J5: 97.94 | K5: 97.24 | L5: =J5/K5-1 | M5: 98.46 | N5: 96.325 | O5: 1415700 | P5: 1814210 | Q5: =O5/P5 | R5: 95.0834 | S5: 93.257 | T5: 91.6624 | U5: =S5/T5-1 | V5: 1 | W5: =J5/R5-1 | X5: =J5/S5-1 | Y5: 4.1291 | Z5: =Y5/J5 | AA5: =(J5-R5)/Y5 | AB5: =(J5-S5)/Y5 | AC5: =IF(ABS(AA5)<=ABS(AB5),"9EMA","21EMA") | AD5: 9+21EMA | AE5: 持續在上方 | AI5: 2026-08-07 | AJ5: 38 | AK5: 5 | AL5: 2026-09-23 | AM5: 89.75 | AN5: 86.29 | AO5: =IF(ISNUMBER(AN5),AM5/AN5-1,"") | AP5: 6 | AQ5: =IF(ISNUMBER(AM5),J5/AM5-1,"") | AR5: 97.94 | AS5: =J5/AR5-1 | AT5: 上升三角（平頂） | AU5: 0.0795 | AV5: 0.2553 | AW5: 0.5456 | AX5: 0.5037 | AY5: 3 | AZ5: 98.46 | BA5: 85.75 | BB5: 92.6847 | BC5: 0.721 | BD5: =IF(M5=N5,0.5,(J5-N5)/(M5-N5)) | BE5: 13.552 | BF5: 8.798 | BG5: =100*(0.4*MIN(1,MAX(0,((U5*100)-(0.0))/((2.5)-(0.0))))+0.3*MIN(1,MAX(0,((V5)-(0.6))/((1.0)-(0.6))))+0.3*MIN(1,MAX(0,((BE5)-(0.0))/((15.0)-(0.0))))) | BH5: =100*(0.4*MIN(1,MAX(0,((MIN(ABS(AA5),ABS(AB5)))-(0.75))/((0.0)-(0.75))))+0.3*MIN(1,MAX(0,((BC5)-(1.2))/((0.6)-(1.2))))+0.3*BD5) | BI5: =100*(0.5*MIN(1,MAX(0,((AK5)-(1.0))/((4.0)-(1.0))))+0.3*MIN(1,MAX(0,((IF(ISNUMBER(AO5),AO5,0)*100)-(0.0))/((8.0)-(0.0))))+0.2*MIN(1,MAX(0,((IF(ISNUMBER(AP5),AP5,0))-(25.0))/((5.0)-(25.0))))) | BJ5: =100*(0.35*MIN(1,MAX(0,((ABS(AU5))-(0.3))/((0.05)-(0.3))))+0.3*MIN(1,MAX(0,((AV5)-(0.0))/((0.3)-(0.0))))+0.25*MIN(1,MAX(0,((AW5)-(0.4))/((0.7)-(0.4))))+0.1*IF(AY5>=2,1,0.5)) | BK5: =0.25*BG5+0.25*BH5+0.2*BI5+0.3*BJ5 | BL5: 全部通過
A6: 1 | B6: 5 | C6: TTMI | D6: TTM Technologies Inc. | E6: NASDAQ | F6: 科技 | G6: Electrical Products | H6: 12.941 | I6: 大型 | J6: 126.5 | K6: 122.84 | L6: =J6/K6-1 | M6: 127.31 | N6: 119.77 | O6: 1783400 | P6: 1904120 | Q6: =O6/P6 | R6: 124.182 | S6: 123.1791 | T6: 122.0737 | U6: =S6/T6-1 | V6: 0.7 | W6: =J6/R6-1 | X6: =J6/S6-1 | Y6: 7.73 | Z6: =Y6/J6 | AA6: =(J6-R6)/Y6 | AB6: =(J6-S6)/Y6 | AC6: =IF(ABS(AA6)<=ABS(AB6),"9EMA","21EMA") | AD6: 9+21EMA | AE6: 持續在上方 | AH6: ✓ | AI6: 2026-09-23 | AJ6: 6 | AK6: 5 | AL6: 2026-09-28 | AM6: 119.02 | AN6: 109.94 | AO6: =IF(ISNUMBER(AN6),AM6/AN6-1,"") | AP6: 3 | AQ6: =IF(ISNUMBER(AM6),J6/AM6-1,"") | AR6: 129.17 | AS6: =J6/AR6-1 | AT6: 上升三角（平頂） | AU6: 0.0437 | AV6: 0.4842 | AW6: 0.5077 | AX6: 0.5551 | AY6: 1 | AZ6: 133.77 | BA6: 109.53 | BB6: 121.8359 | BC6: 0.8119 | BD6: =IF(M6=N6,0.5,(J6-N6)/(M6-N6)) | BE6: 14.439 | BF6: 9.685 | BG6: =100*(0.4*MIN(1,MAX(0,((U6*100)-(0.0))/((2.5)-(0.0))))+0.3*MIN(1,MAX(0,((V6)-(0.6))/((1.0)-(0.6))))+0.3*MIN(1,MAX(0,((BE6)-(0.0))/((15.0)-(0.0))))) | BH6: =100*(0.4*MIN(1,MAX(0,((MIN(ABS(AA6),ABS(AB6)))-(0.75))/((0.0)-(0.75))))+0.3*MIN(1,MAX(0,((BC6)-(1.2))/((0.6)-(1.2))))+0.3*BD6) | BI6: =100*(0.5*MIN(1,MAX(0,((AK6)-(1.0))/((4.0)-(1.0))))+0.3*MIN(1,MAX(0,((IF(ISNUMBER(AO6),AO6,0)*100)-(0.0))/((8.0)-(0.0))))+0.2*MIN(1,MAX(0,((IF(ISNUMBER(AP6),AP6,0))-(25.0))/((5.0)-(25.0))))) | BJ6: =100*(0.35*MIN(1,MAX(0,((ABS(AU6))-(0.3))/((0.05)-(0.3))))+0.3*MIN(1,MAX(0,((AV6)-(0.0))/((0.3)-(0.0))))+0.25*MIN(1,MAX(0,((AW6)-(0.4))/((0.7)-(0.4))))+0.1*IF(AY6>=2,1,0.5)) | BK6: =0.25*BG6+0.25*BH6+0.2*BI6+0.3*BJ6 | BL6: 全部通過
A7: 1 | B7: 6 | C7: NVAX | D7: Novavax Inc. | E7: NASDAQ | F7: 醫療保健 | G7: Biotechnology: Biological Products (No Diagnostic Substances) | H7: 1.783 | I7: 小型 | J7: 10.6 | K7: 10.81 | L7: =J7/K7-1 | M7: 10.98 | N7: 10.55 | O7: 3147200 | P7: 5277710 | Q7: =O7/P7 | R7: 10.5668 | S7: 10.1617 | T7: 9.8145 | U7: =S7/T7-1 | V7: 1 | W7: =J7/R7-1 | X7: =J7/S7-1 | Y7: 0.5687 | Z7: =Y7/J7 | AA7: =(J7-R7)/Y7 | AB7: =(J7-S7)/Y7 | AC7: =IF(ABS(AA7)<=ABS(AB7),"9EMA","21EMA") | AD7: 9EMA | AE7: 持續在上方 | AH7: ✓ | AI7: 2026-08-19 | AJ7: 30 | AK7: 5 | AL7: 2026-09-28 | AM7: 10.26 | AN7: 9.11 | AO7: =IF(ISNUMBER(AN7),AM7/AN7-1,"") | AP7: 3 | AQ7: =IF(ISNUMBER(AM7),J7/AM7-1,"") | AR7: 10.83 | AS7: =J7/AR7-1 | AT7: 上傾收窄（楔形） | AU7: 0.2916 | AV7: 0.6666 | AW7: 0.5422 | AX7: 0.5863 | AY7: 6 | AZ7: 11.11 | BA7: 8.89 | BB7: 10.0936 | BC7: 0.7553 | BD7: =IF(M7=N7,0.5,(J7-N7)/(M7-N7)) | BE7: 9.497 | BF7: 4.743 | BG7: =100*(0.4*MIN(1,MAX(0,((U7*100)-(0.0))/((2.5)-(0.0))))+0.3*MIN(1,MAX(0,((V7)-(0.6))/((1.0)-(0.6))))+0.3*MIN(1,MAX(0,((BE7)-(0.0))/((15.0)-(0.0))))) | BH7: =100*(0.4*MIN(1,MAX(0,((MIN(ABS(AA7),ABS(AB7)))-(0.75))/((0.0)-(0.75))))+0.3*MIN(1,MAX(0,((BC7)-(1.2))/((0.6)-(1.2))))+0.3*BD7) | BI7: =100*(0.5*MIN(1,MAX(0,((AK7)-(1.0))/((4.0)-(1.0))))+0.3*MIN(1,MAX(0,((IF(ISNUMBER(AO7),AO7,0)*100)-(0.0))/((8.0)-(0.0))))+0.2*MIN(1,MAX(0,((IF(ISNUMBER(AP7),AP7,0))-(25.0))/((5.0)-(25.0))))) | BJ7: =100*(0.35*MIN(1,MAX(0,((ABS(AU7))-(0.3))/((0.05)-(0.3))))+0.3*MIN(1,MAX(0,((AV7)-(0.0))/((0.3)-(0.0))))+0.25*MIN(1,MAX(0,((AW7)-(0.4))/((0.7)-(0.4))))+0.1*IF(AY7>=2,1,0.5)) | BK7: =0.25*BG7+0.25*BH7+0.2*BI7+0.3*BJ7 | BL7: 全部通過
A8: 1 | B8: 7 | C8: FRNM | D8: Freenome Inc. Common stock | E8: NASDAQ | F8: 醫療保健 | G8: Medical Specialities | H8: 1.692 | I8: 小型 | J8: 15.64 | K8: 15.75 | L8: =J8/K8-1 | M8: 16.4 | N8: 15.6 | O8: 586000 | P8: 861365 | Q8: =O8/P8 | R8: 15.8676 | S8: 15.5117 | T8: 15.2893 | U8: =S8/T8-1 | V8: 1 | W8: =J8/R8-1 | X8: =J8/S8-1 | Y8: 0.8875 | Z8: =Y8/J8 | AA8: =(J8-R8)/Y8 | AB8: =(J8-S8)/Y8 | AC8: =IF(ABS(AA8)<=ABS(AB8),"9EMA","21EMA") | AD8: 9+21EMA | AE8: 持續在上方 | AG8: ✓ | AI8: 2026-08-11 | AJ8: 36 | AK8: 4 | AL8: 2026-09-24 | AM8: 15.28 | AN8: 14.25 | AO8: =IF(ISNUMBER(AN8),AM8/AN8-1,"") | AP8: 5 | AQ8: =IF(ISNUMBER(AM8),J8/AM8-1,"") | AR8: 17.11 | AS8: =J8/AR8-1 | AT8: 上傾收窄（楔形） | AU8: 0.2078 | AV8: 0.8232 | AW8: 0.588 | AX8: 0.637 | AY8: 2 | AZ8: 17.5 | BA8: 13.76 | BB8: 15.9592 | BC8: 0.237 | BD8: =IF(M8=N8,0.5,(J8-N8)/(M8-N8)) | BE8: 7.312 | BF8: 2.557 | BG8: =100*(0.4*MIN(1,MAX(0,((U8*100)-(0.0))/((2.5)-(0.0))))+0.3*MIN(1,MAX(0,((V8)-(0.6))/((1.0)-(0.6))))+0.3*MIN(1,MAX(0,((BE8)-(0.0))/((15.0)-(0.0))))) | BH8: =100*(0.4*MIN(1,MAX(0,((MIN(ABS(AA8),ABS(AB8)))-(0.75))/((0.0)-(0.75))))+0.3*MIN(1,MAX(0,((BC8)-(1.2))/((0.6)-(1.2))))+0.3*BD8) | BI8: =100*(0.5*MIN(1,MAX(0,((AK8)-(1.0))/((4.0)-(1.0))))+0.3*MIN(1,MAX(0,((IF(ISNUMBER(AO8),AO8,0)*100)-(0.0))/((8.0)-(0.0))))+0.2*MIN(1,MAX(0,((IF(ISNUMBER(AP8),AP8,0))-(25.0))/((5.0)-(25.0))))) | BJ8: =100*(0.35*MIN(1,MAX(0,((ABS(AU8))-(0.3))/((0.05)-(0.3))))+0.3*MIN(1,MAX(0,((AV8)-(0.0))/((0.3)-(0.0))))+0.25*MIN(1,MAX(0,((AW8)-(0.4))/((0.7)-(0.4))))+0.1*IF(AY8>=2,1,0.5)) | BK8: =0.25*BG8+0.25*BH8+0.2*BI8+0.3*BJ8 | BL8: 全部通過
A9: 1 | B9: 8 | C9: NET | D9: Cloudflare Inc. | E9: NYSE | F9: 科技 | G9: Computer Software: Prepackaged Software | H9: 123.659 | I9: 大型 | J9: 351 | K9: 347.28 | L9: =J9/K9-1 | M9: 353.84 | N9: 342.11 | O9: 2774300 | P9: 3118820 | Q9: =O9/P9 | R9: 346.9575 | S9: 332.7633 | T9: 321.8414 | U9: =S9/T9-1 | V9: 1 | W9: =J9/R9-1 | X9: =J9/S9-1 | Y9: 16.4744 | Z9: =Y9/J9 | AA9: =(J9-R9)/Y9 | AB9: =(J9-S9)/Y9 | AC9: =IF(ABS(AA9)<=ABS(AB9),"9EMA","21EMA") | AD9: 9EMA | AE9: 持續在上方 | AH9: ✓ | AI9: 2026-09-09 | AJ9: 16 | AK9: 3 | AL9: 2026-09-28 | AM9: 338.67 | AN9: 313.5 | AO9: =IF(ISNUMBER(AN9),AM9/AN9-1,"") | AP9: 3 | AQ9: =IF(ISNUMBER(AM9),J9/AM9-1,"") | AR9: 358.82 | AS9: =J9/AR9-1 | AT9: 上傾收窄（楔形） | AU9: 0.8682 | AV9: 1.1604 | AW9: 0.5481 | AX9: 0.5848 | AY9: 3 | AZ9: 367.43 | BA9: 269.3 | BB9: 323.0821 | BC9: 0.9639 | BD9: =IF(M9=N9,0.5,(J9-N9)/(M9-N9)) | BE9: 27.692 | BF9: 22.938 | BG9: =100*(0.4*MIN(1,MAX(0,((U9*100)-(0.0))/((2.5)-(0.0))))+0.3*MIN(1,MAX(0,((V9)-(0.6))/((1.0)-(0.6))))+0.3*MIN(1,MAX(0,((BE9)-(0.0))/((15.0)-(0.0))))) | BH9: =100*(0.4*MIN(1,MAX(0,((MIN(ABS(AA9),ABS(AB9)))-(0.75))/((0.0)-(0.75))))+0.3*MIN(1,MAX(0,((BC9)-(1.2))/((0.6)-(1.2))))+0.3*BD9) | BI9: =100*(0.5*MIN(1,MAX(0,((AK9)-(1.0))/((4.0)-(1.0))))+0.3*MIN(1,MAX(0,((IF(ISNUMBER(AO9),AO9,0)*100)-(0.0))/((8.0)-(0.0))))+0.2*MIN(1,MAX(0,((IF(ISNUMBER(AP9),AP9,0))-(25.0))/((5.0)-(25.0))))) | BJ9: =100*(0.35*MIN(1,MAX(0,((ABS(AU9))-(0.3))/((0.05)-(0.3))))+0.3*MIN(1,MAX(0,((AV9)-(0.0))/((0.3)-(0.0))))+0.25*MIN(1,MAX(0,((AW9)-(0.4))/((0.7)-(0.4))))+0.1*IF(AY9>=2,1,0.5)) | BK9: =0.25*BG9+0.25*BH9+0.2*BI9+0.3*BJ9 | BL9: 全部通過
A10: 1 | B10: 9 | C10: MTSI | D10: MACOM Technology Solutions Holdings Inc. | E10: NASDAQ | F10: 科技 | G10: Semiconductors | H10: 21.752 | I10: 大型 | J10: 301.63 | K10: 284.82 | L10: =J10/K10-1 | M10: 304.29 | N10: 283.59 | O10: 1174700 | P10: 1335305 | Q10: =O10/P10 | R10: 283.7348 | S10: 277.7225 | T10: 271.6084 | U10: =S10/T10-1 | V10: 1 | W10: =J10/R10-1 | X10: =J10/S10-1 | Y10: 14.0183 | Z10: =Y10/J10 | AA10: =(J10-R10)/Y10 | AB10: =(J10-S10)/Y10 | AC10: =IF(ABS(AA10)<=ABS(AB10),"9EMA","21EMA") | AD10: 9EMA | AE10: 持續在上方 | AI10: 2026-09-23 | AJ10: 6 | AK10: 2 | AL10: 2026-09-24 | AM10: 266.42 | AN10: 235.63 | AO10: =IF(ISNUMBER(AN10),AM10/AN10-1,"") | AP10: 5 | AQ10: =IF(ISNUMBER(AM10),J10/AM10-1,"") | AR10: 301.63 | AS10: =J10/AR10-1 | AT10: 上升三角（平頂） | AU10: 0.0303 | AV10: 0.5106 | AW10: 0.5158 | AX10: 0.5068 | AY10: 1 | AZ10: 304.29 | BA10: 235.63 | BB10: 271.0477 | BC10: 0.8119 | BD10: =IF(M10=N10,0.5,(J10-N10)/(M10-N10)) | BE10: 19.876 | BF10: 15.122 | BG10: =100*(0.4*MIN(1,MAX(0,((U10*100)-(0.0))/((2.5)-(0.0))))+0.3*MIN(1,MAX(0,((V10)-(0.6))/((1.0)-(0.6))))+0.3*MIN(1,MAX(0,((BE10)-(0.0))/((15.0)-(0.0))))) | BH10: =100*(0.4*MIN(1,MAX(0,((MIN(ABS(AA10),ABS(AB10)))-(0.75))/((0.0)-(0.75))))+0.3*MIN(1,MAX(0,((BC10)-(1.2))/((0.6)-(1.2))))+0.3*BD10) | BI10: =100*(0.5*MIN(1,MAX(0,((AK10)-(1.0))/((4.0)-(1.0))))+0.3*MIN(1,MAX(0,((IF(ISNUMBER(AO10),AO10,0)*100)-(0.0))/((8.0)-(0.0))))+0.2*MIN(1,MAX(0,((IF(ISNUMBER(AP10),AP10,0))-(25.0))/((5.0)-(25.0))))) | BJ10: =100*(0.35*MIN(1,MAX(0,((ABS(AU10))-(0.3))/((0.05)-(0.3))))+0.3*MIN(1,MAX(0,((AV10)-(0.0))/((0.3)-(0.0))))+0.25*MIN(1,MAX(0,((AW10)-(0.4))/((0.7)-(0.4))))+0.1*IF(AY10>=2,1,0.5)) | BK10: =0.25*BG10+0.25*BH10+0.2*BI10+0.3*BJ10 | BL10: 全部通過
A11: 1 | B11: 10 | C11: ACVA | D11: ACV Auctions Inc. | E11: NYSE | F11: 非必需消費 | G11: Business Services | H11: 1.771 | I11: 小型 | J11: 10.45 | K11: 10.43 | L11: =J11/K11-1 | M11: 10.47 | N11: 10.44 | O11: 6423300 | P11: 15693280 | Q11: =O11/P11 | R11: 10.3306 | S11: 9.6783 | T11: 9.2089 | U11: =S11/T11-1 | V11: 1 | W11: =J11/R11-1 | X11: =J11/S11-1 | Y11: 0.2471 | Z11: =Y11/J11 | AA11: =(J11-R11)/Y11 | AB11: =(J11-S11)/Y11 | AC11: =IF(ABS(AA11)<=ABS(AB11),"9EMA","21EMA") | AD11: — | AE11: 持續在上方 | AH11: ✓ | AI11: 2026-09-11 | AJ11: 14 | AK11: 2 | AL11: 2026-09-23 | AM11: 10.41 | AN11: 6.6 | AO11: =IF(ISNUMBER(AN11),AM11/AN11-1,"") | AP11: 6 | AQ11: =IF(ISNUMBER(AM11),J11/AM11-1,"") | AR11: 10.48 | AS11: =J11/AR11-1 | AT11: 上升三角（平頂） | AU11: 0.0957 | AV11: 3.0383 | AW11: 0.8595 | AX11: 0.8604 | AY11: 15 | AZ11: 10.5 | BA11: 6.6 | BB11: 9.9522 | BC11: 2.1707 | BD11: =IF(M11=N11,0.5,(J11-N11)/(M11-N11)) | BE11: 59.34 | BF11: 54.586 | BG11: =100*(0.4*MIN(1,MAX(0,((U11*100)-(0.0))/((2.5)-(0.0))))+0.3*MIN(1,MAX(0,((V11)-(0.6))/((1.0)-(0.6))))+0.3*MIN(1,MAX(0,((BE11)-(0.0))/((15.0)-(0.0))))) | BH11: =100*(0.4*MIN(1,MAX(0,((MIN(ABS(AA11),ABS(AB11)))-(0.75))/((0.0)-(0.75))))+0.3*MIN(1,MAX(0,((BC11)-(1.2))/((0.6)-(1.2))))+0.3*BD11) | BI11: =100*(0.5*MIN(1,MAX(0,((AK11)-(1.0))/((4.0)-(1.0))))+0.3*MIN(1,MAX(0,((IF(ISNUMBER(AO11),AO11,0)*100)-(0.0))/((8.0)-(0.0))))+0.2*MIN(1,MAX(0,((IF(ISNUMBER(AP11),AP11,0))-(25.0))/((5.0)-(25.0))))) | BJ11: =100*(0.35*MIN(1,MAX(0,((ABS(AU11))-(0.3))/((0.05)-(0.3))))+0.3*MIN(1,MAX(0,((AV11)-(0.0))/((0.3)-(0.0))))+0.25*MIN(1,MAX(0,((AW11)-(0.4))/((0.7)-(0.4))))+0.1*IF(AY11>=2,1,0.5)) | BK11: =0.25*BG11+0.25*BH11+0.2*BI11+0.3*BJ11 | BL11: 全部通過
A12: 1 | B12: 11 | C12: LTC | D12: LTC Properties Inc. | E12: NYSE | F12: 房地產 | G12: Real Estate Investment Trusts | H12: 2.311 | I12: 中型 | J12: 42.67 | K12: 42.87 | L12: =J12/K12-1 | M12: 42.81 | N12: 42.08 | O12: 633200 | P12: 654050 | Q12: =O12/P12 | R12: 42.8522 | S12: 42.4586 | T12: 42.1776 | U12: =S12/T12-1 | V12: 1 | W12: =J12/R12-1 | X12: =J12/S12-1 | Y12: 0.8352 | Z12: =Y12/J12 | AA12: =(J12-R12)/Y12 | AB12: =(J12-S12)/Y12 | AC12: =IF(ABS(AA12)<=ABS(AB12),"9EMA","21EMA") | AD12: 9+21EMA | AE12: 持續在上方 | AH12: ✓ | AI12: 2026-08-20 | AJ12: 29 | AK12: 5 | AL12: 2026-09-21 | AM12: 42.06 | AN12: 40.82 | AO12: =IF(ISNUMBER(AN12),AM12/AN12-1,"") | AP12: 8 | AQ12: =IF(ISNUMBER(AM12),J12/AM12-1,"") | AR12: 43.5 | AS12: =J12/AR12-1 | AT12: 上升三角（平頂） | AU12: -0.0146 | AV12: 0.3172 | AW12: 0.6696 | AX12: 0.6751 | AY12: 12 | AZ12: 43.6 | BA12: 40.17 | BB12: 42.4667 | BC12: 1.2972 | BD12: =IF(M12=N12,0.5,(J12-N12)/(M12-N12)) | BE12: 7.822 | BF12: 3.068 | BG12: =100*(0.4*MIN(1,MAX(0,((U12*100)-(0.0))/((2.5)-(0.0))))+0.3*MIN(1,MAX(0,((V12)-(0.6))/((1.0)-(0.6))))+0.3*MIN(1,MAX(0,((BE12)-(0.0))/((15.0)-(0.0))))) | BH12: =100*(0.4*MIN(1,MAX(0,((MIN(ABS(AA12),ABS(AB12)))-(0.75))/((0.0)-(0.75))))+0.3*MIN(1,MAX(0,((BC12)-(1.2))/((0.6)-(1.2))))+0.3*BD12) | BI12: =100*(0.5*MIN(1,MAX(0,((AK12)-(1.0))/((4.0)-(1.0))))+0.3*MIN(1,MAX(0,((IF(ISNUMBER(AO12),AO12,0)*100)-(0.0))/((8.0)-(0.0))))+0.2*MIN(1,MAX(0,((IF(ISNUMBER(AP12),AP12,0))-(25.0))/((5.0)-(25.0))))) | BJ12: =100*(0.35*MIN(1,MAX(0,((ABS(AU12))-(0.3))/((0.05)-(0.3))))+0.3*MIN(1,MAX(0,((AV12)-(0.0))/((0.3)-(0.0))))+0.25*MIN(1,MAX(0,((AW12)-(0.4))/((0.7)-(0.4))))+0.1*IF(AY12>=2,1,0.5)) | BK12: =0.25*BG12+0.25*BH12+0.2*BI12+0.3*BJ12 | BL12: 全部通過
A13: 1 | B13: 12 | C13: PANW | D13: Palo Alto Networks Inc. | E13: NASDAQ | F13: 科技 | G13: Computer peripheral equipment | H13: 325 | I13: 大型 | J13: 396.25 | K13: 397.31 | L13: =J13/K13-1 | M13: 398.58 | N13: 387.02 | O13: 5309000 | P13: 6369485 | Q13: =O13/P13 | R13: 386.2583 | S13: 374.9784 | T13: 365.4081 | U13: =S13/T13-1 | V13: 1 | W13: =J13/R13-1 | X13: =J13/S13-1 | Y13: 17.56 | Z13: =Y13/J13 | AA13: =(J13-R13)/Y13 | AB13: =(J13-S13)/Y13 | AC13: =IF(ABS(AA13)<=ABS(AB13),"9EMA","21EMA") | AD13: 9EMA | AE13: 持續在上方 | AH13: ✓ | AI13: 2026-09-15 | AJ13: 12 | AK13: 3 | AL13: 2026-09-28 | AM13: 367.27 | AN13: 356 | AO13: =IF(ISNUMBER(AN13),AM13/AN13-1,"") | AP13: 3 | AQ13: =IF(ISNUMBER(AM13),J13/AM13-1,"") | AR13: 397.31 | AS13: =J13/AR13-1 | AT13: 上升三角（平頂） | AU13: 0.0769 | AV13: 0.695 | AW13: 0.5354 | AX13: 0.545 | AY13: 1 | AZ13: 404.69 | BA13: 321.39 | BB13: 365.992 | BC13: 1.0372 | BD13: =IF(M13=N13,0.5,(J13-N13)/(M13-N13)) | BE13: 14.188 | BF13: 9.434 | BG13: =100*(0.4*MIN(1,MAX(0,((U13*100)-(0.0))/((2.5)-(0.0))))+0.3*MIN(1,MAX(0,((V13)-(0.6))/((1.0)-(0.6))))+0.3*MIN(1,MAX(0,((BE13)-(0.0))/((15.0)-(0.0))))) | BH13: =100*(0.4*MIN(1,MAX(0,((MIN(ABS(AA13),ABS(AB13)))-(0.75))/((0.0)-(0.75))))+0.3*MIN(1,MAX(0,((BC13)-(1.2))/((0.6)-(1.2))))+0.3*BD13) | BI13: =100*(0.5*MIN(1,MAX(0,((AK13)-(1.0))/((4.0)-(1.0))))+0.3*MIN(1,MAX(0,((IF(ISNUMBER(AO13),AO13,0)*100)-(0.0))/((8.0)-(0.0))))+0.2*MIN(1,MAX(0,((IF(ISNUMBER(AP13),AP13,0))-(25.0))/((5.0)-(25.0))))) | BJ13: =100*(0.35*MIN(1,MAX(0,((ABS(AU13))-(0.3))/((0.05)-(0.3))))+0.3*MIN(1,MAX(0,((AV13)-(0.0))/((0.3)-(0.0))))+0.25*MIN(1,MAX(0,((AW13)-(0.4))/((0.7)-(0.4))))+0.1*IF(AY13>=2,1,0.5)) | BK13: =0.25*BG13+0.25*BH13+0.2*BI13+0.3*BJ13 | BL13: 全部通過
A14: 1 | B14: 13 | C14: PENG | D14: Penguin Solutions Inc. | E14: NASDAQ | F14: 科技 | G14: Semiconductors | H14: 2.802 | I14: 中型 | J14: 54.98 | K14: 54.69 | L14: =J14/K14-1 | M14: 55.67 | N14: 53.44 | O14: 1157400 | P14: 1358460 | Q14: =O14/P14 | R14: 54.4126 | S14: 53.4053 | T14: 52.2605 | U14: =S14/T14-1 | V14: 1 | W14: =J14/R14-1 | X14: =J14/S14-1 | Y14: 3.0785 | Z14: =Y14/J14 | AA14: =(J14-R14)/Y14 | AB14: =(J14-S14)/Y14 | AC14: =IF(ABS(AA14)<=ABS(AB14),"9EMA","21EMA") | AD14: 9+21EMA | AE14: 持續在上方 | AH14: ✓ | AI14: 2026-09-22 | AJ14: 7 | AK14: 3 | AL14: 2026-09-24 | AM14: 51.31 | AN14: 46.19 | AO14: =IF(ISNUMBER(AN14),AM14/AN14-1,"") | AP14: 5 | AQ14: =IF(ISNUMBER(AM14),J14/AM14-1,"") | AR14: 56.58 | AS14: =J14/AR14-1 | AT14: 上傾收窄（楔形） | AU14: 0.3647 | AV14: 0.7392 | AW14: 0.514 | AX14: 0.5141 | AY14: 3 | AZ14: 57.5 | BA14: 45.62 | BB14: 51.7262 | BC14: 0.9476 | BD14: =IF(M14=N14,0.5,(J14-N14)/(M14-N14)) | BE14: 20.283 | BF14: 15.528 | BG14: =100*(0.4*MIN(1,MAX(0,((U14*100)-(0.0))/((2.5)-(0.0))))+0.3*MIN(1,MAX(0,((V14)-(0.6))/((1.0)-(0.6))))+0.3*MIN(1,MAX(0,((BE14)-(0.0))/((15.0)-(0.0))))) | BH14: =100*(0.4*MIN(1,MAX(0,((MIN(ABS(AA14),ABS(AB14)))-(0.75))/((0.0)-(0.75))))+0.3*MIN(1,MAX(0,((BC14)-(1.2))/((0.6)-(1.2))))+0.3*BD14) | BI14: =100*(0.5*MIN(1,MAX(0,((AK14)-(1.0))/((4.0)-(1.0))))+0.3*MIN(1,MAX(0,((IF(ISNUMBER(AO14),AO14,0)*100)-(0.0))/((8.0)-(0.0))))+0.2*MIN(1,MAX(0,((IF(ISNUMBER(AP14),AP14,0))-(25.0))/((5.0)-(25.0))))) | BJ14: =100*(0.35*MIN(1,MAX(0,((ABS(AU14))-(0.3))/((0.05)-(0.3))))+0.3*MIN(1,MAX(0,((AV14)-(0.0))/((0.3)-(0.0))))+0.25*MIN(1,MAX(0,((AW14)-(0.4))/((0.7)-(0.4))))+0.1*IF(AY14>=2,1,0.5)) | BK14: =0.25*BG14+0.25*BH14+0.2*BI14+0.3*BJ14 | BL14: 全部通過
A15: 1 | B15: 14 | C15: DT | D15: Dynatrace Inc. | E15: NYSE | F15: 科技 | G15: Computer Software: Prepackaged Software | H15: 16.687 | I15: 大型 | J15: 59.26 | K15: 57.74 | L15: =J15/K15-1 | M15: 59.42 | N15: 58.26 | O15: 5248200 | P15: 6901235 | Q15: =O15/P15 | R15: 57.5596 | S15: 55.5806 | T15: 54.0331 | U15: =S15/T15-1 | V15: 1 | W15: =J15/R15-1 | X15: =J15/S15-1 | Y15: 1.7535 | Z15: =Y15/J15 | AA15: =(J15-R15)/Y15 | AB15: =(J15-S15)/Y15 | AC15: =IF(ABS(AA15)<=ABS(AB15),"9EMA","21EMA") | AD15: 9EMA | AE15: 持續在上方 | AH15: ✓ | AI15: 2026-07-29 | AJ15: 45 | AK15: 4 | AL15: 2026-09-28 | AM15: 55.644 | AN15: 49.56 | AO15: =IF(ISNUMBER(AN15),AM15/AN15-1,"") | AP15: 3 | AQ15: =IF(ISNUMBER(AM15),J15/AM15-1,"") | AR15: 59.26 | AS15: =J15/AR15-1 | AT15: 上傾收窄（楔形） | AU15: 0.4541 | AV15: 0.7897 | AW15: 0.5627 | AX15: 0.5372 | AY15: 5 | AZ15: 59.42 | BA15: 49.56 | BB15: 55.1085 | BC15: 0.9148 | BD15: =IF(M15=N15,0.5,(J15-N15)/(M15-N15)) | BE15: 16.862 | BF15: 12.107 | BG15: =100*(0.4*MIN(1,MAX(0,((U15*100)-(0.0))/((2.5)-(0.0))))+0.3*MIN(1,MAX(0,((V15)-(0.6))/((1.0)-(0.6))))+0.3*MIN(1,MAX(0,((BE15)-(0.0))/((15.0)-(0.0))))) | BH15: =100*(0.4*MIN(1,MAX(0,((MIN(ABS(AA15),ABS(AB15)))-(0.75))/((0.0)-(0.75))))+0.3*MIN(1,MAX(0,((BC15)-(1.2))/((0.6)-(1.2))))+0.3*BD15) | BI15: =100*(0.5*MIN(1,MAX(0,((AK15)-(1.0))/((4.0)-(1.0))))+0.3*MIN(1,MAX(0,((IF(ISNUMBER(AO15),AO15,0)*100)-(0.0))/((8.0)-(0.0))))+0.2*MIN(1,MAX(0,((IF(ISNUMBER(AP15),AP15,0))-(25.0))/((5.0)-(25.0))))) | BJ15: =100*(0.35*MIN(1,MAX(0,((ABS(AU15))-(0.3))/((0.05)-(0.3))))+0.3*MIN(1,MAX(0,((AV15)-(0.0))/((0.3)-(0.0))))+0.25*MIN(1,MAX(0,((AW15)-(0.4))/((0.7)-(0.4))))+0.1*IF(AY15>=2,1,0.5)) | BK15: =0.25*BG15+0.25*BH15+0.2*BI15+0.3*BJ15 | BL15: 全部通過
A16: 1 | B16: 15 | C16: NUTX | D16: Nutex Health Inc. | E16: NASDAQ | F16: 非必需消費 | G16: Business Services | H16: 1.449 | I16: 小型 | J16: 212.31 | K16: 211.66 | L16: =J16/K16-1 | M16: 219.94 | N16: 210.195 | O16: 122500 | P16: 155030 | Q16: =O16/P16 | R16: 210.3854 | S16: 205.1014 | T16: 200.2276 | U16: =S16/T16-1 | V16: 1 | W16: =J16/R16-1 | X16: =J16/S16-1 | Y16: 10.5554 | Z16: =Y16/J16 | AA16: =(J16-R16)/Y16 | AB16: =(J16-S16)/Y16 | AC16: =IF(ABS(AA16)<=ABS(AB16),"9EMA","21EMA") | AD16: 9EMA | AE16: 持續在上方 | AH16: ✓ | AI16: 2026-08-10 | AJ16: 37 | AK16: 5 | AL16: 2026-09-24 | AM16: 198.25 | AN16: 184 | AO16: =IF(ISNUMBER(AN16),AM16/AN16-1,"") | AP16: 5 | AQ16: =IF(ISNUMBER(AM16),J16/AM16-1,"") | AR16: 220.11 | AS16: =J16/AR16-1 | AT16: 上傾擴張 | AU16: 0.6755 | AV16: 0.4838 | AW16: 0.5032 | AX16: 0.4963 | AY16: 4 | AZ16: 224.28 | BA16: 182.66 | BB16: 203.6045 | BC16: 1.0121 | BD16: =IF(M16=N16,0.5,(J16-N16)/(M16-N16)) | BE16: 18.083 | BF16: 13.329 | BG16: =100*(0.4*MIN(1,MAX(0,((U16*100)-(0.0))/((2.5)-(0.0))))+0.3*MIN(1,MAX(0,((V16)-(0.6))/((1.0)-(0.6))))+0.3*MIN(1,MAX(0,((BE16)-(0.0))/((15.0)-(0.0))))) | BH16: =100*(0.4*MIN(1,MAX(0,((MIN(ABS(AA16),ABS(AB16)))-(0.75))/((0.0)-(0.75))))+0.3*MIN(1,MAX(0,((BC16)-(1.2))/((0.6)-(1.2))))+0.3*BD16) | BI16: =100*(0.5*MIN(1,MAX(0,((AK16)-(1.0))/((4.0)-(1.0))))+0.3*MIN(1,MAX(0,((IF(ISNUMBER(AO16),AO16,0)*100)-(0.0))/((8.0)-(0.0))))+0.2*MIN(1,MAX(0,((IF(ISNUMBER(AP16),AP16,0))-(25.0))/((5.0)-(25.0))))) | BJ16: =100*(0.35*MIN(1,MAX(0,((ABS(AU16))-(0.3))/((0.05)-(0.3))))+0.3*MIN(1,MAX(0,((AV16)-(0.0))/((0.3)-(0.0))))+0.25*MIN(1,MAX(0,((AW16)-(0.4))/((0.7)-(0.4))))+0.1*IF(AY16>=2,1,0.5)) | BK16: =0.25*BG16+0.25*BH16+0.2*BI16+0.3*BJ16 | BL16: 全部通過
A17: 1 | B17: 16 | C17: DDD | D17: 3D Systems Corporation | E17: NYSE | F17: 科技 | G17: Computer Software: Prepackaged Software | H17: 0.598 | I17: 小型 | J17: 3.54 | K17: 3.6 | L17: =J17/K17-1 | M17: 3.57 | N17: 3.44 | O17: 2659000 | P17: 2217730 | Q17: =O17/P17 | R17: 3.5163 | S17: 3.449 | T17: 3.3871 | U17: =S17/T17-1 | V17: 1 | W17: =J17/R17-1 | X17: =J17/S17-1 | Y17: 0.2003 | Z17: =Y17/J17 | AA17: =(J17-R17)/Y17 | AB17: =(J17-S17)/Y17 | AC17: =IF(ABS(AA17)<=ABS(AB17),"9EMA","21EMA") | AD17: 9+21EMA | AE17: 持續在上方 | AH17: ✓ | AI17: 2026-09-17 | AJ17: 10 | AK17: 2 | AL17: 2026-09-25 | AM17: 3.35 | AN17: 3.1 | AO17: =IF(ISNUMBER(AN17),AM17/AN17-1,"") | AP17: 4 | AQ17: =IF(ISNUMBER(AM17),J17/AM17-1,"") | AR17: 3.63 | AS17: =J17/AR17-1 | AT17: 上傾收窄（楔形） | AU17: 0.3329 | AV17: 1.0089 | AW17: 0.5249 | AX17: 0.6039 | AY17: 3 | AZ17: 3.74 | BA17: 3.1 | BB17: 3.4359 | BC17: 0.6653 | BD17: =IF(M17=N17,0.5,(J17-N17)/(M17-N17)) | BE17: 12.353 | BF17: 7.599 | BG17: =100*(0.4*MIN(1,MAX(0,((U17*100)-(0.0))/((2.5)-(0.0))))+0.3*MIN(1,MAX(0,((V17)-(0.6))/((1.0)-(0.6))))+0.3*MIN(1,MAX(0,((BE17)-(0.0))/((15.0)-(0.0))))) | BH17: =100*(0.4*MIN(1,MAX(0,((MIN(ABS(AA17),ABS(AB17)))-(0.75))/((0.0)-(0.75))))+0.3*MIN(1,MAX(0,((BC17)-(1.2))/((0.6)-(1.2))))+0.3*BD17) | BI17: =100*(0.5*MIN(1,MAX(0,((AK17)-(1.0))/((4.0)-(1.0))))+0.3*MIN(1,MAX(0,((IF(ISNUMBER(AO17),AO17,0)*100)-(0.0))/((8.0)-(0.0))))+0.2*MIN(1,MAX(0,((IF(ISNUMBER(AP17),AP17,0))-(25.0))/((5.0)-(25.0))))) | BJ17: =100*(0.35*MIN(1,MAX(0,((ABS(AU17))-(0.3))/((0.05)-(0.3))))+0.3*MIN(1,MAX(0,((AV17)-(0.0))/((0.3)-(0.0))))+0.25*MIN(1,MAX(0,((AW17)-(0.4))/((0.7)-(0.4))))+0.1*IF(AY17>=2,1,0.5)) | BK17: =0.25*BG17+0.25*BH17+0.2*BI17+0.3*BJ17 | BL17: 全部通過
A18: 1 | B18: 17 | C18: MTW | D18: Manitowoc Company Inc. (The) | E18: NYSE | F18: 工業 | G18: Construction/Ag Equipment/Trucks | H18: 0.774 | I18: 小型 | J18: 22.4 | K18: 21.46 | L18: =J18/K18-1 | M18: 22.7 | N18: 21.14 | O18: 551400 | P18: 498695 | Q18: =O18/P18 | R18: 21.9569 | S18: 21.3218 | T18: 20.8739 | U18: =S18/T18-1 | V18: 1 | W18: =J18/R18-1 | X18: =J18/S18-1 | Y18: 0.9582 | Z18: =Y18/J18 | AA18: =(J18-R18)/Y18 | AB18: =(J18-S18)/Y18 | AC18: =IF(ABS(AA18)<=ABS(AB18),"9EMA","21EMA") | AD18: 9+21EMA | AE18: 持續在上方 | AH18: ✓ | AI18: 2026-07-16 | AJ18: 54 | AK18: 5 | AL18: 2026-09-24 | AM18: 21.19 | AN18: 19.63 | AO18: =IF(ISNUMBER(AN18),AM18/AN18-1,"") | AP18: 5 | AQ18: =IF(ISNUMBER(AM18),J18/AM18-1,"") | AR18: 22.76 | AS18: =J18/AR18-1 | AT18: 上升通道 | AU18: 0.6778 | AV18: 0.6864 | AW18: 0.5851 | AX18: 0.6232 | AY18: 3 | AZ18: 23.17 | BA18: 18.73 | BB18: 21.3281 | BC18: 1.292 | BD18: =IF(M18=N18,0.5,(J18-N18)/(M18-N18)) | BE18: 22.898 | BF18: 18.143 | BG18: =100*(0.4*MIN(1,MAX(0,((U18*100)-(0.0))/((2.5)-(0.0))))+0.3*MIN(1,MAX(0,((V18)-(0.6))/((1.0)-(0.6))))+0.3*MIN(1,MAX(0,((BE18)-(0.0))/((15.0)-(0.0))))) | BH18: =100*(0.4*MIN(1,MAX(0,((MIN(ABS(AA18),ABS(AB18)))-(0.75))/((0.0)-(0.75))))+0.3*MIN(1,MAX(0,((BC18)-(1.2))/((0.6)-(1.2))))+0.3*BD18) | BI18: =100*(0.5*MIN(1,MAX(0,((AK18)-(1.0))/((4.0)-(1.0))))+0.3*MIN(1,MAX(0,((IF(ISNUMBER(AO18),AO18,0)*100)-(0.0))/((8.0)-(0.0))))+0.2*MIN(1,MAX(0,((IF(ISNUMBER(AP18),AP18,0))-(25.0))/((5.0)-(25.0))))) | BJ18: =100*(0.35*MIN(1,MAX(0,((ABS(AU18))-(0.3))/((0.05)-(0.3))))+0.3*MIN(1,MAX(0,((AV18)-(0.0))/((0.3)-(0.0))))+0.25*MIN(1,MAX(0,((AW18)-(0.4))/((0.7)-(0.4))))+0.1*IF(AY18>=2,1,0.5)) | BK18: =0.25*BG18+0.25*BH18+0.2*BI18+0.3*BJ18 | BL18: 全部通過
A19: 1 | B19: 18 | C19: ISRG | D19: Intuitive Surgical Inc. | E19: NASDAQ | F19: 醫療保健 | G19: Industrial Specialties | H19: 143.653 | I19: 大型 | J19: 401.24 | K19: 406.63 | L19: =J19/K19-1 | M19: 410.52 | N19: 399.25 | O19: 1511300 | P19: 2411950 | Q19: =O19/P19 | R19: 401.8931 | S19: 392.5062 | T19: 383.2484 | U19: =S19/T19-1 | V19: 1 | W19: =J19/R19-1 | X19: =J19/S19-1 | Y19: 10.9654 | Z19: =Y19/J19 | AA19: =(J19-R19)/Y19 | AB19: =(J19-S19)/Y19 | AC19: =IF(ABS(AA19)<=ABS(AB19),"9EMA","21EMA") | AD19: 9EMA | AE19: 持續在上方 | AH19: ✓ | AI19: 2026-09-17 | AJ19: 10 | AK19: 2 | AL19: 2026-09-25 | AM19: 391.92 | AN19: 345.25 | AO19: =IF(ISNUMBER(AN19),AM19/AN19-1,"") | AP19: 4 | AQ19: =IF(ISNUMBER(AM19),J19/AM19-1,"") | AR19: 414.79 | AS19: =J19/AR19-1 | AT19: 上升通道 | AU19: 0.4999 | AV19: 0.4297 | AW19: 0.5212 | AX19: 0.4986 | AY19: 4 | AZ19: 416.51 | BA19: 345.25 | BB19: 382.3872 | BC19: 0.6169 | BD19: =IF(M19=N19,0.5,(J19-N19)/(M19-N19)) | BE19: 13.418 | BF19: 8.664 | BG19: =100*(0.4*MIN(1,MAX(0,((U19*100)-(0.0))/((2.5)-(0.0))))+0.3*MIN(1,MAX(0,((V19)-(0.6))/((1.0)-(0.6))))+0.3*MIN(1,MAX(0,((BE19)-(0.0))/((15.0)-(0.0))))) | BH19: =100*(0.4*MIN(1,MAX(0,((MIN(ABS(AA19),ABS(AB19)))-(0.75))/((0.0)-(0.75))))+0.3*MIN(1,MAX(0,((BC19)-(1.2))/((0.6)-(1.2))))+0.3*BD19) | BI19: =100*(0.5*MIN(1,MAX(0,((AK19)-(1.0))/((4.0)-(1.0))))+0.3*MIN(1,MAX(0,((IF(ISNUMBER(AO19),AO19,0)*100)-(0.0))/((8.0)-(0.0))))+0.2*MIN(1,MAX(0,((IF(ISNUMBER(AP19),AP19,0))-(25.0))/((5.0)-(25.0))))) | BJ19: =100*(0.35*MIN(1,MAX(0,((ABS(AU19))-(0.3))/((0.05)-(0.3))))+0.3*MIN(1,MAX(0,((AV19)-(0.0))/((0.3)-(0.0))))+0.25*MIN(1,MAX(0,((AW19)-(0.4))/((0.7)-(0.4))))+0.1*IF(AY19>=2,1,0.5)) | BK19: =0.25*BG19+0.25*BH19+0.2*BI19+0.3*BJ19 | BL19: 全部通過
A20: 1 | B20: 19 | C20: SEI | D20: Solaris Energy Infrastructure Inc. | E20: NYSE | F20: 非必需消費 | G20: Oil and Gas Field Machinery | H20: 5.45 | I20: 中型 | J20: 71.38 | K20: 71.18 | L20: =J20/K20-1 | M20: 72.5 | N20: 70.23 | O20: 1718800 | P20: 2796590 | Q20: =O20/P20 | R20: 69.1653 | S20: 65.9819 | T20: 63.367 | U20: =S20/T20-1 | V20: 1 | W20: =J20/R20-1 | X20: =J20/S20-1 | Y20: 4.0993 | Z20: =Y20/J20 | AA20: =(J20-R20)/Y20 | AB20: =(J20-S20)/Y20 | AC20: =IF(ABS(AA20)<=ABS(AB20),"9EMA","21EMA") | AD20: 9EMA | AE20: 持續在上方 | AI20: 2026-09-09 | AJ20: 16 | AK20: 3 | AL20: 2026-09-23 | AM20: 64.23 | AN20: 60.59 | AO20: =IF(ISNUMBER(AN20),AM20/AN20-1,"") | AP20: 6 | AQ20: =IF(ISNUMBER(AM20),J20/AM20-1,"") | AR20: 71.38 | AS20: =J20/AR20-1 | AT20: 上傾收窄（楔形） | AU20: 0.2498 | AV20: 1.6431 | AW20: 0.6585 | AX20: 0.6637 | AY20: 5 | AZ20: 72.5 | BA20: 47.81 | BB20: 64.0693 | BC20: 0.9737 | BD20: =IF(M20=N20,0.5,(J20-N20)/(M20-N20)) | BE20: 48.549 | BF20: 43.795 | BG20: =100*(0.4*MIN(1,MAX(0,((U20*100)-(0.0))/((2.5)-(0.0))))+0.3*MIN(1,MAX(0,((V20)-(0.6))/((1.0)-(0.6))))+0.3*MIN(1,MAX(0,((BE20)-(0.0))/((15.0)-(0.0))))) | BH20: =100*(0.4*MIN(1,MAX(0,((MIN(ABS(AA20),ABS(AB20)))-(0.75))/((0.0)-(0.75))))+0.3*MIN(1,MAX(0,((BC20)-(1.2))/((0.6)-(1.2))))+0.3*BD20) | BI20: =100*(0.5*MIN(1,MAX(0,((AK20)-(1.0))/((4.0)-(1.0))))+0.3*MIN(1,MAX(0,((IF(ISNUMBER(AO20),AO20,0)*100)-(0.0))/((8.0)-(0.0))))+0.2*MIN(1,MAX(0,((IF(ISNUMBER(AP20),AP20,0))-(25.0))/((5.0)-(25.0))))) | BJ20: =100*(0.35*MIN(1,MAX(0,((ABS(AU20))-(0.3))/((0.05)-(0.3))))+0.3*MIN(1,MAX(0,((AV20)-(0.0))/((0.3)-(0.0))))+0.25*MIN(1,MAX(0,((AW20)-(0.4))/((0.7)-(0.4))))+0.1*IF(AY20>=2,1,0.5)) | BK20: =0.25*BG20+0.25*BH20+0.2*BI20+0.3*BJ20 | BL20: 全部通過
A21: 1 | B21: 20 | C21: FTNT | D21: Fortinet Inc. | E21: NASDAQ | F21: 科技 | G21: Computer peripheral equipment | H21: 131.159 | I21: 大型 | J21: 178.72 | K21: 178.76 | L21: =J21/K21-1 | M21: 180 | N21: 175.02 | O21: 2962800 | P21: 3961810 | Q21: =O21/P21 | R21: 175.8128 | S21: 171.1716 | T21: 167.6807 | U21: =S21/T21-1 | V21: 1 | W21: =J21/R21-1 | X21: =J21/S21-1 | Y21: 6.4558 | Z21: =Y21/J21 | AA21: =(J21-R21)/Y21 | AB21: =(J21-S21)/Y21 | AC21: =IF(ABS(AA21)<=ABS(AB21),"9EMA","21EMA") | AD21: 9EMA | AE21: 持續在上方 | AH21: ✓ | AI21: 2026-09-14 | AJ21: 13 | AK21: 4 | AL21: 2026-09-28 | AM21: 169.56 | AN21: 166.09 | AO21: =IF(ISNUMBER(AN21),AM21/AN21-1,"") | AP21: 3 | AQ21: =IF(ISNUMBER(AM21),J21/AM21-1,"") | AR21: 178.76 | AS21: =J21/AR21-1 | AT21: 上傾收窄（楔形） | AU21: 0.1917 | AV21: 0.6021 | AW21: 0.573 | AX21: 0.5865 | AY21: 4 | AZ21: 181.37 | BA21: 151.8 | BB21: 168.7443 | BC21: 1.52 | BD21: =IF(M21=N21,0.5,(J21-N21)/(M21-N21)) | BE21: 15.177 | BF21: 10.423 | BG21: =100*(0.4*MIN(1,MAX(0,((U21*100)-(0.0))/((2.5)-(0.0))))+0.3*MIN(1,MAX(0,((V21)-(0.6))/((1.0)-(0.6))))+0.3*MIN(1,MAX(0,((BE21)-(0.0))/((15.0)-(0.0))))) | BH21: =100*(0.4*MIN(1,MAX(0,((MIN(ABS(AA21),ABS(AB21)))-(0.75))/((0.0)-(0.75))))+0.3*MIN(1,MAX(0,((BC21)-(1.2))/((0.6)-(1.2))))+0.3*BD21) | BI21: =100*(0.5*MIN(1,MAX(0,((AK21)-(1.0))/((4.0)-(1.0))))+0.3*MIN(1,MAX(0,((IF(ISNUMBER(AO21),AO21,0)*100)-(0.0))/((8.0)-(0.0))))+0.2*MIN(1,MAX(0,((IF(ISNUMBER(AP21),AP21,0))-(25.0))/((5.0)-(25.0))))) | BJ21: =100*(0.35*MIN(1,MAX(0,((ABS(AU21))-(0.3))/((0.05)-(0.3))))+0.3*MIN(1,MAX(0,((AV21)-(0.0))/((0.3)-(0.0))))+0.25*MIN(1,MAX(0,((AW21)-(0.4))/((0.7)-(0.4))))+0.1*IF(AY21>=2,1,0.5)) | BK21: =0.25*BG21+0.25*BH21+0.2*BI21+0.3*BJ21 | BL21: 全部通過
A22: 1 | B22: 21 | C22: AVT | D22: Avnet Inc. | E22: NASDAQ | F22: 科技 | G22: Electronic Components | H22: 8.203 | I22: 中型 | J22: 102.24 | K22: 99.95 | L22: =J22/K22-1 | M22: 103.46 | N22: 98.55 | O22: 1203700 | P22: 1365340 | Q22: =O22/P22 | R22: 100.1881 | S22: 97.3309 | T22: 94.6101 | U22: =S22/T22-1 | V22: 1 | W22: =J22/R22-1 | X22: =J22/S22-1 | Y22: 3.8317 | Z22: =Y22/J22 | AA22: =(J22-R22)/Y22 | AB22: =(J22-S22)/Y22 | AC22: =IF(ABS(AA22)<=ABS(AB22),"9EMA","21EMA") | AD22: 9EMA | AE22: 持續在上方 | AH22: ✓ | AI22: 2026-09-08 | AJ22: 17 | AK22: 5 | AL22: 2026-09-16 | AM22: 90.9 | AN22: 86.71 | AO22: =IF(ISNUMBER(AN22),AM22/AN22-1,"") | AP22: 11 | AQ22: =IF(ISNUMBER(AM22),J22/AM22-1,"") | AR22: 103.08 | AS22: =J22/AR22-1 | AT22: 上升通道 | AU22: 0.6087 | AV22: 0.5123 | AW22: 0.5054 | AX22: 0.4921 | AY22: 4 | AZ22: 104.58 | BA22: 86.71 | BB22: 95.7408 | BC22: 0.8726 | BD22: =IF(M22=N22,0.5,(J22-N22)/(M22-N22)) | BE22: 19.129 | BF22: 14.375 | BG22: =100*(0.4*MIN(1,MAX(0,((U22*100)-(0.0))/((2.5)-(0.0))))+0.3*MIN(1,MAX(0,((V22)-(0.6))/((1.0)-(0.6))))+0.3*MIN(1,MAX(0,((BE22)-(0.0))/((15.0)-(0.0))))) | BH22: =100*(0.4*MIN(1,MAX(0,((MIN(ABS(AA22),ABS(AB22)))-(0.75))/((0.0)-(0.75))))+0.3*MIN(1,MAX(0,((BC22)-(1.2))/((0.6)-(1.2))))+0.3*BD22) | BI22: =100*(0.5*MIN(1,MAX(0,((AK22)-(1.0))/((4.0)-(1.0))))+0.3*MIN(1,MAX(0,((IF(ISNUMBER(AO22),AO22,0)*100)-(0.0))/((8.0)-(0.0))))+0.2*MIN(1,MAX(0,((IF(ISNUMBER(AP22),AP22,0))-(25.0))/((5.0)-(25.0))))) | BJ22: =100*(0.35*MIN(1,MAX(0,((ABS(AU22))-(0.3))/((0.05)-(0.3))))+0.3*MIN(1,MAX(0,((AV22)-(0.0))/((0.3)-(0.0))))+0.25*MIN(1,MAX(0,((AW22)-(0.4))/((0.7)-(0.4))))+0.1*IF(AY22>=2,1,0.5)) | BK22: =0.25*BG22+0.25*BH22+0.2*BI22+0.3*BJ22 | BL22: 全部通過
A23: 1 | B23: 22 | C23: MRVL | D23: Marvell Technology Inc. | E23: NASDAQ | F23: 科技 | G23: Semiconductors | H23: 231.686 | I23: 大型 | J23: 268.08 | K23: 264.21 | L23: =J23/K23-1 | M23: 270.28 | N23: 257.58 | O23: 18986300 | P23: 17834650 | Q23: =O23/P23 | R23: 258.2212 | S23: 247 | T23: 237.6213 | U23: =S23/T23-1 | V23: 1 | W23: =J23/R23-1 | X23: =J23/S23-1 | Y23: 13.0892 | Z23: =Y23/J23 | AA23: =(J23-R23)/Y23 | AB23: =(J23-S23)/Y23 | AC23: =IF(ABS(AA23)<=ABS(AB23),"9EMA","21EMA") | AD23: 9EMA | AE23: 持續在上方 | AI23: 2026-09-09 | AJ23: 16 | AK23: 3 | AL23: 2026-09-28 | AM23: 248.14 | AN23: 213.63 | AO23: =IF(ISNUMBER(AN23),AM23/AN23-1,"") | AP23: 3 | AQ23: =IF(ISNUMBER(AM23),J23/AM23-1,"") | AR23: 268.08 | AS23: =J23/AR23-1 | AT23: 上傾收窄（楔形） | AU23: 0.2841 | AV23: 0.9972 | AW23: 0.5018 | AX23: 0.4723 | AY23: 2 | AZ23: 270.28 | BA23: 200.62 | BB23: 235.5757 | BC23: 0.8184 | BD23: =IF(M23=N23,0.5,(J23-N23)/(M23-N23)) | BE23: 32.175 | BF23: 27.421 | BG23: =100*(0.4*MIN(1,MAX(0,((U23*100)-(0.0))/((2.5)-(0.0))))+0.3*MIN(1,MAX(0,((V23)-(0.6))/((1.0)-(0.6))))+0.3*MIN(1,MAX(0,((BE23)-(0.0))/((15.0)-(0.0))))) | BH23: =100*(0.4*MIN(1,MAX(0,((MIN(ABS(AA23),ABS(AB23)))-(0.75))/((0.0)-(0.75))))+0.3*MIN(1,MAX(0,((BC23)-(1.2))/((0.6)-(1.2))))+0.3*BD23) | BI23: =100*(0.5*MIN(1,MAX(0,((AK23)-(1.0))/((4.0)-(1.0))))+0.3*MIN(1,MAX(0,((IF(ISNUMBER(AO23),AO23,0)*100)-(0.0))/((8.0)-(0.0))))+0.2*MIN(1,MAX(0,((IF(ISNUMBER(AP23),AP23,0))-(25.0))/((5.0)-(25.0))))) | BJ23: =100*(0.35*MIN(1,MAX(0,((ABS(AU23))-(0.3))/((0.05)-(0.3))))+0.3*MIN(1,MAX(0,((AV23)-(0.0))/((0.3)-(0.0))))+0.25*MIN(1,MAX(0,((AW23)-(0.4))/((0.7)-(0.4))))+0.1*IF(AY23>=2,1,0.5)) | BK23: =0.25*BG23+0.25*BH23+0.2*BI23+0.3*BJ23 | BL23: 全部通過
A24: 1 | B24: 23 | C24: CVLT | D24: Commvault Systems Inc. | E24: NASDAQ | F24: 科技 | G24: Computer Software: Prepackaged Software | H24: 6.213 | I24: 中型 | J24: 147.77 | K24: 149.92 | L24: =J24/K24-1 | M24: 151.5 | N24: 145.69 | O24: 706300 | P24: 592410 | Q24: =O24/P24 | R24: 146.9838 | S24: 143.7918 | T24: 141.4376 | U24: =S24/T24-1 | V24: 1 | W24: =J24/R24-1 | X24: =J24/S24-1 | Y24: 5.7889 | Z24: =Y24/J24 | AA24: =(J24-R24)/Y24 | AB24: =(J24-S24)/Y24 | AC24: =IF(ABS(AA24)<=ABS(AB24),"9EMA","21EMA") | AD24: 9EMA | AE24: 持續在上方 | AH24: ✓ | AI24: 2026-09-15 | AJ24: 12 | AK24: 3 | AL24: 2026-09-28 | AM24: 141.1 | AN24: 129.5 | AO24: =IF(ISNUMBER(AN24),AM24/AN24-1,"") | AP24: 3 | AQ24: =IF(ISNUMBER(AM24),J24/AM24-1,"") | AR24: 150 | AS24: =J24/AR24-1 | AT24: 上傾收窄（楔形） | AU24: 0.343 | AV24: 0.6185 | AW24: 0.6215 | AX24: 0.6098 | AY24: 8 | AZ24: 151.62 | BA24: 125.9 | BB24: 141.8847 | BC24: 1.1136 | BD24: =IF(M24=N24,0.5,(J24-N24)/(M24-N24)) | BE24: 19.127 | BF24: 14.373 | BG24: =100*(0.4*MIN(1,MAX(0,((U24*100)-(0.0))/((2.5)-(0.0))))+0.3*MIN(1,MAX(0,((V24)-(0.6))/((1.0)-(0.6))))+0.3*MIN(1,MAX(0,((BE24)-(0.0))/((15.0)-(0.0))))) | BH24: =100*(0.4*MIN(1,MAX(0,((MIN(ABS(AA24),ABS(AB24)))-(0.75))/((0.0)-(0.75))))+0.3*MIN(1,MAX(0,((BC24)-(1.2))/((0.6)-(1.2))))+0.3*BD24) | BI24: =100*(0.5*MIN(1,MAX(0,((AK24)-(1.0))/((4.0)-(1.0))))+0.3*MIN(1,MAX(0,((IF(ISNUMBER(AO24),AO24,0)*100)-(0.0))/((8.0)-(0.0))))+0.2*MIN(1,MAX(0,((IF(ISNUMBER(AP24),AP24,0))-(25.0))/((5.0)-(25.0))))) | BJ24: =100*(0.35*MIN(1,MAX(0,((ABS(AU24))-(0.3))/((0.05)-(0.3))))+0.3*MIN(1,MAX(0,((AV24)-(0.0))/((0.3)-(0.0))))+0.25*MIN(1,MAX(0,((AW24)-(0.4))/((0.7)-(0.4))))+0.1*IF(AY24>=2,1,0.5)) | BK24: =0.25*BG24+0.25*BH24+0.2*BI24+0.3*BJ24 | BL24: 全部通過
A25: 1 | B25: 24 | C25: ADPT | D25: Adaptive Biotechnologies Corporation | E25: NASDAQ | F25: 醫療保健 | G25: Biotechnology: Biological Products (No Diagnostic Substances) | H25: 4.612 | I25: 中型 | J25: 27.37 | K25: 28.9 | L25: =J25/K25-1 | M25: 29 | N25: 27.145 | O25: 6018700 | P25: 2499620 | Q25: =O25/P25 | R25: 28.197 | S25: 27.2931 | T25: 26.5416 | U25: =S25/T25-1 | V25: 1 | W25: =J25/R25-1 | X25: =J25/S25-1 | Y25: 1.272 | Z25: =Y25/J25 | AA25: =(J25-R25)/Y25 | AB25: =(J25-S25)/Y25 | AC25: =IF(ABS(AA25)<=ABS(AB25),"9EMA","21EMA") | AD25: 9+21EMA | AE25: 持續在上方 | AG25: ✓ | AI25: 2026-09-15 | AJ25: 12 | AK25: 2 | AL25: 2026-09-22 | AM25: 26.733 | AN25: 23.53 | AO25: =IF(ISNUMBER(AN25),AM25/AN25-1,"") | AP25: 7 | AQ25: =IF(ISNUMBER(AM25),J25/AM25-1,"") | AR25: 29.57 | AS25: =J25/AR25-1 | AT25: 上傾收窄（楔形） | AU25: 0.6928 | AV25: 1.4628 | AW25: 0.5473 | AX25: 0.5305 | AY25: 5 | AZ25: 29.96 | BA25: 23.53 | BB25: 27.049 | BC25: 0.8816 | BD25: =IF(M25=N25,0.5,(J25-N25)/(M25-N25)) | BE25: 17.203 | BF25: 12.449 | BG25: =100*(0.4*MIN(1,MAX(0,((U25*100)-(0.0))/((2.5)-(0.0))))+0.3*MIN(1,MAX(0,((V25)-(0.6))/((1.0)-(0.6))))+0.3*MIN(1,MAX(0,((BE25)-(0.0))/((15.0)-(0.0))))) | BH25: =100*(0.4*MIN(1,MAX(0,((MIN(ABS(AA25),ABS(AB25)))-(0.75))/((0.0)-(0.75))))+0.3*MIN(1,MAX(0,((BC25)-(1.2))/((0.6)-(1.2))))+0.3*BD25) | BI25: =100*(0.5*MIN(1,MAX(0,((AK25)-(1.0))/((4.0)-(1.0))))+0.3*MIN(1,MAX(0,((IF(ISNUMBER(AO25),AO25,0)*100)-(0.0))/((8.0)-(0.0))))+0.2*MIN(1,MAX(0,((IF(ISNUMBER(AP25),AP25,0))-(25.0))/((5.0)-(25.0))))) | BJ25: =100*(0.35*MIN(1,MAX(0,((ABS(AU25))-(0.3))/((0.05)-(0.3))))+0.3*MIN(1,MAX(0,((AV25)-(0.0))/((0.3)-(0.0))))+0.25*MIN(1,MAX(0,((AW25)-(0.4))/((0.7)-(0.4))))+0.1*IF(AY25>=2,1,0.5)) | BK25: =0.25*BG25+0.25*BH25+0.2*BI25+0.3*BJ25 | BL25: 全部通過
A26: 1 | B26: 25 | C26: DELL | D26: Dell Technologies Inc. Class C | E26: NYSE | F26: 科技 | G26: Computer Manufacturing | H26: 342.035 | I26: 大型 | J26: 541.74 | K26: 537.95 | L26: =J26/K26-1 | M26: 550.29 | N26: 520.18 | O26: 6669200 | P26: 9281610 | Q26: =O26/P26 | R26: 545.0722 | S26: 533.3966 | T26: 526.7666 | U26: =S26/T26-1 | V26: 1 | W26: =J26/R26-1 | X26: =J26/S26-1 | Y26: 29.1657 | Z26: =Y26/J26 | AA26: =(J26-R26)/Y26 | AB26: =(J26-S26)/Y26 | AC26: =IF(ABS(AA26)<=ABS(AB26),"9EMA","21EMA") | AD26: 9+21EMA | AE26: 持續在上方 | AH26: ✓ | AI26: 2026-08-04 | AJ26: 41 | AK26: 3 | AL26: 2026-09-24 | AM26: 530.45 | AN26: 506.25 | AO26: =IF(ISNUMBER(AN26),AM26/AN26-1,"") | AP26: 5 | AQ26: =IF(ISNUMBER(AM26),J26/AM26-1,"") | AR26: 588.4 | AS26: =J26/AR26-1 | AT26: 上傾收窄（楔形） | AU26: 0.7022 | AV26: 1.1702 | AW26: 0.5963 | AX26: 0.6145 | AY26: 3 | AZ26: 595.51 | BA26: 421.89 | BB26: 525.4152 | BC26: 0.9982 | BD26: =IF(M26=N26,0.5,(J26-N26)/(M26-N26)) | BE26: 32.222 | BF26: 27.468 | BG26: =100*(0.4*MIN(1,MAX(0,((U26*100)-(0.0))/((2.5)-(0.0))))+0.3*MIN(1,MAX(0,((V26)-(0.6))/((1.0)-(0.6))))+0.3*MIN(1,MAX(0,((BE26)-(0.0))/((15.0)-(0.0))))) | BH26: =100*(0.4*MIN(1,MAX(0,((MIN(ABS(AA26),ABS(AB26)))-(0.75))/((0.0)-(0.75))))+0.3*MIN(1,MAX(0,((BC26)-(1.2))/((0.6)-(1.2))))+0.3*BD26) | BI26: =100*(0.5*MIN(1,MAX(0,((AK26)-(1.0))/((4.0)-(1.0))))+0.3*MIN(1,MAX(0,((IF(ISNUMBER(AO26),AO26,0)*100)-(0.0))/((8.0)-(0.0))))+0.2*MIN(1,MAX(0,((IF(ISNUMBER(AP26),AP26,0))-(25.0))/((5.0)-(25.0))))) | BJ26: =100*(0.35*MIN(1,MAX(0,((ABS(AU26))-(0.3))/((0.05)-(0.3))))+0.3*MIN(1,MAX(0,((AV26)-(0.0))/((0.3)-(0.0))))+0.25*MIN(1,MAX(0,((AW26)-(0.4))/((0.7)-(0.4))))+0.1*IF(AY26>=2,1,0.5)) | BK26: =0.25*BG26+0.25*BH26+0.2*BI26+0.3*BJ26 | BL26: 全部通過
A27: 1 | B27: 26 | C27: STX | D27: Seagate Technology Holdings PLC | E27: NASDAQ | F27: 科技 | G27: Electronic Components | H27: 210.956 | I27: 大型 | J27: 945.57 | K27: 922.34 | L27: =J27/K27-1 | M27: 946.36 | N27: 893.75 | O27: 2480800 | P27: 3764645 | Q27: =O27/P27 | R27: 909.5021 | S27: 882.858 | T27: 857.0708 | U27: =S27/T27-1 | V27: 1 | W27: =J27/R27-1 | X27: =J27/S27-1 | Y27: 48.238 | Z27: =Y27/J27 | AA27: =(J27-R27)/Y27 | AB27: =(J27-S27)/Y27 | AC27: =IF(ABS(AA27)<=ABS(AB27),"9EMA","21EMA") | AD27: 9EMA | AE27: 持續在上方 | AI27: 2026-09-22 | AJ27: 7 | AK27: 2 | AL27: 2026-09-28 | AM27: 870.38 | AN27: 758.35 | AO27: =IF(ISNUMBER(AN27),AM27/AN27-1,"") | AP27: 3 | AQ27: =IF(ISNUMBER(AM27),J27/AM27-1,"") | AR27: 945.57 | AS27: =J27/AR27-1 | AT27: 上傾收窄（楔形） | AU27: 0.3629 | AV27: 0.7348 | AW27: 0.5406 | AX27: 0.5075 | AY27: 4 | AZ27: 946.36 | BA27: 758.35 | BB27: 859.9854 | BC27: 0.7204 | BD27: =IF(M27=N27,0.5,(J27-N27)/(M27-N27)) | BE27: 20.542 | BF27: 15.788 | BG27: =100*(0.4*MIN(1,MAX(0,((U27*100)-(0.0))/((2.5)-(0.0))))+0.3*MIN(1,MAX(0,((V27)-(0.6))/((1.0)-(0.6))))+0.3*MIN(1,MAX(0,((BE27)-(0.0))/((15.0)-(0.0))))) | BH27: =100*(0.4*MIN(1,MAX(0,((MIN(ABS(AA27),ABS(AB27)))-(0.75))/((0.0)-(0.75))))+0.3*MIN(1,MAX(0,((BC27)-(1.2))/((0.6)-(1.2))))+0.3*BD27) | BI27: =100*(0.5*MIN(1,MAX(0,((AK27)-(1.0))/((4.0)-(1.0))))+0.3*MIN(1,MAX(0,((IF(ISNUMBER(AO27),AO27,0)*100)-(0.0))/((8.0)-(0.0))))+0.2*MIN(1,MAX(0,((IF(ISNUMBER(AP27),AP27,0))-(25.0))/((5.0)-(25.0))))) | BJ27: =100*(0.35*MIN(1,MAX(0,((ABS(AU27))-(0.3))/((0.05)-(0.3))))+0.3*MIN(1,MAX(0,((AV27)-(0.0))/((0.3)-(0.0))))+0.25*MIN(1,MAX(0,((AW27)-(0.4))/((0.7)-(0.4))))+0.1*IF(AY27>=2,1,0.5)) | BK27: =0.25*BG27+0.25*BH27+0.2*BI27+0.3*BJ27 | BL27: 全部通過
A28: 1 | B28: 27 | C28: OBIO | D28: Orchestra BioMed Holdings Inc. | E28: NASDAQ | F28: 醫療保健 | G28: Medicinal Chemicals and Botanical Products | H28: 0.374 | I28: 小型 | J28: 6.35 | K28: 6.22 | L28: =J28/K28-1 | M28: 6.5 | N28: 6.23 | O28: 389900 | P28: 382525 | Q28: =O28/P28 | R28: 6.0841 | S28: 5.8318 | T28: 5.656 | U28: =S28/T28-1 | V28: 1 | W28: =J28/R28-1 | X28: =J28/S28-1 | Y28: 0.3362 | Z28: =Y28/J28 | AA28: =(J28-R28)/Y28 | AB28: =(J28-S28)/Y28 | AC28: =IF(ABS(AA28)<=ABS(AB28),"9EMA","21EMA") | AD28: 9EMA | AE28: 持續在上方 | AI28: 2026-08-03 | AJ28: 42 | AK28: 4 | AL28: 2026-09-24 | AM28: 5.75 | AN28: 5.71 | AO28: =IF(ISNUMBER(AN28),AM28/AN28-1,"") | AP28: 5 | AQ28: =IF(ISNUMBER(AM28),J28/AM28-1,"") | AR28: 6.35 | AS28: =J28/AR28-1 | AT28: 上傾收窄（楔形） | AU28: 0.8451 | AV28: 1.2477 | AW28: 0.5919 | AX28: 0.6395 | AY28: 2 | AZ28: 6.5 | BA28: 4.71 | BB28: 5.7695 | BC28: 0.5585 | BD28: =IF(M28=N28,0.5,(J28-N28)/(M28-N28)) | BE28: 34.346 | BF28: 29.592 | BG28: =100*(0.4*MIN(1,MAX(0,((U28*100)-(0.0))/((2.5)-(0.0))))+0.3*MIN(1,MAX(0,((V28)-(0.6))/((1.0)-(0.6))))+0.3*MIN(1,MAX(0,((BE28)-(0.0))/((15.0)-(0.0))))) | BH28: =100*(0.4*MIN(1,MAX(0,((MIN(ABS(AA28),ABS(AB28)))-(0.75))/((0.0)-(0.75))))+0.3*MIN(1,MAX(0,((BC28)-(1.2))/((0.6)-(1.2))))+0.3*BD28) | BI28: =100*(0.5*MIN(1,MAX(0,((AK28)-(1.0))/((4.0)-(1.0))))+0.3*MIN(1,MAX(0,((IF(ISNUMBER(AO28),AO28,0)*100)-(0.0))/((8.0)-(0.0))))+0.2*MIN(1,MAX(0,((IF(ISNUMBER(AP28),AP28,0))-(25.0))/((5.0)-(25.0))))) | BJ28: =100*(0.35*MIN(1,MAX(0,((ABS(AU28))-(0.3))/((0.05)-(0.3))))+0.3*MIN(1,MAX(0,((AV28)-(0.0))/((0.3)-(0.0))))+0.25*MIN(1,MAX(0,((AW28)-(0.4))/((0.7)-(0.4))))+0.1*IF(AY28>=2,1,0.5)) | BK28: =0.25*BG28+0.25*BH28+0.2*BI28+0.3*BJ28 | BL28: 全部通過
A29: 1 | B29: 28 | C29: ANET | D29: Arista Networks Inc. | E29: NYSE | F29: 電訊 | G29: Computer Communications Equipment | H29: 256.773 | I29: 大型 | J29: 204.49 | K29: 203.59 | L29: =J29/K29-1 | M29: 206.35 | N29: 200.771 | O29: 4106100 | P29: 4781150 | Q29: =O29/P29 | R29: 203.2534 | S29: 199.9286 | T29: 197.2075 | U29: =S29/T29-1 | V29: 1 | W29: =J29/R29-1 | X29: =J29/S29-1 | Y29: 7.0691 | Z29: =Y29/J29 | AA29: =(J29-R29)/Y29 | AB29: =(J29-S29)/Y29 | AC29: =IF(ABS(AA29)<=ABS(AB29),"9EMA","21EMA") | AD29: 9+21EMA | AE29: 持續在上方 | AH29: ✓ | AI29: 2026-07-31 | AJ29: 43 | AK29: 3 | AL29: 2026-09-24 | AM29: 198.757 | AN29: 186.11 | AO29: =IF(ISNUMBER(AN29),AM29/AN29-1,"") | AP29: 5 | AQ29: =IF(ISNUMBER(AM29),J29/AM29-1,"") | AR29: 206.55 | AS29: =J29/AR29-1 | AT29: 上傾收窄（楔形） | AU29: 0.1792 | AV29: 0.6196 | AW29: 0.5462 | AX29: 0.5846 | AY29: 1 | AZ29: 212 | BA29: 181.27 | BB29: 198.0549 | BC29: 1.2441 | BD29: =IF(M29=N29,0.5,(J29-N29)/(M29-N29)) | BE29: 12.801 | BF29: 8.047 | BG29: =100*(0.4*MIN(1,MAX(0,((U29*100)-(0.0))/((2.5)-(0.0))))+0.3*MIN(1,MAX(0,((V29)-(0.6))/((1.0)-(0.6))))+0.3*MIN(1,MAX(0,((BE29)-(0.0))/((15.0)-(0.0))))) | BH29: =100*(0.4*MIN(1,MAX(0,((MIN(ABS(AA29),ABS(AB29)))-(0.75))/((0.0)-(0.75))))+0.3*MIN(1,MAX(0,((BC29)-(1.2))/((0.6)-(1.2))))+0.3*BD29) | BI29: =100*(0.5*MIN(1,MAX(0,((AK29)-(1.0))/((4.0)-(1.0))))+0.3*MIN(1,MAX(0,((IF(ISNUMBER(AO29),AO29,0)*100)-(0.0))/((8.0)-(0.0))))+0.2*MIN(1,MAX(0,((IF(ISNUMBER(AP29),AP29,0))-(25.0))/((5.0)-(25.0))))) | BJ29: =100*(0.35*MIN(1,MAX(0,((ABS(AU29))-(0.3))/((0.05)-(0.3))))+0.3*MIN(1,MAX(0,((AV29)-(0.0))/((0.3)-(0.0))))+0.25*MIN(1,MAX(0,((AW29)-(0.4))/((0.7)-(0.4))))+0.1*IF(AY29>=2,1,0.5)) | BK29: =0.25*BG29+0.25*BH29+0.2*BI29+0.3*BJ29 | BL29: 全部通過
A30: 1 | B30: 29 | C30: ARW | D30: Arrow Electronics Inc. | E30: NYSE | F30: 科技 | G30: Electronic Components | H30: 11.556 | I30: 大型 | J30: 231.63 | K30: 227 | L30: =J30/K30-1 | M30: 232.95 | N30: 225.3 | O30: 471800 | P30: 538675 | Q30: =O30/P30 | R30: 227.1167 | S30: 221.875 | T30: 216.7168 | U30: =S30/T30-1 | V30: 1 | W30: =J30/R30-1 | X30: =J30/S30-1 | Y30: 7.3602 | Z30: =Y30/J30 | AA30: =(J30-R30)/Y30 | AB30: =(J30-S30)/Y30 | AC30: =IF(ABS(AA30)<=ABS(AB30),"9EMA","21EMA") | AD30: 9EMA | AE30: 持續在上方 | AH30: ✓ | AI30: 2026-09-08 | AJ30: 17 | AK30: 4 | AL30: 2026-09-16 | AM30: 207.88 | AN30: 200.99 | AO30: =IF(ISNUMBER(AN30),AM30/AN30-1,"") | AP30: 11 | AQ30: =IF(ISNUMBER(AM30),J30/AM30-1,"") | AR30: 232.8 | AS30: =J30/AR30-1 | AT30: 上傾擴張 | AU30: 0.5025 | AV30: 0.2975 | AW30: 0.5173 | AX30: 0.4888 | AY30: 6 | AZ30: 233.94 | BA30: 200.99 | BB30: 218.0354 | BC30: 0.8659 | BD30: =IF(M30=N30,0.5,(J30-N30)/(M30-N30)) | BE30: 17.207 | BF30: 12.453 | BG30: =100*(0.4*MIN(1,MAX(0,((U30*100)-(0.0))/((2.5)-(0.0))))+0.3*MIN(1,MAX(0,((V30)-(0.6))/((1.0)-(0.6))))+0.3*MIN(1,MAX(0,((BE30)-(0.0))/((15.0)-(0.0))))) | BH30: =100*(0.4*MIN(1,MAX(0,((MIN(ABS(AA30),ABS(AB30)))-(0.75))/((0.0)-(0.75))))+0.3*MIN(1,MAX(0,((BC30)-(1.2))/((0.6)-(1.2))))+0.3*BD30) | BI30: =100*(0.5*MIN(1,MAX(0,((AK30)-(1.0))/((4.0)-(1.0))))+0.3*MIN(1,MAX(0,((IF(ISNUMBER(AO30),AO30,0)*100)-(0.0))/((8.0)-(0.0))))+0.2*MIN(1,MAX(0,((IF(ISNUMBER(AP30),AP30,0))-(25.0))/((5.0)-(25.0))))) | BJ30: =100*(0.35*MIN(1,MAX(0,((ABS(AU30))-(0.3))/((0.05)-(0.3))))+0.3*MIN(1,MAX(0,((AV30)-(0.0))/((0.3)-(0.0))))+0.25*MIN(1,MAX(0,((AW30)-(0.4))/((0.7)-(0.4))))+0.1*IF(AY30>=2,1,0.5)) | BK30: =0.25*BG30+0.25*BH30+0.2*BI30+0.3*BJ30 | BL30: 全部通過
A31: 1 | B31: 30 | C31: FLGT | D31: Fulgent Genetics Inc. | E31: NASDAQ | F31: 醫療保健 | G31: Medical Specialities | H31: 0.606 | I31: 小型 | J31: 21.3 | K31: 22.02 | L31: =J31/K31-1 | M31: 22.05 | N31: 21.12 | O31: 338200 | P31: 330000 | Q31: =O31/P31 | R31: 21.6971 | S31: 21.196 | T31: 20.7358 | U31: =S31/T31-1 | V31: 1 | W31: =J31/R31-1 | X31: =J31/S31-1 | Y31: 0.6669 | Z31: =Y31/J31 | AA31: =(J31-R31)/Y31 | AB31: =(J31-S31)/Y31 | AC31: =IF(ABS(AA31)<=ABS(AB31),"9EMA","21EMA") | AD31: 9+21EMA | AE31: 持續在上方 | AG31: ✓ | AI31: 2026-08-20 | AJ31: 29 | AK31: 4 | AL31: 2026-09-21 | AM31: 21.01 | AN31: 19.04 | AO31: =IF(ISNUMBER(AN31),AM31/AN31-1,"") | AP31: 8 | AQ31: =IF(ISNUMBER(AM31),J31/AM31-1,"") | AR31: 22.36 | AS31: =J31/AR31-1 | AT31: 上升通道 | AU31: 0.5332 | AV31: 0.6606 | AW31: 0.5164 | AX31: 0.5028 | AY31: 2 | AZ31: 22.59 | BA31: 19.04 | BB31: 20.8733 | BC31: 1.2258 | BD31: =IF(M31=N31,0.5,(J31-N31)/(M31-N31)) | BE31: 13.483 | BF31: 8.729 | BG31: =100*(0.4*MIN(1,MAX(0,((U31*100)-(0.0))/((2.5)-(0.0))))+0.3*MIN(1,MAX(0,((V31)-(0.6))/((1.0)-(0.6))))+0.3*MIN(1,MAX(0,((BE31)-(0.0))/((15.0)-(0.0))))) | BH31: =100*(0.4*MIN(1,MAX(0,((MIN(ABS(AA31),ABS(AB31)))-(0.75))/((0.0)-(0.75))))+0.3*MIN(1,MAX(0,((BC31)-(1.2))/((0.6)-(1.2))))+0.3*BD31) | BI31: =100*(0.5*MIN(1,MAX(0,((AK31)-(1.0))/((4.0)-(1.0))))+0.3*MIN(1,MAX(0,((IF(ISNUMBER(AO31),AO31,0)*100)-(0.0))/((8.0)-(0.0))))+0.2*MIN(1,MAX(0,((IF(ISNUMBER(AP31),AP31,0))-(25.0))/((5.0)-(25.0))))) | BJ31: =100*(0.35*MIN(1,MAX(0,((ABS(AU31))-(0.3))/((0.05)-(0.3))))+0.3*MIN(1,MAX(0,((AV31)-(0.0))/((0.3)-(0.0))))+0.25*MIN(1,MAX(0,((AW31)-(0.4))/((0.7)-(0.4))))+0.1*IF(AY31>=2,1,0.5)) | BK31: =0.25*BG31+0.25*BH31+0.2*BI31+0.3*BJ31 | BL31: 全部通過
A32: 1 | B32: 31 | C32: CRSR | D32: Corsair Gaming Inc. | E32: NASDAQ | F32: 科技 | G32: Computer peripheral equipment | H32: 1.46 | I32: 小型 | J32: 13.85 | K32: 13.5 | L32: =J32/K32-1 | M32: 14.24 | N32: 13.385 | O32: 1396000 | P32: 1064355 | Q32: =O32/P32 | R32: 13.5283 | S32: 13.159 | T32: 12.8885 | U32: =S32/T32-1 | V32: 1 | W32: =J32/R32-1 | X32: =J32/S32-1 | Y32: 0.5997 | Z32: =Y32/J32 | AA32: =(J32-R32)/Y32 | AB32: =(J32-S32)/Y32 | AC32: =IF(ABS(AA32)<=ABS(AB32),"9EMA","21EMA") | AD32: 9EMA | AE32: 持續在上方 | AH32: ✓ | AI32: 2026-06-29 | AJ32: 66 | AK32: 6 | AL32: 2026-09-24 | AM32: 13.06 | AN32: 12.05 | AO32: =IF(ISNUMBER(AN32),AM32/AN32-1,"") | AP32: 5 | AQ32: =IF(ISNUMBER(AM32),J32/AM32-1,"") | AR32: 13.85 | AS32: =J32/AR32-1 | AT32: 上傾收窄（楔形） | AU32: 0.5091 | AV32: 0.6863 | AW32: 0.5308 | AX32: 0.6089 | AY32: 1 | AZ32: 14.24 | BA32: 11.55 | BB32: 12.9778 | BC32: 0.9966 | BD32: =IF(M32=N32,0.5,(J32-N32)/(M32-N32)) | BE32: 23.945 | BF32: 19.191 | BG32: =100*(0.4*MIN(1,MAX(0,((U32*100)-(0.0))/((2.5)-(0.0))))+0.3*MIN(1,MAX(0,((V32)-(0.6))/((1.0)-(0.6))))+0.3*MIN(1,MAX(0,((BE32)-(0.0))/((15.0)-(0.0))))) | BH32: =100*(0.4*MIN(1,MAX(0,((MIN(ABS(AA32),ABS(AB32)))-(0.75))/((0.0)-(0.75))))+0.3*MIN(1,MAX(0,((BC32)-(1.2))/((0.6)-(1.2))))+0.3*BD32) | BI32: =100*(0.5*MIN(1,MAX(0,((AK32)-(1.0))/((4.0)-(1.0))))+0.3*MIN(1,MAX(0,((IF(ISNUMBER(AO32),AO32,0)*100)-(0.0))/((8.0)-(0.0))))+0.2*MIN(1,MAX(0,((IF(ISNUMBER(AP32),AP32,0))-(25.0))/((5.0)-(25.0))))) | BJ32: =100*(0.35*MIN(1,MAX(0,((ABS(AU32))-(0.3))/((0.05)-(0.3))))+0.3*MIN(1,MAX(0,((AV32)-(0.0))/((0.3)-(0.0))))+0.25*MIN(1,MAX(0,((AW32)-(0.4))/((0.7)-(0.4))))+0.1*IF(AY32>=2,1,0.5)) | BK32: =0.25*BG32+0.25*BH32+0.2*BI32+0.3*BJ32 | BL32: 全部通過
A33: 1 | B33: 32 | C33: UCTT | D33: Ultra Clean Holdings Inc. | E33: NASDAQ | F33: 科技 | G33: Semiconductors | H33: 3.67 | I33: 中型 | J33: 78.64 | K33: 81.06 | L33: =J33/K33-1 | M33: 81.87 | N33: 77.76 | O33: 1264200 | P33: 872500 | Q33: =O33/P33 | R33: 77.3895 | S33: 75.6253 | T33: 73.4001 | U33: =S33/T33-1 | V33: 0.9 | W33: =J33/R33-1 | X33: =J33/S33-1 | Y33: 4.445 | Z33: =Y33/J33 | AA33: =(J33-R33)/Y33 | AB33: =(J33-S33)/Y33 | AC33: =IF(ABS(AA33)<=ABS(AB33),"9EMA","21EMA") | AD33: 9EMA | AE33: 剛黃金交叉 | AF33: ✓ | AH33: ✓ | AI33: 2026-09-25 | AJ33: 4 | AK33: 2 | AL33: 2026-09-15 | AM33: 64.77 | AN33: 62.68 | AO33: =IF(ISNUMBER(AN33),AM33/AN33-1,"") | AP33: 12 | AQ33: =IF(ISNUMBER(AM33),J33/AM33-1,"") | AR33: 81.06 | AS33: =J33/AR33-1 | AT33: 上升三角（平頂） | AU33: -0.0827 | AV33: 0.3797 | AW33: 0.5265 | AX33: 0.5043 | AY33: 3 | AZ33: 82.57 | BA33: 62.68 | BB33: 73.1529 | BC33: 0.9717 | BD33: =IF(M33=N33,0.5,(J33-N33)/(M33-N33)) | BE33: 25.534 | BF33: 20.78 | BG33: =100*(0.4*MIN(1,MAX(0,((U33*100)-(0.0))/((2.5)-(0.0))))+0.3*MIN(1,MAX(0,((V33)-(0.6))/((1.0)-(0.6))))+0.3*MIN(1,MAX(0,((BE33)-(0.0))/((15.0)-(0.0))))) | BH33: =100*(0.4*MIN(1,MAX(0,((MIN(ABS(AA33),ABS(AB33)))-(0.75))/((0.0)-(0.75))))+0.3*MIN(1,MAX(0,((BC33)-(1.2))/((0.6)-(1.2))))+0.3*BD33) | BI33: =100*(0.5*MIN(1,MAX(0,((AK33)-(1.0))/((4.0)-(1.0))))+0.3*MIN(1,MAX(0,((IF(ISNUMBER(AO33),AO33,0)*100)-(0.0))/((8.0)-(0.0))))+0.2*MIN(1,MAX(0,((IF(ISNUMBER(AP33),AP33,0))-(25.0))/((5.0)-(25.0))))) | BJ33: =100*(0.35*MIN(1,MAX(0,((ABS(AU33))-(0.3))/((0.05)-(0.3))))+0.3*MIN(1,MAX(0,((AV33)-(0.0))/((0.3)-(0.0))))+0.25*MIN(1,MAX(0,((AW33)-(0.4))/((0.7)-(0.4))))+0.1*IF(AY33>=2,1,0.5)) | BK33: =0.25*BG33+0.25*BH33+0.2*BI33+0.3*BJ33 | BL33: 全部通過
A34: 1 | B34: 33 | C34: NTAP | D34: NetApp Inc. | E34: NASDAQ | F34: 科技 | G34: Electronic Components | H34: 41.264 | I34: 大型 | J34: 215.05 | K34: 210.08 | L34: =J34/K34-1 | M34: 215.22 | N34: 208.03 | O34: 2348700 | P34: 2566565 | Q34: =O34/P34 | R34: 204.5743 | S34: 198.3394 | T34: 192.0695 | U34: =S34/T34-1 | V34: 1 | W34: =J34/R34-1 | X34: =J34/S34-1 | Y34: 7.7496 | Z34: =Y34/J34 | AA34: =(J34-R34)/Y34 | AB34: =(J34-S34)/Y34 | AC34: =IF(ABS(AA34)<=ABS(AB34),"9EMA","21EMA") | AD34: 9EMA | AE34: 持續在上方 | AI34: 2026-09-11 | AJ34: 14 | AK34: 2 | AL34: 2026-09-22 | AM34: 190.89 | AN34: 161 | AO34: =IF(ISNUMBER(AN34),AM34/AN34-1,"") | AP34: 7 | AQ34: =IF(ISNUMBER(AM34),J34/AM34-1,"") | AR34: 215.05 | AS34: =J34/AR34-1 | AT34: 上傾收窄（楔形） | AU34: 0.4592 | AV34: 1.1583 | AW34: 0.5816 | AX34: 0.3701 | AY34: 2 | AZ34: 216.81 | BA34: 161 | BB34: 193.4577 | BC34: 0.8843 | BD34: =IF(M34=N34,0.5,(J34-N34)/(M34-N34)) | BE34: 22.165 | BF34: 17.411 | BG34: =100*(0.4*MIN(1,MAX(0,((U34*100)-(0.0))/((2.5)-(0.0))))+0.3*MIN(1,MAX(0,((V34)-(0.6))/((1.0)-(0.6))))+0.3*MIN(1,MAX(0,((BE34)-(0.0))/((15.0)-(0.0))))) | BH34: =100*(0.4*MIN(1,MAX(0,((MIN(ABS(AA34),ABS(AB34)))-(0.75))/((0.0)-(0.75))))+0.3*MIN(1,MAX(0,((BC34)-(1.2))/((0.6)-(1.2))))+0.3*BD34) | BI34: =100*(0.5*MIN(1,MAX(0,((AK34)-(1.0))/((4.0)-(1.0))))+0.3*MIN(1,MAX(0,((IF(ISNUMBER(AO34),AO34,0)*100)-(0.0))/((8.0)-(0.0))))+0.2*MIN(1,MAX(0,((IF(ISNUMBER(AP34),AP34,0))-(25.0))/((5.0)-(25.0))))) | BJ34: =100*(0.35*MIN(1,MAX(0,((ABS(AU34))-(0.3))/((0.05)-(0.3))))+0.3*MIN(1,MAX(0,((AV34)-(0.0))/((0.3)-(0.0))))+0.25*MIN(1,MAX(0,((AW34)-(0.4))/((0.7)-(0.4))))+0.1*IF(AY34>=2,1,0.5)) | BK34: =0.25*BG34+0.25*BH34+0.2*BI34+0.3*BJ34 | BL34: 全部通過
A35: 1 | B35: 34 | C35: OSPN | D35: OneSpan Inc. | E35: NASDAQ | F35: 科技 | G35: EDP Services | H35: 0.66 | I35: 小型 | J35: 18.04 | K35: 17.91 | L35: =J35/K35-1 | M35: 18.25 | N35: 17.58 | O35: 514100 | P35: 584265 | Q35: =O35/P35 | R35: 17.7902 | S35: 17.3836 | T35: 17.0675 | U35: =S35/T35-1 | V35: 1 | W35: =J35/R35-1 | X35: =J35/S35-1 | Y35: 0.5678 | Z35: =Y35/J35 | AA35: =(J35-R35)/Y35 | AB35: =(J35-S35)/Y35 | AC35: =IF(ABS(AA35)<=ABS(AB35),"9EMA","21EMA") | AD35: 9EMA | AE35: 持續在上方 | AH35: ✓ | AI35: 2026-08-27 | AJ35: 24 | AK35: 3 | AL35: 2026-09-22 | AM35: 17.05 | AN35: 15.97 | AO35: =IF(ISNUMBER(AN35),AM35/AN35-1,"") | AP35: 7 | AQ35: =IF(ISNUMBER(AM35),J35/AM35-1,"") | AR35: 18.04 | AS35: =J35/AR35-1 | AT35: 上傾收窄（楔形） | AU35: 0.4796 | AV35: 0.7483 | AW35: 0.6649 | AX35: 0.683 | AY35: 6 | AZ35: 18.25 | BA35: 15.58 | BB35: 17.3552 | BC35: 2.0453 | BD35: =IF(M35=N35,0.5,(J35-N35)/(M35-N35)) | BE35: 18.356 | BF35: 13.602 | BG35: =100*(0.4*MIN(1,MAX(0,((U35*100)-(0.0))/((2.5)-(0.0))))+0.3*MIN(1,MAX(0,((V35)-(0.6))/((1.0)-(0.6))))+0.3*MIN(1,MAX(0,((BE35)-(0.0))/((15.0)-(0.0))))) | BH35: =100*(0.4*MIN(1,MAX(0,((MIN(ABS(AA35),ABS(AB35)))-(0.75))/((0.0)-(0.75))))+0.3*MIN(1,MAX(0,((BC35)-(1.2))/((0.6)-(1.2))))+0.3*BD35) | BI35: =100*(0.5*MIN(1,MAX(0,((AK35)-(1.0))/((4.0)-(1.0))))+0.3*MIN(1,MAX(0,((IF(ISNUMBER(AO35),AO35,0)*100)-(0.0))/((8.0)-(0.0))))+0.2*MIN(1,MAX(0,((IF(ISNUMBER(AP35),AP35,0))-(25.0))/((5.0)-(25.0))))) | BJ35: =100*(0.35*MIN(1,MAX(0,((ABS(AU35))-(0.3))/((0.05)-(0.3))))+0.3*MIN(1,MAX(0,((AV35)-(0.0))/((0.3)-(0.0))))+0.25*MIN(1,MAX(0,((AW35)-(0.4))/((0.7)-(0.4))))+0.1*IF(AY35>=2,1,0.5)) | BK35: =0.25*BG35+0.25*BH35+0.2*BI35+0.3*BJ35 | BL35: 全部通過
