Workbook

Sheet 本版更新
A1: R4.00 更新重點
A2: 1 | B2: R4.00：加入 MACD（12/26/9）兩個核心條件 —— ⑤ 慢線（訊號線）高過前一日 ⑥ 柱狀圖動能轉勢：近 3 日內出現第一根「深紅之後嘅淺紅」或「淺綠之後嘅深綠」，其後每根都升（顏色跟 TradingView 四色柱）。連同 ① 21EMA 向上 ② 9EMA 在 21EMA 上 ③ 一底高於一底 ④ 上升三角重心偏上，六項全過＝第一梯隊。總表加咗 MACD、慢線、慢線斜率、三日柱值、柱顏色、轉勢種類／幾日前、柱顏色序列。
A3: 2 | B3: 三個分頁（引用總表）：a 剛黃金交叉（5 日內金叉）6 隻；b 回到 21EMA（離 EMA21 ≤3% 兼 ≤0.75 ATR 或近 3 日觸及）0 隻；c 回到 9EMA（同樣口徑對 EMA9，離兩條都近就歸較近嗰條）18 隻 —— 都係第一梯隊數目；每頁下方另加灰底第二梯隊（只差一項）同橙底第三梯隊（價格四項過、只差 MACD，共 71 隻）畀你候補。b 頁第一梯隊得零隻：回到 21EMA 嘅股票柱狀圖多數仲喺減速中、未出現第一根淺紅／深綠，候補嗰啲就係要等嘅名。
A4: 3 | B4: 數據更新至 2026-10-02 收市（193 個交易日，2025-12-26 起；Yahoo 日線由 GitHub Actions 抓取）。
A5: 4 | B5: 合資格 2,792 隻 → C1 630 → C2 597 → C3 368 → C4 97 → C5 MACD 慢線 44 → C6 柱轉勢 第一梯隊 26 隻（大型 9／中型 9／小型 7；平頂上升三角 10 隻）。第二梯隊（差一項）35 隻。
A6: 5 | B6: 排名：綜合分數 = 0.25 趨勢 + 0.25 回調質素 + 0.2 底部結構 + 0.3 三角形（每項 0–100，總表全部係公式）。頭五位：AMN（67）、SEI（65）、DDD（63）、FFIV（62）、ANET（62）。
A7: 6 | B7: 市況：10-02 就業轉弱（9 月只加 2.9 萬、失業率 4.2%）→ 10 月加息機率大減、債息油價齊回落、指數反彈；但闊度仍弱、10 年息仍 5.2% 樓上 —— 由「偏防守」升級為「審慎偏多」，只做 9/21EMA 回調、倉位由一半加至七成（市況頁有指數／ETF／商品／債息嘅 EMA 狀態、合資格股票池闊度、四大力量周期對標同領先指標觀察表）。
A8: 7 | B8: 頁：總表（兩個梯隊）、a 剛黃金交叉、b 回到21EMA、c 回到9EMA、大型股／中型股／小型股（引用總表）、差一項、樞軸底頂、篩選規則、市況、數據核對。所有代號連 TradingView；藍字係量度值、黑字係公式。
A9: 8 | B9: 產出：9EMA-Uptrend_Watchlist_R4.00_claudefable51xhigh_10.03_1043.xlsx（claudefable51xhigh = Claude Fable 5.1，effort xhigh；2026-10-03 10:43 香港時間）。

Sheet 總表
A1: 梯隊 | B1: 排名 | C1: 代號 | D1: 公司 | E1: 交易所 | F1: 板塊 | G1: 行業 | H1: 市值(十億美元) | I1: 市值組 | J1: 收市價 | K1: 前收 | L1: 當日% | M1: 當日高 | N1: 當日低 | O1: 成交量 | P1: 20日均量 | Q1: 量比 | R1: EMA9 | S1: EMA21 | T1: EMA21（5日前） | U1: EMA21 5日斜率% | V1: EMA21 10步上升比例 | W1: 距EMA9% | X1: 距EMA21% | Y1: ATR14 | Z1: ATR14% | AA1: 距EMA9（ATR倍） | AB1: 距EMA21（ATR倍） | AC1: 最接近 | AD1: 近3日低位觸及 | AE1: 9/21狀態 | AF1: a 剛金叉 | AG1: b 回到21EMA | AH1: c 回到9EMA | AI1: 金叉日期 | AJ1: 金叉後日數 | AK1: 連續上升底數目 | AL1: 最後一底日期 | AM1: 最後一底價 | AN1: 上一底價 | AO1: 底較底升% | AP1: 最後一底距今（日） | AQ1: 距最後一底% | AR1: 15日最高收市 | AS1: 距15日高% | AT1: MACD | AU1: MACD慢線 | AV1: 慢線（前日） | AW1: 慢線斜率 | AX1: 柱（今日） | AY1: 柱（前日） | AZ1: 柱（前2日） | BA1: 柱顏色 | BB1: 柱轉勢 | BC1: 轉勢幾日前 | BD1: 柱顏色序列（舊→新） | BE1: 形態（25日） | BF1: 高位斜率（%/日） | BG1: 低位斜率（%/日） | BH1: 重心（VWAP在25日高低區間位置） | BI1: 重心（收市範圍） | BJ1: 頂部觸及次數 | BK1: 25日最高 | BL1: 25日最低 | BM1: 25日VWAP | BN1: 跌日／升日量比（10日） | BO1: 收市在當日區間位置 | BP1: RS21（對全池中位數）% | BQ1: 21日回報% | BR1: 趨勢分數 | BS1: 回調質素 | BT1: 底部結構 | BU1: 三角形分數 | BV1: 綜合分數 | BW1: 唔過嘅條件 | BX1: 備註
A2: 1 | B2: 1 | C2: AMN | D2: AMN Healthcare Services Inc | E2: NYSE | F2: 非必需消費 | G2: Professional Services | H2: 1.389 | I2: 小型 | J2: 36.63 | K2: 35.86 | L2: =J2/K2-1 | M2: 36.9 | N2: 36.21 | O2: 887200 | P2: 637170 | Q2: =O2/P2 | R2: 35.289 | S2: 34.7366 | T2: 34.1968 | U2: =S2/T2-1 | V2: 0.9 | W2: =J2/R2-1 | X2: =J2/S2-1 | Y2: 1.2015 | Z2: =Y2/J2 | AA2: =(J2-R2)/Y2 | AB2: =(J2-S2)/Y2 | AC2: =IF(ABS(AA2)<=ABS(AB2),"9EMA","21EMA") | AD2: — | AE2: 持續在上方 | AI2: 2026-09-16 | AJ2: 12 | AK2: 3 | AL2: 2026-09-24 | AM2: 33.41 | AN2: 32.66 | AO2: =IF(ISNUMBER(AN2),AM2/AN2-1,"") | AP2: 6 | AQ2: =IF(ISNUMBER(AM2),J2/AM2-1,"") | AR2: 36.63 | AS2: =J2/AR2-1 | AT2: 0.4756 | AU2: 0.2509 | AV2: 0.1947 | AW2: =AU2-AV2 | AX2: 0.2247 | AY2: 0.1616 | AZ2: 0.1229 | BA2: 深綠 | BB2: 淺綠→深綠 | BC2: 3 | BD2: 淺綠 深綠 深綠 淺綠 深綠 深綠 深綠 深綠 | BE2: 上升三角（平頂） | BF2: -0.021 | BG2: 0.2567 | BH2: 0.5016 | BI2: 0.3974 | BJ2: 2 | BK2: 36.9 | BL2: 32.03 | BM2: 34.4728 | BN2: 0.5669 | BO2: =IF(M2=N2,0.5,(J2-N2)/(M2-N2)) | BP2: 14.777 | BQ2: 9.736 | BR2: =100*(0.4*MIN(1,MAX(0,((U2*100)-(0.0))/((2.5)-(0.0))))+0.3*MIN(1,MAX(0,((V2)-(0.6))/((1.0)-(0.6))))+0.3*MIN(1,MAX(0,((BP2)-(0.0))/((15.0)-(0.0))))) | BS2: =100*(0.4*MIN(1,MAX(0,((MIN(ABS(AA2),ABS(AB2)))-(0.75))/((0.0)-(0.75))))+0.3*MIN(1,MAX(0,((BN2)-(1.2))/((0.6)-(1.2))))+0.3*BO2) | BT2: =100*(0.5*MIN(1,MAX(0,((AK2)-(1.0))/((4.0)-(1.0))))+0.3*MIN(1,MAX(0,((IF(ISNUMBER(AO2),AO2,0)*100)-(0.0))/((8.0)-(0.0))))+0.2*MIN(1,MAX(0,((IF(ISNUMBER(AP2),AP2,0))-(25.0))/((5.0)-(25.0))))) | BU2: =100*(0.35*MIN(1,MAX(0,((ABS(BF2))-(0.3))/((0.05)-(0.3))))+0.3*MIN(1,MAX(0,((BG2)-(0.0))/((0.3)-(0.0))))+0.25*MIN(1,MAX(0,((BH2)-(0.4))/((0.7)-(0.4))))+0.1*IF(BJ2>=2,1,0.5)) | BV2: =0.25*BR2+0.25*BS2+0.2*BT2+0.3*BU2 | BW2: 全部通過
A3: 1 | B3: 2 | C3: SEI | D3: Solaris Energy Infrastructure Inc. | E3: NYSE | F3: 非必需消費 | G3: Oil and Gas Field Machinery | H3: 5.45 | I3: 中型 | J3: 74.93 | K3: 71.38 | L3: =J3/K3-1 | M3: 75.46 | N3: 72.19 | O3: 2870200 | P3: 2853615 | Q3: =O3/P3 | R3: 70.3182 | S3: 66.7953 | T3: 64.0582 | U3: =S3/T3-1 | V3: 1 | W3: =J3/R3-1 | X3: =J3/S3-1 | Y3: 4.0979 | Z3: =Y3/J3 | AA3: =(J3-R3)/Y3 | AB3: =(J3-S3)/Y3 | AC3: =IF(ABS(AA3)<=ABS(AB3),"9EMA","21EMA") | AD3: 9EMA | AE3: 持續在上方 | AI3: 2026-09-09 | AJ3: 17 | AK3: 3 | AL3: 2026-09-23 | AM3: 64.23 | AN3: 60.59 | AO3: =IF(ISNUMBER(AN3),AM3/AN3-1,"") | AP3: 7 | AQ3: =IF(ISNUMBER(AM3),J3/AM3-1,"") | AR3: 74.93 | AS3: =J3/AR3-1 | AT3: 3.5038 | AU3: 2.956 | AV3: 2.8191 | AW3: =AU3-AV3 | AX3: 0.5477 | AY3: 0.3936 | AZ3: 0.4351 | BA3: 深綠 | BB3: 淺綠→深綠 | BC3: 0 | BD3: 淺綠 淺綠 淺綠 淺綠 淺綠 淺綠 淺綠 深綠 | BE3: 上傾收窄（楔形） | BF3: 0.238 | BG3: 1.5653 | BH3: 0.6124 | BI3: 0.5972 | BJ3: 1 | BK3: 75.46 | BL3: 47.81 | BM3: 64.7421 | BN3: 1.1418 | BO3: =IF(M3=N3,0.5,(J3-N3)/(M3-N3)) | BP3: 47.035 | BQ3: 41.994 | BR3: =100*(0.4*MIN(1,MAX(0,((U3*100)-(0.0))/((2.5)-(0.0))))+0.3*MIN(1,MAX(0,((V3)-(0.6))/((1.0)-(0.6))))+0.3*MIN(1,MAX(0,((BP3)-(0.0))/((15.0)-(0.0))))) | BS3: =100*(0.4*MIN(1,MAX(0,((MIN(ABS(AA3),ABS(AB3)))-(0.75))/((0.0)-(0.75))))+0.3*MIN(1,MAX(0,((BN3)-(1.2))/((0.6)-(1.2))))+0.3*BO3) | BT3: =100*(0.5*MIN(1,MAX(0,((AK3)-(1.0))/((4.0)-(1.0))))+0.3*MIN(1,MAX(0,((IF(ISNUMBER(AO3),AO3,0)*100)-(0.0))/((8.0)-(0.0))))+0.2*MIN(1,MAX(0,((IF(ISNUMBER(AP3),AP3,0))-(25.0))/((5.0)-(25.0))))) | BU3: =100*(0.35*MIN(1,MAX(0,((ABS(BF3))-(0.3))/((0.05)-(0.3))))+0.3*MIN(1,MAX(0,((BG3)-(0.0))/((0.3)-(0.0))))+0.25*MIN(1,MAX(0,((BH3)-(0.4))/((0.7)-(0.4))))+0.1*IF(BJ3>=2,1,0.5)) | BV3: =0.25*BR3+0.25*BS3+0.2*BT3+0.3*BU3 | BW3: 全部通過
A4: 1 | B4: 3 | C4: DDD | D4: 3D Systems Corporation | E4: NYSE | F4: 科技 | G4: Computer Software: Prepackaged Software | H4: 0.598 | I4: 小型 | J4: 3.78 | K4: 3.54 | L4: =J4/K4-1 | M4: 3.78 | N4: 3.57 | O4: 3224800 | P4: 2286085 | Q4: =O4/P4 | R4: 3.569 | S4: 3.4791 | T4: 3.4037 | U4: =S4/T4-1 | V4: 1 | W4: =J4/R4-1 | X4: =J4/S4-1 | Y4: 0.2031 | Z4: =Y4/J4 | AA4: =(J4-R4)/Y4 | AB4: =(J4-S4)/Y4 | AC4: =IF(ABS(AA4)<=ABS(AB4),"9EMA","21EMA") | AD4: 9+21EMA | AE4: 持續在上方 | AI4: 2026-09-17 | AJ4: 11 | AK4: 2 | AL4: 2026-09-25 | AM4: 3.35 | AN4: 3.1 | AO4: =IF(ISNUMBER(AN4),AM4/AN4-1,"") | AP4: 5 | AQ4: =IF(ISNUMBER(AM4),J4/AM4-1,"") | AR4: 3.78 | AS4: =J4/AR4-1 | AT4: 0.0883 | AU4: 0.0669 | AV4: 0.0616 | AW4: =AU4-AV4 | AX4: 0.0214 | AY4: 0.0094 | AZ4: 0.013 | BA4: 深綠 | BB4: 淺綠→深綠 | BC4: 0 | BD4: 淺綠 淺綠 深綠 淺綠 淺綠 深綠 淺綠 深綠 | BE4: 上傾收窄（楔形） | BF4: 0.3118 | BG4: 0.9448 | BH4: 0.5228 | BI4: 0.493 | BJ4: 2 | BK4: 3.78 | BL4: 3.1 | BM4: 3.4555 | BN4: 0.92 | BO4: =IF(M4=N4,0.5,(J4-N4)/(M4-N4)) | BP4: 16.875 | BQ4: 11.834 | BR4: =100*(0.4*MIN(1,MAX(0,((U4*100)-(0.0))/((2.5)-(0.0))))+0.3*MIN(1,MAX(0,((V4)-(0.6))/((1.0)-(0.6))))+0.3*MIN(1,MAX(0,((BP4)-(0.0))/((15.0)-(0.0))))) | BS4: =100*(0.4*MIN(1,MAX(0,((MIN(ABS(AA4),ABS(AB4)))-(0.75))/((0.0)-(0.75))))+0.3*MIN(1,MAX(0,((BN4)-(1.2))/((0.6)-(1.2))))+0.3*BO4) | BT4: =100*(0.5*MIN(1,MAX(0,((AK4)-(1.0))/((4.0)-(1.0))))+0.3*MIN(1,MAX(0,((IF(ISNUMBER(AO4),AO4,0)*100)-(0.0))/((8.0)-(0.0))))+0.2*MIN(1,MAX(0,((IF(ISNUMBER(AP4),AP4,0))-(25.0))/((5.0)-(25.0))))) | BU4: =100*(0.35*MIN(1,MAX(0,((ABS(BF4))-(0.3))/((0.05)-(0.3))))+0.3*MIN(1,MAX(0,((BG4)-(0.0))/((0.3)-(0.0))))+0.25*MIN(1,MAX(0,((BH4)-(0.4))/((0.7)-(0.4))))+0.1*IF(BJ4>=2,1,0.5)) | BV4: =0.25*BR4+0.25*BS4+0.2*BT4+0.3*BU4 | BW4: 全部通過
A5: 1 | B5: 4 | C5: FFIV | D5: F5 Inc. | E5: NASDAQ | F5: 電訊 | G5: Computer Communications Equipment | H5: 25.209 | I5: 大型 | J5: 454.04 | K5: 443.68 | L5: =J5/K5-1 | M5: 459.88 | N5: 446.13 | O5: 633200 | P5: 563155 | Q5: =O5/P5 | R5: 443.1567 | S5: 431.9116 | T5: 424.4576 | U5: =S5/T5-1 | V5: 1 | W5: =J5/R5-1 | X5: =J5/S5-1 | Y5: 13.6727 | Z5: =Y5/J5 | AA5: =(J5-R5)/Y5 | AB5: =(J5-S5)/Y5 | AC5: =IF(ABS(AA5)<=ABS(AB5),"9EMA","21EMA") | AD5: 9EMA | AE5: 持續在上方 | AH5: ✓ | AI5: 2026-09-11 | AJ5: 15 | AK5: 3 | AL5: 2026-09-29 | AM5: 428.93 | AN5: 384.95 | AO5: =IF(ISNUMBER(AN5),AM5/AN5-1,"") | AP5: 3 | AQ5: =IF(ISNUMBER(AM5),J5/AM5-1,"") | AR5: 455.99 | AS5: =J5/AR5-1 | AT5: 11.906 | AU5: 11.0672 | AV5: 10.8575 | AW5: =AU5-AV5 | AX5: 0.8388 | AY5: 0.5942 | AZ5: 1.0512 | BA5: 深綠 | BB5: 淺綠→深綠 | BC5: 0 | BD5: 深綠 淺綠 淺綠 淺綠 淺綠 淺綠 淺綠 深綠 | BE5: 上升通道 | BF5: 0.6261 | BG5: 0.5381 | BH5: 0.5245 | BI5: 0.5385 | BJ5: 3 | BK5: 462 | BL5: 384.95 | BM5: 425.36 | BN5: 0.9017 | BO5: =IF(M5=N5,0.5,(J5-N5)/(M5-N5)) | BP5: 21.14 | BQ5: 16.099 | BR5: =100*(0.4*MIN(1,MAX(0,((U5*100)-(0.0))/((2.5)-(0.0))))+0.3*MIN(1,MAX(0,((V5)-(0.6))/((1.0)-(0.6))))+0.3*MIN(1,MAX(0,((BP5)-(0.0))/((15.0)-(0.0))))) | BS5: =100*(0.4*MIN(1,MAX(0,((MIN(ABS(AA5),ABS(AB5)))-(0.75))/((0.0)-(0.75))))+0.3*MIN(1,MAX(0,((BN5)-(1.2))/((0.6)-(1.2))))+0.3*BO5) | BT5: =100*(0.5*MIN(1,MAX(0,((AK5)-(1.0))/((4.0)-(1.0))))+0.3*MIN(1,MAX(0,((IF(ISNUMBER(AO5),AO5,0)*100)-(0.0))/((8.0)-(0.0))))+0.2*MIN(1,MAX(0,((IF(ISNUMBER(AP5),AP5,0))-(25.0))/((5.0)-(25.0))))) | BU5: =100*(0.35*MIN(1,MAX(0,((ABS(BF5))-(0.3))/((0.05)-(0.3))))+0.3*MIN(1,MAX(0,((BG5)-(0.0))/((0.3)-(0.0))))+0.25*MIN(1,MAX(0,((BH5)-(0.4))/((0.7)-(0.4))))+0.1*IF(BJ5>=2,1,0.5)) | BV5: =0.25*BR5+0.25*BS5+0.2*BT5+0.3*BU5 | BW5: 全部通過
A6: 1 | B6: 5 | C6: ANET | D6: Arista Networks Inc. | E6: NYSE | F6: 電訊 | G6: Computer Communications Equipment | H6: 256.773 | I6: 大型 | J6: 207.35 | K6: 204.49 | L6: =J6/K6-1 | M6: 208.632 | N6: 204.66 | O6: 4145600 | P6: 4783005 | Q6: =O6/P6 | R6: 204.0727 | S6: 200.6033 | T6: 198.0568 | U6: =S6/T6-1 | V6: 1 | W6: =J6/R6-1 | X6: =J6/S6-1 | Y6: 6.86 | Z6: =Y6/J6 | AA6: =(J6-R6)/Y6 | AB6: =(J6-S6)/Y6 | AC6: =IF(ABS(AA6)<=ABS(AB6),"9EMA","21EMA") | AD6: 9+21EMA | AE6: 持續在上方 | AH6: ✓ | AI6: 2026-07-31 | AJ6: 44 | AK6: 3 | AL6: 2026-09-24 | AM6: 198.757 | AN6: 186.11 | AO6: =IF(ISNUMBER(AN6),AM6/AN6-1,"") | AP6: 6 | AQ6: =IF(ISNUMBER(AM6),J6/AM6-1,"") | AR6: 207.35 | AS6: =J6/AR6-1 | AT6: 3.8867 | AU6: 3.7117 | AV6: 3.668 | AW6: =AU6-AV6 | AX6: 0.175 | AY6: 0.1031 | AZ6: 0.2175 | BA6: 深綠 | BB6: 淺綠→深綠 | BC6: 0 | BD6: 淺綠 深綠 深綠 淺綠 淺綠 淺綠 淺綠 深綠 | BE6: 上傾收窄（楔形） | BF6: 0.4201 | BG6: 0.611 | BH6: 0.553 | BI6: 0.5724 | BJ6: 1 | BK6: 212 | BL6: 181.27 | BM6: 198.2633 | BN6: 0.9529 | BO6: =IF(M6=N6,0.5,(J6-N6)/(M6-N6)) | BP6: 16.46 | BQ6: 11.419 | BR6: =100*(0.4*MIN(1,MAX(0,((U6*100)-(0.0))/((2.5)-(0.0))))+0.3*MIN(1,MAX(0,((V6)-(0.6))/((1.0)-(0.6))))+0.3*MIN(1,MAX(0,((BP6)-(0.0))/((15.0)-(0.0))))) | BS6: =100*(0.4*MIN(1,MAX(0,((MIN(ABS(AA6),ABS(AB6)))-(0.75))/((0.0)-(0.75))))+0.3*MIN(1,MAX(0,((BN6)-(1.2))/((0.6)-(1.2))))+0.3*BO6) | BT6: =100*(0.5*MIN(1,MAX(0,((AK6)-(1.0))/((4.0)-(1.0))))+0.3*MIN(1,MAX(0,((IF(ISNUMBER(AO6),AO6,0)*100)-(0.0))/((8.0)-(0.0))))+0.2*MIN(1,MAX(0,((IF(ISNUMBER(AP6),AP6,0))-(25.0))/((5.0)-(25.0))))) | BU6: =100*(0.35*MIN(1,MAX(0,((ABS(BF6))-(0.3))/((0.05)-(0.3))))+0.3*MIN(1,MAX(0,((BG6)-(0.0))/((0.3)-(0.0))))+0.25*MIN(1,MAX(0,((BH6)-(0.4))/((0.7)-(0.4))))+0.1*IF(BJ6>=2,1,0.5)) | BV6: =0.25*BR6+0.25*BS6+0.2*BT6+0.3*BU6 | BW6: 全部通過
A7: 1 | B7: 6 | C7: FTNT | D7: Fortinet Inc. | E7: NASDAQ | F7: 科技 | G7: Computer peripheral equipment | H7: 131.159 | I7: 大型 | J7: 180.95 | K7: 178.72 | L7: =J7/K7-1 | M7: 183.09 | N7: 180.04 | O7: 3412200 | P7: 3976270 | Q7: =O7/P7 | R7: 176.8402 | S7: 172.0605 | T7: 168.2061 | U7: =S7/T7-1 | V7: 1 | W7: =J7/R7-1 | X7: =J7/S7-1 | Y7: 6.3068 | Z7: =Y7/J7 | AA7: =(J7-R7)/Y7 | AB7: =(J7-S7)/Y7 | AC7: =IF(ABS(AA7)<=ABS(AB7),"9EMA","21EMA") | AD7: 9EMA | AE7: 持續在上方 | AH7: ✓ | AI7: 2026-09-14 | AJ7: 14 | AK7: 4 | AL7: 2026-09-28 | AM7: 169.56 | AN7: 166.09 | AO7: =IF(ISNUMBER(AN7),AM7/AN7-1,"") | AP7: 4 | AQ7: =IF(ISNUMBER(AM7),J7/AM7-1,"") | AR7: 180.95 | AS7: =J7/AR7-1 | AT7: 4.9944 | AU7: 4.4384 | AV7: 4.2994 | AW7: =AU7-AV7 | AX7: 0.5559 | AY7: 0.5413 | AZ7: 0.6371 | BA7: 深綠 | BB7: 淺綠→深綠 | BC7: 0 | BD7: 深綠 淺綠 淺綠 淺綠 淺綠 淺綠 淺綠 深綠 | BE7: 上升通道 | BF7: 0.5825 | BG7: 0.5947 | BH7: 0.5457 | BI7: 0.5428 | BJ7: 3 | BK7: 183.09 | BL7: 151.8 | BM7: 168.8756 | BN7: 0.9929 | BO7: =IF(M7=N7,0.5,(J7-N7)/(M7-N7)) | BP7: 22.13 | BQ7: 17.089 | BR7: =100*(0.4*MIN(1,MAX(0,((U7*100)-(0.0))/((2.5)-(0.0))))+0.3*MIN(1,MAX(0,((V7)-(0.6))/((1.0)-(0.6))))+0.3*MIN(1,MAX(0,((BP7)-(0.0))/((15.0)-(0.0))))) | BS7: =100*(0.4*MIN(1,MAX(0,((MIN(ABS(AA7),ABS(AB7)))-(0.75))/((0.0)-(0.75))))+0.3*MIN(1,MAX(0,((BN7)-(1.2))/((0.6)-(1.2))))+0.3*BO7) | BT7: =100*(0.5*MIN(1,MAX(0,((AK7)-(1.0))/((4.0)-(1.0))))+0.3*MIN(1,MAX(0,((IF(ISNUMBER(AO7),AO7,0)*100)-(0.0))/((8.0)-(0.0))))+0.2*MIN(1,MAX(0,((IF(ISNUMBER(AP7),AP7,0))-(25.0))/((5.0)-(25.0))))) | BU7: =100*(0.35*MIN(1,MAX(0,((ABS(BF7))-(0.3))/((0.05)-(0.3))))+0.3*MIN(1,MAX(0,((BG7)-(0.0))/((0.3)-(0.0))))+0.25*MIN(1,MAX(0,((BH7)-(0.4))/((0.7)-(0.4))))+0.1*IF(BJ7>=2,1,0.5)) | BV7: =0.25*BR7+0.25*BS7+0.2*BT7+0.3*BU7 | BW7: 全部通過
A8: 1 | B8: 7 | C8: PANW | D8: Palo Alto Networks Inc. | E8: NASDAQ | F8: 科技 | G8: Computer peripheral equipment | H8: 325 | I8: 大型 | J8: 403.24 | K8: 396.25 | L8: =J8/K8-1 | M8: 409.5 | N8: 399.95 | O8: 4904700 | P8: 6269560 | Q8: =O8/P8 | R8: 389.6546 | S8: 377.5477 | T8: 366.2564 | U8: =S8/T8-1 | V8: 1 | W8: =J8/R8-1 | X8: =J8/S8-1 | Y8: 17.2522 | Z8: =Y8/J8 | AA8: =(J8-R8)/Y8 | AB8: =(J8-S8)/Y8 | AC8: =IF(ABS(AA8)<=ABS(AB8),"9EMA","21EMA") | AD8: 9EMA | AE8: 持續在上方 | AI8: 2026-09-15 | AJ8: 13 | AK8: 3 | AL8: 2026-09-28 | AM8: 367.27 | AN8: 356 | AO8: =IF(ISNUMBER(AN8),AM8/AN8-1,"") | AP8: 4 | AQ8: =IF(ISNUMBER(AM8),J8/AM8-1,"") | AR8: 403.24 | AS8: =J8/AR8-1 | AT8: 11.6713 | AU8: 8.7792 | AV8: 8.0561 | AW8: =AU8-AV8 | AX8: 2.8921 | AY8: 2.7769 | AZ8: 2.9553 | BA8: 深綠 | BB8: 淺綠→深綠 | BC8: 0 | BD8: 深綠 深綠 淺綠 深綠 淺綠 深綠 淺綠 深綠 | BE8: 上升通道 | BF8: 0.6537 | BG8: 0.683 | BH8: 0.5102 | BI8: 0.5065 | BJ8: 2 | BK8: 409.5 | BL8: 321.39 | BM8: 366.3431 | BN8: 0.7854 | BO8: =IF(M8=N8,0.5,(J8-N8)/(M8-N8)) | BP8: 27.8 | BQ8: 22.759 | BR8: =100*(0.4*MIN(1,MAX(0,((U8*100)-(0.0))/((2.5)-(0.0))))+0.3*MIN(1,MAX(0,((V8)-(0.6))/((1.0)-(0.6))))+0.3*MIN(1,MAX(0,((BP8)-(0.0))/((15.0)-(0.0))))) | BS8: =100*(0.4*MIN(1,MAX(0,((MIN(ABS(AA8),ABS(AB8)))-(0.75))/((0.0)-(0.75))))+0.3*MIN(1,MAX(0,((BN8)-(1.2))/((0.6)-(1.2))))+0.3*BO8) | BT8: =100*(0.5*MIN(1,MAX(0,((AK8)-(1.0))/((4.0)-(1.0))))+0.3*MIN(1,MAX(0,((IF(ISNUMBER(AO8),AO8,0)*100)-(0.0))/((8.0)-(0.0))))+0.2*MIN(1,MAX(0,((IF(ISNUMBER(AP8),AP8,0))-(25.0))/((5.0)-(25.0))))) | BU8: =100*(0.35*MIN(1,MAX(0,((ABS(BF8))-(0.3))/((0.05)-(0.3))))+0.3*MIN(1,MAX(0,((BG8)-(0.0))/((0.3)-(0.0))))+0.25*MIN(1,MAX(0,((BH8)-(0.4))/((0.7)-(0.4))))+0.1*IF(BJ8>=2,1,0.5)) | BV8: =0.25*BR8+0.25*BS8+0.2*BT8+0.3*BU8 | BW8: 全部通過
A9: 1 | B9: 8 | C9: NEU | D9: NewMarket Corp | E9: NYSE | F9: 工業 | G9: Major Chemicals | H9: 8.254 | I9: 中型 | J9: 924.06 | K9: 921.14 | L9: =J9/K9-1 | M9: 929.74 | N9: 913.15 | O9: 113500 | P9: 121270 | Q9: =O9/P9 | R9: 906.476 | S9: 899.7516 | T9: 891.8104 | U9: =S9/T9-1 | V9: 0.7 | W9: =J9/R9-1 | X9: =J9/S9-1 | Y9: 22.764 | Z9: =Y9/J9 | AA9: =(J9-R9)/Y9 | AB9: =(J9-S9)/Y9 | AC9: =IF(ABS(AA9)<=ABS(AB9),"9EMA","21EMA") | AD9: 9+21EMA | AE9: 剛黃金交叉 | AF9: ✓ | AH9: ✓ | AI9: 2026-09-28 | AJ9: 4 | AK9: 4 | AL9: 2026-09-22 | AM9: 874.71 | AN9: 833.43 | AO9: =IF(ISNUMBER(AN9),AM9/AN9-1,"") | AP9: 8 | AQ9: =IF(ISNUMBER(AM9),J9/AM9-1,"") | AR9: 924.06 | AS9: =J9/AR9-1 | AT9: 6.2616 | AU9: 3.3488 | AV9: 2.6206 | AW9: =AU9-AV9 | AX9: 2.9128 | AY9: 2.0799 | AZ9: 0.8363 | BA9: 深綠 | BB9: 淺綠→深綠 | BC9: 1 | BD9: 淺紅 淺紅 淺紅 深綠 深綠 淺綠 深綠 深綠 | BE9: 上升三角（平頂） | BF9: 0.0163 | BG9: 0.4964 | BH9: 0.5851 | BI9: 0.5102 | BJ9: 3 | BK9: 936.77 | BL9: 833.43 | BM9: 893.8933 | BN9: 0.9945 | BO9: =IF(M9=N9,0.5,(J9-N9)/(M9-N9)) | BP9: 6.681 | BQ9: 1.64 | BR9: =100*(0.4*MIN(1,MAX(0,((U9*100)-(0.0))/((2.5)-(0.0))))+0.3*MIN(1,MAX(0,((V9)-(0.6))/((1.0)-(0.6))))+0.3*MIN(1,MAX(0,((BP9)-(0.0))/((15.0)-(0.0))))) | BS9: =100*(0.4*MIN(1,MAX(0,((MIN(ABS(AA9),ABS(AB9)))-(0.75))/((0.0)-(0.75))))+0.3*MIN(1,MAX(0,((BN9)-(1.2))/((0.6)-(1.2))))+0.3*BO9) | BT9: =100*(0.5*MIN(1,MAX(0,((AK9)-(1.0))/((4.0)-(1.0))))+0.3*MIN(1,MAX(0,((IF(ISNUMBER(AO9),AO9,0)*100)-(0.0))/((8.0)-(0.0))))+0.2*MIN(1,MAX(0,((IF(ISNUMBER(AP9),AP9,0))-(25.0))/((5.0)-(25.0))))) | BU9: =100*(0.35*MIN(1,MAX(0,((ABS(BF9))-(0.3))/((0.05)-(0.3))))+0.3*MIN(1,MAX(0,((BG9)-(0.0))/((0.3)-(0.0))))+0.25*MIN(1,MAX(0,((BH9)-(0.4))/((0.7)-(0.4))))+0.1*IF(BJ9>=2,1,0.5)) | BV9: =0.25*BR9+0.25*BS9+0.2*BT9+0.3*BU9 | BW9: 全部通過
A10: 1 | B10: 9 | C10: HNGE | D10: Hinge Health Inc. | E10: NYSE | F10: 科技 | G10: EDP Services | H10: 7.847 | I10: 中型 | J10: 97.67 | K10: 97.94 | L10: =J10/K10-1 | M10: 99.73 | N10: 96.95 | O10: 975300 | P10: 1797980 | Q10: =O10/P10 | R10: 95.6008 | S10: 93.6582 | T10: 92.0176 | U10: =S10/T10-1 | V10: 1 | W10: =J10/R10-1 | X10: =J10/S10-1 | Y10: 4.0328 | Z10: =Y10/J10 | AA10: =(J10-R10)/Y10 | AB10: =(J10-S10)/Y10 | AC10: =IF(ABS(AA10)<=ABS(AB10),"9EMA","21EMA") | AD10: 9EMA | AE10: 持續在上方 | AH10: ✓ | AI10: 2026-08-07 | AJ10: 39 | AK10: 5 | AL10: 2026-09-23 | AM10: 89.75 | AN10: 86.29 | AO10: =IF(ISNUMBER(AN10),AM10/AN10-1,"") | AP10: 7 | AQ10: =IF(ISNUMBER(AM10),J10/AM10-1,"") | AR10: 97.94 | AS10: =J10/AR10-1 | AT10: 2.1522 | AU10: 1.9662 | AV10: 1.9197 | AW10: =AU10-AV10 | AX10: 0.186 | AY10: 0.1384 | AZ10: -0.0045 | BA10: 深綠 | BB10: 深紅→淺紅 | BC10: 3 | BD10: 深紅 深紅 淺紅 深紅 淺紅 淺紅 深綠 深綠 | BE10: 上升通道 | BF10: 0.2509 | BG10: 0.256 | BH10: 0.5031 | BI10: 0.5131 | BJ10: 3 | BK10: 99.73 | BL10: 85.75 | BM10: 92.7834 | BN10: 0.9903 | BO10: =IF(M10=N10,0.5,(J10-N10)/(M10-N10)) | BP10: 11.377 | BQ10: 6.336 | BR10: =100*(0.4*MIN(1,MAX(0,((U10*100)-(0.0))/((2.5)-(0.0))))+0.3*MIN(1,MAX(0,((V10)-(0.6))/((1.0)-(0.6))))+0.3*MIN(1,MAX(0,((BP10)-(0.0))/((15.0)-(0.0))))) | BS10: =100*(0.4*MIN(1,MAX(0,((MIN(ABS(AA10),ABS(AB10)))-(0.75))/((0.0)-(0.75))))+0.3*MIN(1,MAX(0,((BN10)-(1.2))/((0.6)-(1.2))))+0.3*BO10) | BT10: =100*(0.5*MIN(1,MAX(0,((AK10)-(1.0))/((4.0)-(1.0))))+0.3*MIN(1,MAX(0,((IF(ISNUMBER(AO10),AO10,0)*100)-(0.0))/((8.0)-(0.0))))+0.2*MIN(1,MAX(0,((IF(ISNUMBER(AP10),AP10,0))-(25.0))/((5.0)-(25.0))))) | BU10: =100*(0.35*MIN(1,MAX(0,((ABS(BF10))-(0.3))/((0.05)-(0.3))))+0.3*MIN(1,MAX(0,((BG10)-(0.0))/((0.3)-(0.0))))+0.25*MIN(1,MAX(0,((BH10)-(0.4))/((0.7)-(0.4))))+0.1*IF(BJ10>=2,1,0.5)) | BV10: =0.25*BR10+0.25*BS10+0.2*BT10+0.3*BU10 | BW10: 全部通過
A11: 1 | B11: 10 | C11: QLYS | D11: Qualys Inc. | E11: NASDAQ | F11: 科技 | G11: Computer Software: Prepackaged Software | H11: 6.476 | I11: 中型 | J11: 193 | K11: 187.43 | L11: =J11/K11-1 | M11: 195.4 | N11: 188.87 | O11: 477400 | P11: 728015 | Q11: =O11/P11 | R11: 183.5015 | S11: 179.8278 | T11: 176.7577 | U11: =S11/T11-1 | V11: 0.8 | W11: =J11/R11-1 | X11: =J11/S11-1 | Y11: 9.0911 | Z11: =Y11/J11 | AA11: =(J11-R11)/Y11 | AB11: =(J11-S11)/Y11 | AC11: =IF(ABS(AA11)<=ABS(AB11),"9EMA","21EMA") | AD11: 9+21EMA | AE11: 持續在上方 | AI11: 2026-09-16 | AJ11: 12 | AK11: 2 | AL11: 2026-09-28 | AM11: 168.06 | AN11: 149.13 | AO11: =IF(ISNUMBER(AN11),AM11/AN11-1,"") | AP11: 4 | AQ11: =IF(ISNUMBER(AM11),J11/AM11-1,"") | AR11: 193 | AS11: =J11/AR11-1 | AT11: 3.5893 | AU11: 2.4661 | AV11: 2.1853 | AW11: =AU11-AV11 | AX11: 1.1232 | AY11: 0.5936 | AZ11: 0.2344 | BA11: 深綠 | BB11: 深紅→淺紅 | BC11: 3 | BD11: 深綠 深綠 深紅 深紅 淺紅 深綠 深綠 深綠 | BE11: 上傾收窄（楔形） | BF11: 0.2221 | BG11: 0.8917 | BH11: 0.5866 | BI11: 0.6085 | BJ11: 1 | BK11: 195.4 | BL11: 149.13 | BM11: 176.2734 | BN11: 0.8695 | BO11: =IF(M11=N11,0.5,(J11-N11)/(M11-N11)) | BP11: 18.019 | BQ11: 12.978 | BR11: =100*(0.4*MIN(1,MAX(0,((U11*100)-(0.0))/((2.5)-(0.0))))+0.3*MIN(1,MAX(0,((V11)-(0.6))/((1.0)-(0.6))))+0.3*MIN(1,MAX(0,((BP11)-(0.0))/((15.0)-(0.0))))) | BS11: =100*(0.4*MIN(1,MAX(0,((MIN(ABS(AA11),ABS(AB11)))-(0.75))/((0.0)-(0.75))))+0.3*MIN(1,MAX(0,((BN11)-(1.2))/((0.6)-(1.2))))+0.3*BO11) | BT11: =100*(0.5*MIN(1,MAX(0,((AK11)-(1.0))/((4.0)-(1.0))))+0.3*MIN(1,MAX(0,((IF(ISNUMBER(AO11),AO11,0)*100)-(0.0))/((8.0)-(0.0))))+0.2*MIN(1,MAX(0,((IF(ISNUMBER(AP11),AP11,0))-(25.0))/((5.0)-(25.0))))) | BU11: =100*(0.35*MIN(1,MAX(0,((ABS(BF11))-(0.3))/((0.05)-(0.3))))+0.3*MIN(1,MAX(0,((BG11)-(0.0))/((0.3)-(0.0))))+0.25*MIN(1,MAX(0,((BH11)-(0.4))/((0.7)-(0.4))))+0.1*IF(BJ11>=2,1,0.5)) | BV11: =0.25*BR11+0.25*BS11+0.2*BT11+0.3*BU11 | BW11: 全部通過
A12: 1 | B12: 11 | C12: CNXN | D12: PC Connection Inc. | E12: NASDAQ | F12: 非必需消費 | G12: Catalog/Specialty Distribution | H12: 2.277 | I12: 中型 | J12: 92.38 | K12: 92.57 | L12: =J12/K12-1 | M12: 93.89 | N12: 92.27 | O12: 124200 | P12: 146260 | Q12: =O12/P12 | R12: 89.9544 | S12: 87.4047 | T12: 85.1881 | U12: =S12/T12-1 | V12: 1 | W12: =J12/R12-1 | X12: =J12/S12-1 | Y12: 2.296 | Z12: =Y12/J12 | AA12: =(J12-R12)/Y12 | AB12: =(J12-S12)/Y12 | AC12: =IF(ABS(AA12)<=ABS(AB12),"9EMA","21EMA") | AD12: 9EMA | AE12: 持續在上方 | AH12: ✓ | AI12: 2026-09-03 | AJ12: 20 | AK12: 3 | AL12: 2026-09-18 | AM12: 84.11 | AN12: 77.98 | AO12: =IF(ISNUMBER(AN12),AM12/AN12-1,"") | AP12: 10 | AQ12: =IF(ISNUMBER(AM12),J12/AM12-1,"") | AR12: 92.57 | AS12: =J12/AR12-1 | AT12: 2.5942 | AU12: 2.1766 | AV12: 2.0722 | AW12: =AU12-AV12 | AX12: 0.4176 | AY12: 0.4065 | AZ12: 0.3055 | BA12: 深綠 | BB12: 淺綠→深綠 | BC12: 1 | BD12: 深綠 深綠 深綠 淺綠 淺綠 淺綠 深綠 深綠 | BE12: 上升通道 | BF12: 0.5602 | BG12: 0.553 | BH12: 0.5245 | BI12: 0.5159 | BJ12: 2 | BK12: 93.89 | BL12: 77.98 | BM12: 86.3246 | BN12: 0.9912 | BO12: =IF(M12=N12,0.5,(J12-N12)/(M12-N12)) | BP12: 19.133 | BQ12: 14.092 | BR12: =100*(0.4*MIN(1,MAX(0,((U12*100)-(0.0))/((2.5)-(0.0))))+0.3*MIN(1,MAX(0,((V12)-(0.6))/((1.0)-(0.6))))+0.3*MIN(1,MAX(0,((BP12)-(0.0))/((15.0)-(0.0))))) | BS12: =100*(0.4*MIN(1,MAX(0,((MIN(ABS(AA12),ABS(AB12)))-(0.75))/((0.0)-(0.75))))+0.3*MIN(1,MAX(0,((BN12)-(1.2))/((0.6)-(1.2))))+0.3*BO12) | BT12: =100*(0.5*MIN(1,MAX(0,((AK12)-(1.0))/((4.0)-(1.0))))+0.3*MIN(1,MAX(0,((IF(ISNUMBER(AO12),AO12,0)*100)-(0.0))/((8.0)-(0.0))))+0.2*MIN(1,MAX(0,((IF(ISNUMBER(AP12),AP12,0))-(25.0))/((5.0)-(25.0))))) | BU12: =100*(0.35*MIN(1,MAX(0,((ABS(BF12))-(0.3))/((0.05)-(0.3))))+0.3*MIN(1,MAX(0,((BG12)-(0.0))/((0.3)-(0.0))))+0.25*MIN(1,MAX(0,((BH12)-(0.4))/((0.7)-(0.4))))+0.1*IF(BJ12>=2,1,0.5)) | BV12: =0.25*BR12+0.25*BS12+0.2*BT12+0.3*BU12 | BW12: 全部通過
A13: 1 | B13: 12 | C13: CRVL | D13: CorVel Corp. | E13: NASDAQ | F13: 金融 | G13: Specialty Insurers | H13: 3.766 | I13: 中型 | J13: 75.47 | K13: 74.72 | L13: =J13/K13-1 | M13: 76 | N13: 74.37 | O13: 168800 | P13: 224250 | Q13: =O13/P13 | R13: 74.0124 | S13: 72.2092 | T13: 70.7026 | U13: =S13/T13-1 | V13: 1 | W13: =J13/R13-1 | X13: =J13/S13-1 | Y13: 1.7655 | Z13: =Y13/J13 | AA13: =(J13-R13)/Y13 | AB13: =(J13-S13)/Y13 | AC13: =IF(ABS(AA13)<=ABS(AB13),"9EMA","21EMA") | AD13: 9EMA | AE13: 持續在上方 | AH13: ✓ | AI13: 2026-08-06 | AJ13: 40 | AK13: 2 | AL13: 2026-09-18 | AM13: 69.15 | AN13: 65.18 | AO13: =IF(ISNUMBER(AN13),AM13/AN13-1,"") | AP13: 10 | AQ13: =IF(ISNUMBER(AM13),J13/AM13-1,"") | AR13: 75.47 | AS13: =J13/AR13-1 | AT13: 1.9798 | AU13: 1.8442 | AV13: 1.8103 | AW13: =AU13-AV13 | AX13: 0.1356 | AY13: 0.13 | AZ13: 0.1602 | BA13: 深綠 | BB13: 淺綠→深綠 | BC13: 0 | BD13: 深綠 深綠 深綠 淺綠 淺綠 淺綠 淺綠 深綠 | BE13: 上傾收窄（楔形） | BF13: 0.2766 | BG13: 0.7515 | BH13: 0.5653 | BI13: 0.5378 | BJ13: 5 | BK13: 76 | BL13: 65.18 | BM13: 71.2961 | BN13: 1.0296 | BO13: =IF(M13=N13,0.5,(J13-N13)/(M13-N13)) | BP13: 12.258 | BQ13: 7.217 | BR13: =100*(0.4*MIN(1,MAX(0,((U13*100)-(0.0))/((2.5)-(0.0))))+0.3*MIN(1,MAX(0,((V13)-(0.6))/((1.0)-(0.6))))+0.3*MIN(1,MAX(0,((BP13)-(0.0))/((15.0)-(0.0))))) | BS13: =100*(0.4*MIN(1,MAX(0,((MIN(ABS(AA13),ABS(AB13)))-(0.75))/((0.0)-(0.75))))+0.3*MIN(1,MAX(0,((BN13)-(1.2))/((0.6)-(1.2))))+0.3*BO13) | BT13: =100*(0.5*MIN(1,MAX(0,((AK13)-(1.0))/((4.0)-(1.0))))+0.3*MIN(1,MAX(0,((IF(ISNUMBER(AO13),AO13,0)*100)-(0.0))/((8.0)-(0.0))))+0.2*MIN(1,MAX(0,((IF(ISNUMBER(AP13),AP13,0))-(25.0))/((5.0)-(25.0))))) | BU13: =100*(0.35*MIN(1,MAX(0,((ABS(BF13))-(0.3))/((0.05)-(0.3))))+0.3*MIN(1,MAX(0,((BG13)-(0.0))/((0.3)-(0.0))))+0.25*MIN(1,MAX(0,((BH13)-(0.4))/((0.7)-(0.4))))+0.1*IF(BJ13>=2,1,0.5)) | BV13: =0.25*BR13+0.25*BS13+0.2*BT13+0.3*BU13 | BW13: 全部通過
A14: 1 | B14: 13 | C14: NVDA | D14: NVIDIA Corporation | E14: NASDAQ | F14: 科技 | G14: Semiconductors | H14: 5503.958 | I14: 大型 | J14: 233.95 | K14: 230.86 | L14: =J14/K14-1 | M14: 237.88 | N14: 233.6 | O14: 134914600 | P14: 109953295 | Q14: =O14/P14 | R14: 228.2091 | S14: 224.6694 | T14: 221.3392 | U14: =S14/T14-1 | V14: 1 | W14: =J14/R14-1 | X14: =J14/S14-1 | Y14: 5.9101 | Z14: =Y14/J14 | AA14: =(J14-R14)/Y14 | AB14: =(J14-S14)/Y14 | AC14: =IF(ABS(AA14)<=ABS(AB14),"9EMA","21EMA") | AD14: — | AE14: 持續在上方 | AI14: 2026-09-18 | AJ14: 10 | AK14: 2 | AL14: 2026-09-24 | AM14: 221.09 | AN14: 208.93 | AO14: =IF(ISNUMBER(AN14),AM14/AN14-1,"") | AP14: 6 | AQ14: =IF(ISNUMBER(AM14),J14/AM14-1,"") | AR14: 233.95 | AS14: =J14/AR14-1 | AT14: 3.4886 | AU14: 2.6614 | AV14: 2.4546 | AW14: =AU14-AV14 | AX14: 0.8272 | AY14: 0.6141 | AZ14: 0.5017 | BA14: 深綠 | BB14: 淺綠→深綠 | BC14: 2 | BD14: 深綠 淺綠 淺綠 深綠 淺綠 深綠 深綠 深綠 | BE14: 上升三角（平頂） | BF14: -0.0743 | BG14: 0.16 | BH14: 0.5016 | BI14: 0.5433 | BJ14: 2 | BK14: 237.88 | BL14: 208.93 | BM14: 223.4515 | BN14: 0.79 | BO14: =IF(M14=N14,0.5,(J14-N14)/(M14-N14)) | BP14: 9.292 | BQ14: 4.251 | BR14: =100*(0.4*MIN(1,MAX(0,((U14*100)-(0.0))/((2.5)-(0.0))))+0.3*MIN(1,MAX(0,((V14)-(0.6))/((1.0)-(0.6))))+0.3*MIN(1,MAX(0,((BP14)-(0.0))/((15.0)-(0.0))))) | BS14: =100*(0.4*MIN(1,MAX(0,((MIN(ABS(AA14),ABS(AB14)))-(0.75))/((0.0)-(0.75))))+0.3*MIN(1,MAX(0,((BN14)-(1.2))/((0.6)-(1.2))))+0.3*BO14) | BT14: =100*(0.5*MIN(1,MAX(0,((AK14)-(1.0))/((4.0)-(1.0))))+0.3*MIN(1,MAX(0,((IF(ISNUMBER(AO14),AO14,0)*100)-(0.0))/((8.0)-(0.0))))+0.2*MIN(1,MAX(0,((IF(ISNUMBER(AP14),AP14,0))-(25.0))/((5.0)-(25.0))))) | BU14: =100*(0.35*MIN(1,MAX(0,((ABS(BF14))-(0.3))/((0.05)-(0.3))))+0.3*MIN(1,MAX(0,((BG14)-(0.0))/((0.3)-(0.0))))+0.25*MIN(1,MAX(0,((BH14)-(0.4))/((0.7)-(0.4))))+0.1*IF(BJ14>=2,1,0.5)) | BV14: =0.25*BR14+0.25*BS14+0.2*BT14+0.3*BU14 | BW14: 全部通過
A15: 1 | B15: 14 | C15: LEGH | D15: Legacy Housing Corporation | E15: NASDAQ | F15: 非必需消費 | G15: Homebuilding | H15: 0.682 | I15: 小型 | J15: 29.35 | K15: 29.19 | L15: =J15/K15-1 | M15: 29.87 | N15: 29.05 | O15: 53800 | P15: 77855 | Q15: =O15/P15 | R15: 28.9334 | S15: 28.5714 | T15: 28.2677 | U15: =S15/T15-1 | V15: 1 | W15: =J15/R15-1 | X15: =J15/S15-1 | Y15: 0.9189 | Z15: =Y15/J15 | AA15: =(J15-R15)/Y15 | AB15: =(J15-S15)/Y15 | AC15: =IF(ABS(AA15)<=ABS(AB15),"9EMA","21EMA") | AD15: 9+21EMA | AE15: 持續在上方 | AH15: ✓ | AI15: 2026-09-21 | AJ15: 9 | AK15: 2 | AL15: 2026-09-29 | AM15: 28.28 | AN15: 26.37 | AO15: =IF(ISNUMBER(AN15),AM15/AN15-1,"") | AP15: 3 | AQ15: =IF(ISNUMBER(AM15),J15/AM15-1,"") | AR15: 29.35 | AS15: =J15/AR15-1 | AT15: 0.3552 | AU15: 0.2682 | AV15: 0.2465 | AW15: =AU15-AV15 | AX15: 0.0869 | AY15: 0.0829 | AZ15: 0.0822 | BA15: 深綠 | BB15: 淺綠→深綠 | BC15: 1 | BD15: 深綠 深綠 深綠 淺綠 淺綠 淺綠 深綠 深綠 | BE15: 上傾擴張 | BF15: 0.3672 | BG15: 0.2189 | BH15: 0.5591 | BI15: 0.5433 | BJ15: 4 | BK15: 29.87 | BL15: 26.37 | BM15: 28.327 | BN15: 0.797 | BO15: =IF(M15=N15,0.5,(J15-N15)/(M15-N15)) | BP15: 10.731 | BQ15: 5.69 | BR15: =100*(0.4*MIN(1,MAX(0,((U15*100)-(0.0))/((2.5)-(0.0))))+0.3*MIN(1,MAX(0,((V15)-(0.6))/((1.0)-(0.6))))+0.3*MIN(1,MAX(0,((BP15)-(0.0))/((15.0)-(0.0))))) | BS15: =100*(0.4*MIN(1,MAX(0,((MIN(ABS(AA15),ABS(AB15)))-(0.75))/((0.0)-(0.75))))+0.3*MIN(1,MAX(0,((BN15)-(1.2))/((0.6)-(1.2))))+0.3*BO15) | BT15: =100*(0.5*MIN(1,MAX(0,((AK15)-(1.0))/((4.0)-(1.0))))+0.3*MIN(1,MAX(0,((IF(ISNUMBER(AO15),AO15,0)*100)-(0.0))/((8.0)-(0.0))))+0.2*MIN(1,MAX(0,((IF(ISNUMBER(AP15),AP15,0))-(25.0))/((5.0)-(25.0))))) | BU15: =100*(0.35*MIN(1,MAX(0,((ABS(BF15))-(0.3))/((0.05)-(0.3))))+0.3*MIN(1,MAX(0,((BG15)-(0.0))/((0.3)-(0.0))))+0.25*MIN(1,MAX(0,((BH15)-(0.4))/((0.7)-(0.4))))+0.1*IF(BJ15>=2,1,0.5)) | BV15: =0.25*BR15+0.25*BS15+0.2*BT15+0.3*BU15 | BW15: 全部通過
A16: 1 | B16: 15 | C16: TENB | D16: Tenable Holdings Inc. | E16: NASDAQ | F16: 科技 | G16: Computer Software: Prepackaged Software | H16: 4.008 | I16: 中型 | J16: 36.85 | K16: 36.11 | L16: =J16/K16-1 | M16: 37.24 | N16: 36.15 | O16: 2044500 | P16: 4744640 | Q16: =O16/P16 | R16: 35.7646 | S16: 35.4596 | T16: 35.2075 | U16: =S16/T16-1 | V16: 0.7 | W16: =J16/R16-1 | X16: =J16/S16-1 | Y16: 2.0802 | Z16: =Y16/J16 | AA16: =(J16-R16)/Y16 | AB16: =(J16-S16)/Y16 | AC16: =IF(ABS(AA16)<=ABS(AB16),"9EMA","21EMA") | AD16: 9+21EMA | AE16: 剛黃金交叉 | AF16: ✓ | AI16: 2026-09-30 | AJ16: 2 | AK16: 2 | AL16: 2026-09-28 | AM16: 32.49 | AN16: 29.97 | AO16: =IF(ISNUMBER(AN16),AM16/AN16-1,"") | AP16: 4 | AQ16: =IF(ISNUMBER(AM16),J16/AM16-1,"") | AR16: 38.09 | AS16: =J16/AR16-1 | AT16: 0.2487 | AU16: 0.1031 | AV16: 0.0667 | AW16: =AU16-AV16 | AX16: 0.1456 | AY16: 0.0792 | AZ16: 0.041 | BA16: 深綠 | BB16: 深紅→淺紅 | BC16: 3 | BD16: 深綠 淺綠 深紅 深紅 淺紅 深綠 深綠 深綠 | BE16: 上升三角（平頂） | BF16: 0.0516 | BG16: 0.0319 | BH16: 0.5809 | BI16: 0.6271 | BJ16: 2 | BK16: 38.89 | BL16: 29.97 | BM16: 35.1516 | BN16: 0.8987 | BO16: =IF(M16=N16,0.5,(J16-N16)/(M16-N16)) | BP16: 12.664 | BQ16: 7.623 | BR16: =100*(0.4*MIN(1,MAX(0,((U16*100)-(0.0))/((2.5)-(0.0))))+0.3*MIN(1,MAX(0,((V16)-(0.6))/((1.0)-(0.6))))+0.3*MIN(1,MAX(0,((BP16)-(0.0))/((15.0)-(0.0))))) | BS16: =100*(0.4*MIN(1,MAX(0,((MIN(ABS(AA16),ABS(AB16)))-(0.75))/((0.0)-(0.75))))+0.3*MIN(1,MAX(0,((BN16)-(1.2))/((0.6)-(1.2))))+0.3*BO16) | BT16: =100*(0.5*MIN(1,MAX(0,((AK16)-(1.0))/((4.0)-(1.0))))+0.3*MIN(1,MAX(0,((IF(ISNUMBER(AO16),AO16,0)*100)-(0.0))/((8.0)-(0.0))))+0.2*MIN(1,MAX(0,((IF(ISNUMBER(AP16),AP16,0))-(25.0))/((5.0)-(25.0))))) | BU16: =100*(0.35*MIN(1,MAX(0,((ABS(BF16))-(0.3))/((0.05)-(0.3))))+0.3*MIN(1,MAX(0,((BG16)-(0.0))/((0.3)-(0.0))))+0.25*MIN(1,MAX(0,((BH16)-(0.4))/((0.7)-(0.4))))+0.1*IF(BJ16>=2,1,0.5)) | BV16: =0.25*BR16+0.25*BS16+0.2*BT16+0.3*BU16 | BW16: 全部通過
A17: 1 | B17: 16 | C17: NHC | D17: National HealthCare Corporation | E17: AMEX | F17: 醫療保健 | G17: Hospital/Nursing Management | H17: 3.438 | I17: 中型 | J17: 227.66 | K17: 223.35 | L17: =J17/K17-1 | M17: 229.53 | N17: 223.8 | O17: 88300 | P17: 106730 | Q17: =O17/P17 | R17: 224.3309 | S17: 224.0502 | T17: 223.9601 | U17: =S17/T17-1 | V17: 0.5 | W17: =J17/R17-1 | X17: =J17/S17-1 | Y17: 6.2622 | Z17: =Y17/J17 | AA17: =(J17-R17)/Y17 | AB17: =(J17-S17)/Y17 | AC17: =IF(ABS(AA17)<=ABS(AB17),"9EMA","21EMA") | AD17: 9+21EMA | AE17: 剛黃金交叉 | AF17: ✓ | AH17: ✓ | AI17: 2026-10-02 | AJ17: 0 | AK17: 4 | AL17: 2026-09-24 | AM17: 219.72 | AN17: 214.15 | AO17: =IF(ISNUMBER(AN17),AM17/AN17-1,"") | AP17: 6 | AQ17: =IF(ISNUMBER(AM17),J17/AM17-1,"") | AR17: 227.76 | AS17: =J17/AR17-1 | AT17: 0.3934 | AU17: 0.3868 | AV17: 0.3851 | AW17: =AU17-AV17 | AX17: 0.0067 | AY17: -0.3081 | AZ17: -0.3512 | BA17: 深綠 | BB17: 深紅→淺紅 | BC17: 1 | BD17: 淺紅 深紅 淺紅 深綠 深紅 深紅 淺紅 深綠 | BE17: 上升三角（平頂） | BF17: -0.0226 | BG17: 0.1439 | BH17: 0.5531 | BI17: 0.5731 | BJ17: 12 | BK17: 230.09 | BL17: 214.15 | BM17: 222.9659 | BN17: 0.8442 | BO17: =IF(M17=N17,0.5,(J17-N17)/(M17-N17)) | BP17: 9.789 | BQ17: 4.748 | BR17: =100*(0.4*MIN(1,MAX(0,((U17*100)-(0.0))/((2.5)-(0.0))))+0.3*MIN(1,MAX(0,((V17)-(0.6))/((1.0)-(0.6))))+0.3*MIN(1,MAX(0,((BP17)-(0.0))/((15.0)-(0.0))))) | BS17: =100*(0.4*MIN(1,MAX(0,((MIN(ABS(AA17),ABS(AB17)))-(0.75))/((0.0)-(0.75))))+0.3*MIN(1,MAX(0,((BN17)-(1.2))/((0.6)-(1.2))))+0.3*BO17) | BT17: =100*(0.5*MIN(1,MAX(0,((AK17)-(1.0))/((4.0)-(1.0))))+0.3*MIN(1,MAX(0,((IF(ISNUMBER(AO17),AO17,0)*100)-(0.0))/((8.0)-(0.0))))+0.2*MIN(1,MAX(0,((IF(ISNUMBER(AP17),AP17,0))-(25.0))/((5.0)-(25.0))))) | BU17: =100*(0.35*MIN(1,MAX(0,((ABS(BF17))-(0.3))/((0.05)-(0.3))))+0.3*MIN(1,MAX(0,((BG17)-(0.0))/((0.3)-(0.0))))+0.25*MIN(1,MAX(0,((BH17)-(0.4))/((0.7)-(0.4))))+0.1*IF(BJ17>=2,1,0.5)) | BV17: =0.25*BR17+0.25*BS17+0.2*BT17+0.3*BU17 | BW17: 全部通過
A18: 1 | B18: 17 | C18: SLAB | D18: Silicon Laboratories Inc. | E18: NASDAQ | F18: 科技 | G18: Semiconductors | H18: 7.393 | I18: 中型 | J18: 222.76 | K18: 222.51 | L18: =J18/K18-1 | M18: 223.5 | N18: 222.24 | O18: 304300 | P18: 281205 | Q18: =O18/P18 | R18: 221.6417 | S18: 220.8472 | T18: 220.2034 | U18: =S18/T18-1 | V18: 1 | W18: =J18/R18-1 | X18: =J18/S18-1 | Y18: 1.0866 | Z18: =Y18/J18 | AA18: =(J18-R18)/Y18 | AB18: =(J18-S18)/Y18 | AC18: =IF(ABS(AA18)<=ABS(AB18),"9EMA","21EMA") | AD18: 9+21EMA | AE18: 持續在上方 | AH18: ✓ | AI18: 2026-08-06 | AJ18: 40 | AK18: 2 | AL18: 2026-09-28 | AM18: 220.78 | AN18: 216.88 | AO18: =IF(ISNUMBER(AN18),AM18/AN18-1,"") | AP18: 4 | AQ18: =IF(ISNUMBER(AM18),J18/AM18-1,"") | AR18: 222.76 | AS18: =J18/AR18-1 | AT18: 0.8013 | AU18: 0.6571 | AV18: 0.6211 | AW18: =AU18-AV18 | AX18: 0.1442 | AY18: 0.1064 | AZ18: 0.0535 | BA18: 深綠 | BB18: 淺綠→深綠 | BC18: 2 | BD18: 淺綠 淺綠 淺綠 淺綠 淺綠 深綠 深綠 深綠 | BE18: 上升三角（平頂） | BF18: -0.0049 | BG18: 0.0704 | BH18: 0.5444 | BI18: 0.4606 | BJ18: 19 | BK18: 223.5 | BL18: 216.88 | BM18: 220.4838 | BN18: 0.4699 | BO18: =IF(M18=N18,0.5,(J18-N18)/(M18-N18)) | BP18: 6.19 | BQ18: 1.149 | BR18: =100*(0.4*MIN(1,MAX(0,((U18*100)-(0.0))/((2.5)-(0.0))))+0.3*MIN(1,MAX(0,((V18)-(0.6))/((1.0)-(0.6))))+0.3*MIN(1,MAX(0,((BP18)-(0.0))/((15.0)-(0.0))))) | BS18: =100*(0.4*MIN(1,MAX(0,((MIN(ABS(AA18),ABS(AB18)))-(0.75))/((0.0)-(0.75))))+0.3*MIN(1,MAX(0,((BN18)-(1.2))/((0.6)-(1.2))))+0.3*BO18) | BT18: =100*(0.5*MIN(1,MAX(0,((AK18)-(1.0))/((4.0)-(1.0))))+0.3*MIN(1,MAX(0,((IF(ISNUMBER(AO18),AO18,0)*100)-(0.0))/((8.0)-(0.0))))+0.2*MIN(1,MAX(0,((IF(ISNUMBER(AP18),AP18,0))-(25.0))/((5.0)-(25.0))))) | BU18: =100*(0.35*MIN(1,MAX(0,((ABS(BF18))-(0.3))/((0.05)-(0.3))))+0.3*MIN(1,MAX(0,((BG18)-(0.0))/((0.3)-(0.0))))+0.25*MIN(1,MAX(0,((BH18)-(0.4))/((0.7)-(0.4))))+0.1*IF(BJ18>=2,1,0.5)) | BV18: =0.25*BR18+0.25*BS18+0.2*BT18+0.3*BU18 | BW18: 全部通過
A19: 1 | B19: 18 | C19: FAST | D19: Fastenal Company | E19: NASDAQ | F19: 非必需消費 | G19: RETAIL: Building Materials | H19: 56.836 | I19: 大型 | J19: 50.75 | K19: 50.23 | L19: =J19/K19-1 | M19: 51.04 | N19: 50.43 | O19: 7156900 | P19: 7019355 | Q19: =O19/P19 | R19: 50.1801 | S19: 49.9633 | T19: 49.8128 | U19: =S19/T19-1 | V19: 0.9 | W19: =J19/R19-1 | X19: =J19/S19-1 | Y19: 0.9691 | Z19: =Y19/J19 | AA19: =(J19-R19)/Y19 | AB19: =(J19-S19)/Y19 | AC19: =IF(ABS(AA19)<=ABS(AB19),"9EMA","21EMA") | AD19: 9+21EMA | AE19: 持續在上方 | AH19: ✓ | AI19: 2026-09-23 | AJ19: 7 | AK19: 3 | AL19: 2026-09-21 | AM19: 48.53 | AN19: 48.06 | AO19: =IF(ISNUMBER(AN19),AM19/AN19-1,"") | AP19: 9 | AQ19: =IF(ISNUMBER(AM19),J19/AM19-1,"") | AR19: 50.99 | AS19: =J19/AR19-1 | AT19: 0.2121 | AU19: 0.1468 | AV19: 0.1305 | AW19: =AU19-AV19 | AX19: 0.0653 | AY19: 0.033 | AZ19: 0.0296 | BA19: 深綠 | BB19: 淺綠→深綠 | BC19: 1 | BD19: 深綠 深綠 淺綠 淺綠 淺綠 淺綠 深綠 深綠 | BE19: 上升三角（平頂） | BF19: 0.0067 | BG19: 0.1437 | BH19: 0.5113 | BI19: 0.5552 | BJ19: 6 | BK19: 51.52 | BL19: 47.65 | BM19: 49.6288 | BN19: 1.3414 | BO19: =IF(M19=N19,0.5,(J19-N19)/(M19-N19)) | BP19: 10.925 | BQ19: 5.884 | BR19: =100*(0.4*MIN(1,MAX(0,((U19*100)-(0.0))/((2.5)-(0.0))))+0.3*MIN(1,MAX(0,((V19)-(0.6))/((1.0)-(0.6))))+0.3*MIN(1,MAX(0,((BP19)-(0.0))/((15.0)-(0.0))))) | BS19: =100*(0.4*MIN(1,MAX(0,((MIN(ABS(AA19),ABS(AB19)))-(0.75))/((0.0)-(0.75))))+0.3*MIN(1,MAX(0,((BN19)-(1.2))/((0.6)-(1.2))))+0.3*BO19) | BT19: =100*(0.5*MIN(1,MAX(0,((AK19)-(1.0))/((4.0)-(1.0))))+0.3*MIN(1,MAX(0,((IF(ISNUMBER(AO19),AO19,0)*100)-(0.0))/((8.0)-(0.0))))+0.2*MIN(1,MAX(0,((IF(ISNUMBER(AP19),AP19,0))-(25.0))/((5.0)-(25.0))))) | BU19: =100*(0.35*MIN(1,MAX(0,((ABS(BF19))-(0.3))/((0.05)-(0.3))))+0.3*MIN(1,MAX(0,((BG19)-(0.0))/((0.3)-(0.0))))+0.25*MIN(1,MAX(0,((BH19)-(0.4))/((0.7)-(0.4))))+0.1*IF(BJ19>=2,1,0.5)) | BV19: =0.25*BR19+0.25*BS19+0.2*BT19+0.3*BU19 | BW19: 全部通過
A20: 1 | B20: 19 | C20: STRL | D20: Sterling Infrastructure Inc. | E20: NASDAQ | F20: 工業 | G20: Military/Government/Technical | H20: 15.043 | I20: 大型 | J20: 533.42 | K20: 505.12 | L20: =J20/K20-1 | M20: 537.01 | N20: 513.87 | O20: 606100 | P20: 536050 | Q20: =O20/P20 | R20: 509.023 | S20: 506.9403 | T20: 506.2181 | U20: =S20/T20-1 | V20: 0.7 | W20: =J20/R20-1 | X20: =J20/S20-1 | Y20: 26.4427 | Z20: =Y20/J20 | AA20: =(J20-R20)/Y20 | AB20: =(J20-S20)/Y20 | AC20: =IF(ABS(AA20)<=ABS(AB20),"9EMA","21EMA") | AD20: 9+21EMA | AE20: 剛黃金交叉 | AF20: ✓ | AI20: 2026-10-02 | AJ20: 0 | AK20: 3 | AL20: 2026-09-24 | AM20: 485 | AN20: 458.51 | AO20: =IF(ISNUMBER(AN20),AM20/AN20-1,"") | AP20: 6 | AQ20: =IF(ISNUMBER(AM20),J20/AM20-1,"") | AR20: 533.42 | AS20: =J20/AR20-1 | AT20: -3.0345 | AU20: -8.5052 | AV20: -9.8729 | AW20: =AU20-AV20 | AX20: 5.4707 | AY20: 3.9241 | AZ20: 4.1535 | BA20: 深綠 | BB20: 淺綠→深綠 | BC20: 0 | BD20: 淺綠 淺綠 淺綠 淺綠 淺綠 淺綠 淺綠 深綠 | BE20: 上升通道 | BF20: 0.439 | BG20: 0.5017 | BH20: 0.5227 | BI20: 0.4754 | BJ20: 2 | BK20: 537.01 | BL20: 444.52 | BM20: 492.8614 | BN20: 0.9802 | BO20: =IF(M20=N20,0.5,(J20-N20)/(M20-N20)) | BP20: 21.61 | BQ20: 16.569 | BR20: =100*(0.4*MIN(1,MAX(0,((U20*100)-(0.0))/((2.5)-(0.0))))+0.3*MIN(1,MAX(0,((V20)-(0.6))/((1.0)-(0.6))))+0.3*MIN(1,MAX(0,((BP20)-(0.0))/((15.0)-(0.0))))) | BS20: =100*(0.4*MIN(1,MAX(0,((MIN(ABS(AA20),ABS(AB20)))-(0.75))/((0.0)-(0.75))))+0.3*MIN(1,MAX(0,((BN20)-(1.2))/((0.6)-(1.2))))+0.3*BO20) | BT20: =100*(0.5*MIN(1,MAX(0,((AK20)-(1.0))/((4.0)-(1.0))))+0.3*MIN(1,MAX(0,((IF(ISNUMBER(AO20),AO20,0)*100)-(0.0))/((8.0)-(0.0))))+0.2*MIN(1,MAX(0,((IF(ISNUMBER(AP20),AP20,0))-(25.0))/((5.0)-(25.0))))) | BU20: =100*(0.35*MIN(1,MAX(0,((ABS(BF20))-(0.3))/((0.05)-(0.3))))+0.3*MIN(1,MAX(0,((BG20)-(0.0))/((0.3)-(0.0))))+0.25*MIN(1,MAX(0,((BH20)-(0.4))/((0.7)-(0.4))))+0.1*IF(BJ20>=2,1,0.5)) | BV20: =0.25*BR20+0.25*BS20+0.2*BT20+0.3*BU20 | BW20: 全部通過
A21: 1 | B21: 20 | C21: VSTS | D21: Vestis Corporation | E21: NYSE | F21: 非必需消費 | G21: Consumer Specialties | H21: 1.766 | I21: 小型 | J21: 14.03 | K21: 13.78 | L21: =J21/K21-1 | M21: 14.51 | N21: 13.67 | O21: 1981200 | P21: 1693705 | Q21: =O21/P21 | R21: 13.7087 | S21: 13.5821 | T21: 13.5437 | U21: =S21/T21-1 | V21: 0.7 | W21: =J21/R21-1 | X21: =J21/S21-1 | Y21: 0.5673 | Z21: =Y21/J21 | AA21: =(J21-R21)/Y21 | AB21: =(J21-S21)/Y21 | AC21: =IF(ABS(AA21)<=ABS(AB21),"9EMA","21EMA") | AD21: 9+21EMA | AE21: 持續在上方 | AH21: ✓ | AI21: 2026-09-16 | AJ21: 12 | AK21: 3 | AL21: 2026-09-28 | AM21: 13.01 | AN21: 12.765 | AO21: =IF(ISNUMBER(AN21),AM21/AN21-1,"") | AP21: 4 | AQ21: =IF(ISNUMBER(AM21),J21/AM21-1,"") | AR21: 14.43 | AS21: =J21/AR21-1 | AT21: 0.1085 | AU21: 0.0778 | AV21: 0.0701 | AW21: =AU21-AV21 | AX21: 0.0307 | AY21: 0.0106 | AZ21: 0.002 | BA21: 深綠 | BB21: 淺綠→深綠 | BC21: 1 | BD21: 淺綠 淺綠 淺綠 淺綠 淺綠 淺綠 深綠 深綠 | BE21: 上傾擴張 | BF21: 0.6123 | BG21: 0.3722 | BH21: 0.5265 | BI21: 0.5668 | BJ21: 4 | BK21: 14.66 | BL21: 12.07 | BM21: 13.4336 | BN21: 0.7942 | BO21: =IF(M21=N21,0.5,(J21-N21)/(M21-N21)) | BP21: 20.324 | BQ21: 15.283 | BR21: =100*(0.4*MIN(1,MAX(0,((U21*100)-(0.0))/((2.5)-(0.0))))+0.3*MIN(1,MAX(0,((V21)-(0.6))/((1.0)-(0.6))))+0.3*MIN(1,MAX(0,((BP21)-(0.0))/((15.0)-(0.0))))) | BS21: =100*(0.4*MIN(1,MAX(0,((MIN(ABS(AA21),ABS(AB21)))-(0.75))/((0.0)-(0.75))))+0.3*MIN(1,MAX(0,((BN21)-(1.2))/((0.6)-(1.2))))+0.3*BO21) | BT21: =100*(0.5*MIN(1,MAX(0,((AK21)-(1.0))/((4.0)-(1.0))))+0.3*MIN(1,MAX(0,((IF(ISNUMBER(AO21),AO21,0)*100)-(0.0))/((8.0)-(0.0))))+0.2*MIN(1,MAX(0,((IF(ISNUMBER(AP21),AP21,0))-(25.0))/((5.0)-(25.0))))) | BU21: =100*(0.35*MIN(1,MAX(0,((ABS(BF21))-(0.3))/((0.05)-(0.3))))+0.3*MIN(1,MAX(0,((BG21)-(0.0))/((0.3)-(0.0))))+0.25*MIN(1,MAX(0,((BH21)-(0.4))/((0.7)-(0.4))))+0.1*IF(BJ21>=2,1,0.5)) | BV21: =0.25*BR21+0.25*BS21+0.2*BT21+0.3*BU21 | BW21: 全部通過
A22: 1 | B22: 21 | C22: GSAT | D22: Globalstar Inc. | E22: NASDAQ | F22: 非必需消費 | G22: Telecommunications Equipment | H22: 10.74 | I22: 大型 | J22: 83.22 | K22: 82.88 | L22: =J22/K22-1 | M22: 83.42 | N22: 83 | O22: 535000 | P22: 565670 | Q22: =O22/P22 | R22: 82.7604 | S22: 82.5135 | T22: 82.3247 | U22: =S22/T22-1 | V22: 1 | W22: =J22/R22-1 | X22: =J22/S22-1 | Y22: 0.6496 | Z22: =Y22/J22 | AA22: =(J22-R22)/Y22 | AB22: =(J22-S22)/Y22 | AC22: =IF(ABS(AA22)<=ABS(AB22),"9EMA","21EMA") | AD22: 9+21EMA | AE22: 持續在上方 | AH22: ✓ | AI22: 2026-09-17 | AJ22: 11 | AK22: 4 | AL22: 2026-09-23 | AM22: 81.95 | AN22: 81.55 | AO22: =IF(ISNUMBER(AN22),AM22/AN22-1,"") | AP22: 7 | AQ22: =IF(ISNUMBER(AM22),J22/AM22-1,"") | AR22: 83.22 | AS22: =J22/AR22-1 | AT22: 0.2467 | AU22: 0.1921 | AV22: 0.1784 | AW22: =AU22-AV22 | AX22: 0.0547 | AY22: 0.0334 | AZ22: 0.0286 | BA22: 深綠 | BB22: 淺綠→深綠 | BC22: 2 | BD22: 淺綠 淺綠 深綠 淺綠 淺綠 深綠 深綠 深綠 | BE22: 上升三角（平頂） | BF22: 0.0906 | BG22: 0.0757 | BH22: 0.5308 | BI22: 0.4994 | BJ22: 19 | BK22: 83.42 | BL22: 81.02 | BM22: 82.294 | BN22: 1.1639 | BO22: =IF(M22=N22,0.5,(J22-N22)/(M22-N22)) | BP22: 7.202 | BQ22: 2.161 | BR22: =100*(0.4*MIN(1,MAX(0,((U22*100)-(0.0))/((2.5)-(0.0))))+0.3*MIN(1,MAX(0,((V22)-(0.6))/((1.0)-(0.6))))+0.3*MIN(1,MAX(0,((BP22)-(0.0))/((15.0)-(0.0))))) | BS22: =100*(0.4*MIN(1,MAX(0,((MIN(ABS(AA22),ABS(AB22)))-(0.75))/((0.0)-(0.75))))+0.3*MIN(1,MAX(0,((BN22)-(1.2))/((0.6)-(1.2))))+0.3*BO22) | BT22: =100*(0.5*MIN(1,MAX(0,((AK22)-(1.0))/((4.0)-(1.0))))+0.3*MIN(1,MAX(0,((IF(ISNUMBER(AO22),AO22,0)*100)-(0.0))/((8.0)-(0.0))))+0.2*MIN(1,MAX(0,((IF(ISNUMBER(AP22),AP22,0))-(25.0))/((5.0)-(25.0))))) | BU22: =100*(0.35*MIN(1,MAX(0,((ABS(BF22))-(0.3))/((0.05)-(0.3))))+0.3*MIN(1,MAX(0,((BG22)-(0.0))/((0.3)-(0.0))))+0.25*MIN(1,MAX(0,((BH22)-(0.4))/((0.7)-(0.4))))+0.1*IF(BJ22>=2,1,0.5)) | BV22: =0.25*BR22+0.25*BS22+0.2*BT22+0.3*BU22 | BW22: 全部通過
A23: 1 | B23: 22 | C23: EGBN | D23: Eagle Bancorp Inc. | E23: NASDAQ | F23: 金融 | G23: Major Banks | H23: 0.847 | I23: 小型 | J23: 28.38 | K23: 28.21 | L23: =J23/K23-1 | M23: 28.96 | N23: 28.25 | O23: 208200 | P23: 336765 | Q23: =O23/P23 | R23: 28.1745 | S23: 28.0807 | T23: 28.0312 | U23: =S23/T23-1 | V23: 0.8 | W23: =J23/R23-1 | X23: =J23/S23-1 | Y23: 0.6668 | Z23: =Y23/J23 | AA23: =(J23-R23)/Y23 | AB23: =(J23-S23)/Y23 | AC23: =IF(ABS(AA23)<=ABS(AB23),"9EMA","21EMA") | AD23: 9+21EMA | AE23: 持續在上方 | AH23: ✓ | AI23: 2026-09-15 | AJ23: 13 | AK23: 2 | AL23: 2026-09-10 | AM23: 27.12 | AN23: 26.52 | AO23: =IF(ISNUMBER(AN23),AM23/AN23-1,"") | AP23: 16 | AQ23: =IF(ISNUMBER(AM23),J23/AM23-1,"") | AR23: 28.54 | AS23: =J23/AR23-1 | AT23: 0.0984 | AU23: 0.0887 | AV23: 0.0863 | AW23: =AU23-AV23 | AX23: 0.0097 | AY23: -0.0035 | AZ23: -0.0082 | BA23: 深綠 | BB23: 深紅→淺紅 | BC23: 1 | BD23: 淺綠 深綠 深綠 深綠 淺綠 深紅 淺紅 深綠 | BE23: 上傾收窄（楔形） | BF23: 0.1857 | BG23: 0.3524 | BH23: 0.6051 | BI23: 0.6964 | BJ23: 5 | BK23: 28.99 | BL23: 26.52 | BM23: 28.0147 | BN23: 0.9716 | BO23: =IF(M23=N23,0.5,(J23-N23)/(M23-N23)) | BP23: 7.496 | BQ23: 2.455 | BR23: =100*(0.4*MIN(1,MAX(0,((U23*100)-(0.0))/((2.5)-(0.0))))+0.3*MIN(1,MAX(0,((V23)-(0.6))/((1.0)-(0.6))))+0.3*MIN(1,MAX(0,((BP23)-(0.0))/((15.0)-(0.0))))) | BS23: =100*(0.4*MIN(1,MAX(0,((MIN(ABS(AA23),ABS(AB23)))-(0.75))/((0.0)-(0.75))))+0.3*MIN(1,MAX(0,((BN23)-(1.2))/((0.6)-(1.2))))+0.3*BO23) | BT23: =100*(0.5*MIN(1,MAX(0,((AK23)-(1.0))/((4.0)-(1.0))))+0.3*MIN(1,MAX(0,((IF(ISNUMBER(AO23),AO23,0)*100)-(0.0))/((8.0)-(0.0))))+0.2*MIN(1,MAX(0,((IF(ISNUMBER(AP23),AP23,0))-(25.0))/((5.0)-(25.0))))) | BU23: =100*(0.35*MIN(1,MAX(0,((ABS(BF23))-(0.3))/((0.05)-(0.3))))+0.3*MIN(1,MAX(0,((BG23)-(0.0))/((0.3)-(0.0))))+0.25*MIN(1,MAX(0,((BH23)-(0.4))/((0.7)-(0.4))))+0.1*IF(BJ23>=2,1,0.5)) | BV23: =0.25*BR23+0.25*BS23+0.2*BT23+0.3*BU23 | BW23: 全部通過
A24: 1 | B24: 23 | C24: APXT | D24: Apex Treasury Corporation | E24: NASDAQ | F24: 金融 | G24: Blank Checks | I24: 未分類 | J24: 10.15 | K24: 10.15 | L24: =J24/K24-1 | M24: 10.15 | N24: 10.14 | O24: 214300 | P24: 146760 | Q24: =O24/P24 | R24: 10.1407 | S24: 10.1354 | T24: 10.131 | U24: =S24/T24-1 | V24: 0.8 | W24: =J24/R24-1 | X24: =J24/S24-1 | Y24: 0.0126 | Z24: =Y24/J24 | AA24: =(J24-R24)/Y24 | AB24: =(J24-S24)/Y24 | AC24: =IF(ABS(AA24)<=ABS(AB24),"9EMA","21EMA") | AD24: 9+21EMA | AE24: 持續在上方 | AH24: ✓ | AI24: 2026-04-06 | AJ24: 125 | AK24: 3 | AL24: 2026-09-29 | AM24: 10.13 | AN24: 10.12 | AO24: =IF(ISNUMBER(AN24),AM24/AN24-1,"") | AP24: 3 | AQ24: =IF(ISNUMBER(AM24),J24/AM24-1,"") | AR24: 10.15 | AS24: =J24/AR24-1 | AT24: 0.0062 | AU24: 0.006 | AV24: 0.0059 | AW24: =AU24-AV24 | AX24: 0.0002 | AY24: -0.0003 | AZ24: -0.0012 | BA24: 深綠 | BB24: 深紅→淺紅 | BC24: 1 | BD24: 深紅 淺紅 淺紅 淺紅 淺紅 深紅 淺紅 深綠 | BE24: 上升三角（平頂） | BF24: 0 | BG24: 0.0164 | BH24: 0.5571 | BI24: 0.5571 | BJ24: 25 | BK24: 10.15 | BL24: 10.12 | BM24: 10.1367 | BN24: 1.0407 | BO24: =IF(M24=N24,0.5,(J24-N24)/(M24-N24)) | BP24: 5.288 | BQ24: 0.247 | BR24: =100*(0.4*MIN(1,MAX(0,((U24*100)-(0.0))/((2.5)-(0.0))))+0.3*MIN(1,MAX(0,((V24)-(0.6))/((1.0)-(0.6))))+0.3*MIN(1,MAX(0,((BP24)-(0.0))/((15.0)-(0.0))))) | BS24: =100*(0.4*MIN(1,MAX(0,((MIN(ABS(AA24),ABS(AB24)))-(0.75))/((0.0)-(0.75))))+0.3*MIN(1,MAX(0,((BN24)-(1.2))/((0.6)-(1.2))))+0.3*BO24) | BT24: =100*(0.5*MIN(1,MAX(0,((AK24)-(1.0))/((4.0)-(1.0))))+0.3*MIN(1,MAX(0,((IF(ISNUMBER(AO24),AO24,0)*100)-(0.0))/((8.0)-(0.0))))+0.2*MIN(1,MAX(0,((IF(ISNUMBER(AP24),AP24,0))-(25.0))/((5.0)-(25.0))))) | BU24: =100*(0.35*MIN(1,MAX(0,((ABS(BF24))-(0.3))/((0.05)-(0.3))))+0.3*MIN(1,MAX(0,((BG24)-(0.0))/((0.3)-(0.0))))+0.25*MIN(1,MAX(0,((BH24)-(0.4))/((0.7)-(0.4))))+0.1*IF(BJ24>=2,1,0.5)) | BV24: =0.25*BR24+0.25*BS24+0.2*BT24+0.3*BU24 | BW24: 全部通過
A25: 1 | B25: 24 | C25: OPY | D25: Oppenheimer Holdings Inc. | E25: NYSE | F25: 金融 | G25: Investment Bankers/Brokers/Service | H25: 1.263 | I25: 小型 | J25: 120.13 | K25: 119.47 | L25: =J25/K25-1 | M25: 124.02 | N25: 119.91 | O25: 185000 | P25: 122170 | Q25: =O25/P25 | R25: 118.7478 | S25: 118.3189 | T25: 117.7539 | U25: =S25/T25-1 | V25: 0.7 | W25: =J25/R25-1 | X25: =J25/S25-1 | Y25: 4.7074 | Z25: =Y25/J25 | AA25: =(J25-R25)/Y25 | AB25: =(J25-S25)/Y25 | AC25: =IF(ABS(AA25)<=ABS(AB25),"9EMA","21EMA") | AD25: 9+21EMA | AE25: 剛黃金交叉 | AF25: ✓ | AH25: ✓ | AI25: 2026-09-28 | AJ25: 4 | AK25: 2 | AL25: 2026-09-22 | AM25: 111.05 | AN25: 110.35 | AO25: =IF(ISNUMBER(AN25),AM25/AN25-1,"") | AP25: 8 | AQ25: =IF(ISNUMBER(AM25),J25/AM25-1,"") | AR25: 123.29 | AS25: =J25/AR25-1 | AT25: 0.5409 | AU25: 0.497 | AV25: 0.486 | AW25: =AU25-AV25 | AX25: 0.0439 | AY25: -0.0564 | AZ25: -0.1516 | BA25: 深綠 | BB25: 深紅→淺紅 | BC25: 1 | BD25: 淺紅 淺紅 淺紅 淺紅 淺紅 深紅 淺紅 深綠 | BE25: 上升三角（平頂） | BF25: 0.0419 | BG25: 0.1457 | BH25: 0.5496 | BI25: 0.5039 | BJ25: 8 | BK25: 125.88 | BL25: 110.35 | BM25: 118.886 | BN25: 1.0601 | BO25: =IF(M25=N25,0.5,(J25-N25)/(M25-N25)) | BP25: 7.401 | BQ25: 2.36 | BR25: =100*(0.4*MIN(1,MAX(0,((U25*100)-(0.0))/((2.5)-(0.0))))+0.3*MIN(1,MAX(0,((V25)-(0.6))/((1.0)-(0.6))))+0.3*MIN(1,MAX(0,((BP25)-(0.0))/((15.0)-(0.0))))) | BS25: =100*(0.4*MIN(1,MAX(0,((MIN(ABS(AA25),ABS(AB25)))-(0.75))/((0.0)-(0.75))))+0.3*MIN(1,MAX(0,((BN25)-(1.2))/((0.6)-(1.2))))+0.3*BO25) | BT25: =100*(0.5*MIN(1,MAX(0,((AK25)-(1.0))/((4.0)-(1.0))))+0.3*MIN(1,MAX(0,((IF(ISNUMBER(AO25),AO25,0)*100)-(0.0))/((8.0)-(0.0))))+0.2*MIN(1,MAX(0,((IF(ISNUMBER(AP25),AP25,0))-(25.0))/((5.0)-(25.0))))) | BU25: =100*(0.35*MIN(1,MAX(0,((ABS(BF25))-(0.3))/((0.05)-(0.3))))+0.3*MIN(1,MAX(0,((BG25)-(0.0))/((0.3)-(0.0))))+0.25*MIN(1,MAX(0,((BH25)-(0.4))/((0.7)-(0.4))))+0.1*IF(BJ25>=2,1,0.5)) | BV25: =0.25*BR25+0.25*BS25+0.2*BT25+0.3*BU25 | BW25: 全部通過
A26: 1 | B26: 25 | C26: TRNS | D26: Transcat Inc. | E26: NASDAQ | F26: 工業 | G26: Electrical Products | H26: 0.83 | I26: 小型 | J26: 90.39 | K26: 90.18 | L26: =J26/K26-1 | M26: 92.49 | N26: 89.8 | O26: 101200 | P26: 122430 | Q26: =O26/P26 | R26: 88.3418 | S26: 87.5059 | T26: 86.7656 | U26: =S26/T26-1 | V26: 0.8 | W26: =J26/R26-1 | X26: =J26/S26-1 | Y26: 3.4718 | Z26: =Y26/J26 | AA26: =(J26-R26)/Y26 | AB26: =(J26-S26)/Y26 | AC26: =IF(ABS(AA26)<=ABS(AB26),"9EMA","21EMA") | AD26: 9+21EMA | AE26: 持續在上方 | AH26: ✓ | AI26: 2026-09-23 | AJ26: 7 | AK26: 2 | AL26: 2026-09-28 | AM26: 83.5 | AN26: 79.68 | AO26: =IF(ISNUMBER(AN26),AM26/AN26-1,"") | AP26: 4 | AQ26: =IF(ISNUMBER(AM26),J26/AM26-1,"") | AR26: 91.83 | AS26: =J26/AR26-1 | AT26: 0.4725 | AU26: -0.1513 | AV26: -0.3072 | AW26: =AU26-AV26 | AX26: 0.6237 | AY26: 0.5697 | AZ26: 0.4617 | BA26: 深綠 | BB26: 淺綠→深綠 | BC26: 2 | BD26: 深綠 淺綠 淺綠 淺綠 淺綠 深綠 深綠 深綠 | BE26: 上傾擴張 | BF26: 0.54 | BG26: 0.1624 | BH26: 0.5333 | BI26: 0.5089 | BJ26: 5 | BK26: 92.49 | BL26: 79.68 | BM26: 86.5111 | BN26: 1.1669 | BO26: =IF(M26=N26,0.5,(J26-N26)/(M26-N26)) | BP26: 10.686 | BQ26: 5.645 | BR26: =100*(0.4*MIN(1,MAX(0,((U26*100)-(0.0))/((2.5)-(0.0))))+0.3*MIN(1,MAX(0,((V26)-(0.6))/((1.0)-(0.6))))+0.3*MIN(1,MAX(0,((BP26)-(0.0))/((15.0)-(0.0))))) | BS26: =100*(0.4*MIN(1,MAX(0,((MIN(ABS(AA26),ABS(AB26)))-(0.75))/((0.0)-(0.75))))+0.3*MIN(1,MAX(0,((BN26)-(1.2))/((0.6)-(1.2))))+0.3*BO26) | BT26: =100*(0.5*MIN(1,MAX(0,((AK26)-(1.0))/((4.0)-(1.0))))+0.3*MIN(1,MAX(0,((IF(ISNUMBER(AO26),AO26,0)*100)-(0.0))/((8.0)-(0.0))))+0.2*MIN(1,MAX(0,((IF(ISNUMBER(AP26),AP26,0))-(25.0))/((5.0)-(25.0))))) | BU26: =100*(0.35*MIN(1,MAX(0,((ABS(BF26))-(0.3))/((0.05)-(0.3))))+0.3*MIN(1,MAX(0,((BG26)-(0.0))/((0.3)-(0.0))))+0.25*MIN(1,MAX(0,((BH26)-(0.4))/((0.7)-(0.4))))+0.1*IF(BJ26>=2,1,0.5)) | BV26: =0.25*BR26+0.25*BS26+0.2*BT26+0.3*BU26 | BW26: 全部通過
A27: 1 | B27: 26 | C27: BJ | D27: BJ's Wholesale Club Holdings Inc. | E27: NYSE | F27: 非必需消費 | G27: Department/Specialty Retail Stores | H27: 11.621 | I27: 大型 | J27: 94.96 | K27: 94.36 | L27: =J27/K27-1 | M27: 95.55 | N27: 93.075 | O27: 2439100 | P27: 1831645 | Q27: =O27/P27 | R27: 93.7887 | S27: 93.2333 | T27: 92.3738 | U27: =S27/T27-1 | V27: 0.5 | W27: =J27/R27-1 | X27: =J27/S27-1 | Y27: 2.7701 | Z27: =Y27/J27 | AA27: =(J27-R27)/Y27 | AB27: =(J27-S27)/Y27 | AC27: =IF(ABS(AA27)<=ABS(AB27),"9EMA","21EMA") | AD27: 9+21EMA | AE27: 剛黃金交叉 | AF27: ✓ | AH27: ✓ | AI27: 2026-09-28 | AJ27: 4 | AK27: 2 | AL27: 2026-09-23 | AM27: 89.89 | AN27: 87.72 | AO27: =IF(ISNUMBER(AN27),AM27/AN27-1,"") | AP27: 7 | AQ27: =IF(ISNUMBER(AM27),J27/AM27-1,"") | AR27: 96.81 | AS27: =J27/AR27-1 | AT27: 0.4088 | AU27: 0.1061 | AV27: 0.0304 | AW27: =AU27-AV27 | AX27: 0.3027 | AY27: 0.2689 | AZ27: 0.2531 | BA27: 深綠 | BB27: 淺綠→深綠 | BC27: 1 | BD27: 深紅 淺紅 深綠 深綠 深綠 淺綠 深綠 深綠 | BE27: 上傾擴張 | BF27: 0.239 | BG27: 0.003 | BH27: 0.5126 | BI27: 0.4965 | BJ27: 3 | BK27: 97.3 | BL27: 87.72 | BM27: 92.6306 | BN27: 1.0862 | BO27: =IF(M27=N27,0.5,(J27-N27)/(M27-N27)) | BP27: 7.424 | BQ27: 2.383 | BR27: =100*(0.4*MIN(1,MAX(0,((U27*100)-(0.0))/((2.5)-(0.0))))+0.3*MIN(1,MAX(0,((V27)-(0.6))/((1.0)-(0.6))))+0.3*MIN(1,MAX(0,((BP27)-(0.0))/((15.0)-(0.0))))) | BS27: =100*(0.4*MIN(1,MAX(0,((MIN(ABS(AA27),ABS(AB27)))-(0.75))/((0.0)-(0.75))))+0.3*MIN(1,MAX(0,((BN27)-(1.2))/((0.6)-(1.2))))+0.3*BO27) | BT27: =100*(0.5*MIN(1,MAX(0,((AK27)-(1.0))/((4.0)-(1.0))))+0.3*MIN(1,MAX(0,((IF(ISNUMBER(AO27),AO27,0)*100)-(0.0))/((8.0)-(0.0))))+0.2*MIN(1,MAX(0,((IF(ISNUMBER(AP27),AP27,0))-(25.0))/((5.0)-(25.0))))) | BU27: =100*(0.35*MIN(1,MAX(0,((ABS(BF27))-(0.3))/((0.05)-(0.3))))+0.3*MIN(1,MAX(0,((BG27)-(0.0))/((0.3)-(0.0))))+0.25*MIN(1,MAX(0,((BH27)-(0.4))/((0.7)-(0.4))))+0.1*IF(BJ27>=2,1,0.5)) | BV27: =0.25*BR27+0.25*BS27+0.2*BT27+0.3*BU27 | BW27: 全部通過
A28: 2 | B28: 1 | C28: DOCS | D28: Doximity Inc. | E28: NYSE | F28: 科技 | G28: EDP Services | H28: 5.051 | I28: 中型 | J28: 27.93 | K28: 28.5 | L28: =J28/K28-1 | M28: 29.2 | N28: 27.795 | O28: 2672100 | P28: 2977815 | Q28: =O28/P28 | R28: 27.2352 | S28: 26.5334 | T28: 25.8834 | U28: =S28/T28-1 | V28: 1 | W28: =J28/R28-1 | X28: =J28/S28-1 | Y28: 1.2021 | Z28: =Y28/J28 | AA28: =(J28-R28)/Y28 | AB28: =(J28-S28)/Y28 | AC28: =IF(ABS(AA28)<=ABS(AB28),"9EMA","21EMA") | AD28: 9EMA | AE28: 持續在上方 | AH28: ✓ | AI28: 2026-08-07 | AJ28: 39 | AK28: 2 | AL28: 2026-09-28 | AM28: 25.33 | AN28: 23.955 | AO28: =IF(ISNUMBER(AN28),AM28/AN28-1,"") | AP28: 4 | AQ28: =IF(ISNUMBER(AM28),J28/AM28-1,"") | AR28: 28.5 | AS28: =J28/AR28-1 | AT28: 0.7219 | AU28: 0.583 | AV28: 0.5483 | AW28: =AU28-AV28 | AX28: 0.1388 | AY28: 0.1384 | AZ28: 0.0601 | BA28: 深綠 | BB28: 深紅→淺紅 | BC28: 3 | BD28: 淺紅 深紅 深紅 深紅 淺紅 深綠 深綠 深綠 | BE28: 上升三角（平頂） | BF28: 0.0477 | BG28: 0.3787 | BH28: 0.4676 | BI28: 0.5146 | BJ28: 2 | BK28: 29.2 | BL28: 23.955 | BM28: 26.4077 | BN28: 0.8506 | BO28: =IF(M28=N28,0.5,(J28-N28)/(M28-N28)) | BP28: 11.158 | BQ28: 6.117 | BR28: =100*(0.4*MIN(1,MAX(0,((U28*100)-(0.0))/((2.5)-(0.0))))+0.3*MIN(1,MAX(0,((V28)-(0.6))/((1.0)-(0.6))))+0.3*MIN(1,MAX(0,((BP28)-(0.0))/((15.0)-(0.0))))) | BS28: =100*(0.4*MIN(1,MAX(0,((MIN(ABS(AA28),ABS(AB28)))-(0.75))/((0.0)-(0.75))))+0.3*MIN(1,MAX(0,((BN28)-(1.2))/((0.6)-(1.2))))+0.3*BO28) | BT28: =100*(0.5*MIN(1,MAX(0,((AK28)-(1.0))/((4.0)-(1.0))))+0.3*MIN(1,MAX(0,((IF(ISNUMBER(AO28),AO28,0)*100)-(0.0))/((8.0)-(0.0))))+0.2*MIN(1,MAX(0,((IF(ISNUMBER(AP28),AP28,0))-(25.0))/((5.0)-(25.0))))) | BU28: =100*(0.35*MIN(1,MAX(0,((ABS(BF28))-(0.3))/((0.05)-(0.3))))+0.3*MIN(1,MAX(0,((BG28)-(0.0))/((0.3)-(0.0))))+0.25*MIN(1,MAX(0,((BH28)-(0.4))/((0.7)-(0.4))))+0.1*IF(BJ28>=2,1,0.5)) | BV28: =0.25*BR28+0.25*BS28+0.2*BT28+0.3*BU28 | BW28: C4 上升三角／重心偏上
A29: 2 | B29: 2 | C29: HYLN | D29: Hyliion Holdings Corp. | E29: AMEX | F29: 非必需消費 | G29: Construction/Ag Equipment/Trucks | H29: 0.745 | I29: 小型 | J29: 4.53 | K29: 4.21 | L29: =J29/K29-1 | M29: 4.54 | N29: 4.29 | O29: 1955600 | P29: 1928700 | Q29: =O29/P29 | R29: 4.2095 | S29: 4.0725 | T29: 3.9936 | U29: =S29/T29-1 | V29: 0.9 | W29: =J29/R29-1 | X29: =J29/S29-1 | Y29: 0.2938 | Z29: =Y29/J29 | AA29: =(J29-R29)/Y29 | AB29: =(J29-S29)/Y29 | AC29: =IF(ABS(AA29)<=ABS(AB29),"9EMA","21EMA") | AD29: 9+21EMA | AE29: 持續在上方 | AI29: 2026-09-09 | AJ29: 17 | AK29: 4 | AL29: 2026-09-28 | AM29: 3.92 | AN29: 3.62 | AO29: =IF(ISNUMBER(AN29),AM29/AN29-1,"") | AP29: 4 | AQ29: =IF(ISNUMBER(AM29),J29/AM29-1,"") | AR29: 4.53 | AS29: =J29/AR29-1 | AT29: 0.1288 | AU29: 0.1018 | AV29: 0.095 | AW29: =AU29-AV29 | AX29: 0.027 | AY29: 0.0074 | AZ29: 0.0066 | BA29: 深綠 | BB29: 淺綠→深綠 | BC29: 1 | BD29: 淺綠 淺綠 淺綠 淺綠 淺綠 淺綠 深綠 深綠 | BE29: 上傾擴張 | BF29: 1.2952 | BG29: 0.8151 | BH29: 0.5223 | BI29: 0.5198 | BJ29: 1 | BK29: 4.68 | BL29: 3.25 | BM29: 3.997 | BN29: 0.8423 | BO29: =IF(M29=N29,0.5,(J29-N29)/(M29-N29)) | BP29: 32.288 | BQ29: 27.247 | BR29: =100*(0.4*MIN(1,MAX(0,((U29*100)-(0.0))/((2.5)-(0.0))))+0.3*MIN(1,MAX(0,((V29)-(0.6))/((1.0)-(0.6))))+0.3*MIN(1,MAX(0,((BP29)-(0.0))/((15.0)-(0.0))))) | BS29: =100*(0.4*MIN(1,MAX(0,((MIN(ABS(AA29),ABS(AB29)))-(0.75))/((0.0)-(0.75))))+0.3*MIN(1,MAX(0,((BN29)-(1.2))/((0.6)-(1.2))))+0.3*BO29) | BT29: =100*(0.5*MIN(1,MAX(0,((AK29)-(1.0))/((4.0)-(1.0))))+0.3*MIN(1,MAX(0,((IF(ISNUMBER(AO29),AO29,0)*100)-(0.0))/((8.0)-(0.0))))+0.2*MIN(1,MAX(0,((IF(ISNUMBER(AP29),AP29,0))-(25.0))/((5.0)-(25.0))))) | BU29: =100*(0.35*MIN(1,MAX(0,((ABS(BF29))-(0.3))/((0.05)-(0.3))))+0.3*MIN(1,MAX(0,((BG29)-(0.0))/((0.3)-(0.0))))+0.25*MIN(1,MAX(0,((BH29)-(0.4))/((0.7)-(0.4))))+0.1*IF(BJ29>=2,1,0.5)) | BV29: =0.25*BR29+0.25*BS29+0.2*BT29+0.3*BU29 | BW29: C4 上升三角／重心偏上
A30: 2 | B30: 3 | C30: SANM | D30: Sanmina Corporation | E30: NASDAQ | F30: 科技 | G30: Electrical Products | H30: 11.519 | I30: 大型 | J30: 229.04 | K30: 221.96 | L30: =J30/K30-1 | M30: 229.4 | N30: 223.62 | O30: 654800 | P30: 587230 | Q30: =O30/P30 | R30: 219.5123 | S30: 212.4794 | T30: 206.6132 | U30: =S30/T30-1 | V30: 1 | W30: =J30/R30-1 | X30: =J30/S30-1 | Y30: 10.7847 | Z30: =Y30/J30 | AA30: =(J30-R30)/Y30 | AB30: =(J30-S30)/Y30 | AC30: =IF(ABS(AA30)<=ABS(AB30),"9EMA","21EMA") | AD30: 9+21EMA | AE30: 持續在上方 | AI30: 2026-09-21 | AJ30: 9 | AK30: 4 | AL30: 2026-09-15 | AM30: 189.58 | AN30: 182.47 | AO30: =IF(ISNUMBER(AN30),AM30/AN30-1,"") | AP30: 13 | AQ30: =IF(ISNUMBER(AM30),J30/AM30-1,"") | AR30: 229.04 | AS30: =J30/AR30-1 | AT30: 6.3917 | AU30: 4.518 | AV30: 4.0496 | AW30: =AU30-AV30 | AX30: 1.8737 | AY30: 1.657 | AZ30: 1.8347 | BA30: 深綠 | BB30: 淺綠→深綠 | BC30: 0 | BD30: 深綠 深綠 深綠 淺綠 淺綠 淺綠 淺綠 深綠 | BE30: 上傾擴張 | BF30: 0.5833 | BG30: 0.388 | BH30: 0.4956 | BI30: 0.4783 | BJ30: 2 | BK30: 232.5 | BL30: 182.47 | BM30: 207.2625 | BN30: 0.921 | BO30: =IF(M30=N30,0.5,(J30-N30)/(M30-N30)) | BP30: 27.085 | BQ30: 22.044 | BR30: =100*(0.4*MIN(1,MAX(0,((U30*100)-(0.0))/((2.5)-(0.0))))+0.3*MIN(1,MAX(0,((V30)-(0.6))/((1.0)-(0.6))))+0.3*MIN(1,MAX(0,((BP30)-(0.0))/((15.0)-(0.0))))) | BS30: =100*(0.4*MIN(1,MAX(0,((MIN(ABS(AA30),ABS(AB30)))-(0.75))/((0.0)-(0.75))))+0.3*MIN(1,MAX(0,((BN30)-(1.2))/((0.6)-(1.2))))+0.3*BO30) | BT30: =100*(0.5*MIN(1,MAX(0,((AK30)-(1.0))/((4.0)-(1.0))))+0.3*MIN(1,MAX(0,((IF(ISNUMBER(AO30),AO30,0)*100)-(0.0))/((8.0)-(0.0))))+0.2*MIN(1,MAX(0,((IF(ISNUMBER(AP30),AP30,0))-(25.0))/((5.0)-(25.0))))) | BU30: =100*(0.35*MIN(1,MAX(0,((ABS(BF30))-(0.3))/((0.05)-(0.3))))+0.3*MIN(1,MAX(0,((BG30)-(0.0))/((0.3)-(0.0))))+0.25*MIN(1,MAX(0,((BH30)-(0.4))/((0.7)-(0.4))))+0.1*IF(BJ30>=2,1,0.5)) | BV30: =0.25*BR30+0.25*BS30+0.2*BT30+0.3*BU30 | BW30: C4 上升三角／重心偏上
A31: 2 | B31: 4 | C31: TTMI | D31: TTM Technologies Inc. | E31: NASDAQ | F31: 科技 | G31: Electrical Products | H31: 12.941 | I31: 大型 | J31: 131.87 | K31: 126.5 | L31: =J31/K31-1 | M31: 134.57 | N31: 127.32 | O31: 1609600 | P31: 1893870 | Q31: =O31/P31 | R31: 125.7196 | S31: 123.9692 | T31: 122.7188 | U31: =S31/T31-1 | V31: 0.8 | W31: =J31/R31-1 | X31: =J31/S31-1 | Y31: 7.7543 | Z31: =Y31/J31 | AA31: =(J31-R31)/Y31 | AB31: =(J31-S31)/Y31 | AC31: =IF(ABS(AA31)<=ABS(AB31),"9EMA","21EMA") | AD31: 9+21EMA | AE31: 持續在上方 | AI31: 2026-09-23 | AJ31: 7 | AK31: 5 | AL31: 2026-09-28 | AM31: 119.02 | AN31: 109.94 | AO31: =IF(ISNUMBER(AN31),AM31/AN31-1,"") | AP31: 4 | AQ31: =IF(ISNUMBER(AM31),J31/AM31-1,"") | AR31: 131.87 | AS31: =J31/AR31-1 | AT31: 0.8416 | AU31: -0.4241 | AV31: -0.7405 | AW31: =AU31-AV31 | AX31: 1.2657 | AY31: 0.9462 | AZ31: 0.9148 | BA31: 深綠 | BB31: 淺綠→深綠 | BC31: 1 | BD31: 深綠 深綠 深綠 淺綠 淺綠 淺綠 深綠 深綠 | BE31: 對稱三角 | BF31: -0.1429 | BG31: 0.4645 | BH31: 0.499 | BI31: 0.4928 | BJ31: 2 | BK31: 134.57 | BL31: 109.53 | BM31: 122.0252 | BN31: 0.8762 | BO31: =IF(M31=N31,0.5,(J31-N31)/(M31-N31)) | BP31: 19.115 | BQ31: 14.074 | BR31: =100*(0.4*MIN(1,MAX(0,((U31*100)-(0.0))/((2.5)-(0.0))))+0.3*MIN(1,MAX(0,((V31)-(0.6))/((1.0)-(0.6))))+0.3*MIN(1,MAX(0,((BP31)-(0.0))/((15.0)-(0.0))))) | BS31: =100*(0.4*MIN(1,MAX(0,((MIN(ABS(AA31),ABS(AB31)))-(0.75))/((0.0)-(0.75))))+0.3*MIN(1,MAX(0,((BN31)-(1.2))/((0.6)-(1.2))))+0.3*BO31) | BT31: =100*(0.5*MIN(1,MAX(0,((AK31)-(1.0))/((4.0)-(1.0))))+0.3*MIN(1,MAX(0,((IF(ISNUMBER(AO31),AO31,0)*100)-(0.0))/((8.0)-(0.0))))+0.2*MIN(1,MAX(0,((IF(ISNUMBER(AP31),AP31,0))-(25.0))/((5.0)-(25.0))))) | BU31: =100*(0.35*MIN(1,MAX(0,((ABS(BF31))-(0.3))/((0.05)-(0.3))))+0.3*MIN(1,MAX(0,((BG31)-(0.0))/((0.3)-(0.0))))+0.25*MIN(1,MAX(0,((BH31)-(0.4))/((0.7)-(0.4))))+0.1*IF(BJ31>=2,1,0.5)) | BV31: =0.25*BR31+0.25*BS31+0.2*BT31+0.3*BU31 | BW31: C4 上升三角／重心偏上
A32: 2 | B32: 5 | C32: ALMR | D32: Alamar Biosciences Inc. | E32: NASDAQ | F32: 工業 | G32: Biotechnology: Laboratory Analytical Instruments | H32: 2.364 | I32: 中型 | J32: 34.36 | K32: 32.46 | L32: =J32/K32-1 | M32: 34.62 | N32: 32.8 | O32: 339900 | P32: 507400 | Q32: =O32/P32 | R32: 33.0398 | S32: 32.1974 | T32: 31.5282 | U32: =S32/T32-1 | V32: 1 | W32: =J32/R32-1 | X32: =J32/S32-1 | Y32: 2.1941 | Z32: =Y32/J32 | AA32: =(J32-R32)/Y32 | AB32: =(J32-S32)/Y32 | AC32: =IF(ABS(AA32)<=ABS(AB32),"9EMA","21EMA") | AD32: 9EMA | AE32: 持續在上方 | AI32: 2026-09-18 | AJ32: 10 | AK32: 2 | AL32: 2026-09-24 | AM32: 31.68 | AN32: 27.25 | AO32: =IF(ISNUMBER(AN32),AM32/AN32-1,"") | AP32: 6 | AQ32: =IF(ISNUMBER(AM32),J32/AM32-1,"") | AR32: 35.05 | AS32: =J32/AR32-1 | AT32: 0.869 | AU32: 0.7185 | AV32: 0.6808 | AW32: =AU32-AV32 | AX32: 0.1506 | AY32: 0.0974 | AZ32: 0.1879 | BA32: 深綠 | BB32: 淺綠→深綠 | BC32: 0 | BD32: 淺綠 淺綠 淺綠 淺綠 淺綠 深綠 淺綠 深綠 | BE32: 上升通道 | BF32: 0.5462 | BG32: 0.4602 | BH32: 0.4706 | BI32: 0.608 | BJ32: 1 | BK32: 37.76 | BL32: 27.25 | BM32: 32.1964 | BN32: 0.5157 | BO32: =IF(M32=N32,0.5,(J32-N32)/(M32-N32)) | BP32: 17.734 | BQ32: 12.693 | BR32: =100*(0.4*MIN(1,MAX(0,((U32*100)-(0.0))/((2.5)-(0.0))))+0.3*MIN(1,MAX(0,((V32)-(0.6))/((1.0)-(0.6))))+0.3*MIN(1,MAX(0,((BP32)-(0.0))/((15.0)-(0.0))))) | BS32: =100*(0.4*MIN(1,MAX(0,((MIN(ABS(AA32),ABS(AB32)))-(0.75))/((0.0)-(0.75))))+0.3*MIN(1,MAX(0,((BN32)-(1.2))/((0.6)-(1.2))))+0.3*BO32) | BT32: =100*(0.5*MIN(1,MAX(0,((AK32)-(1.0))/((4.0)-(1.0))))+0.3*MIN(1,MAX(0,((IF(ISNUMBER(AO32),AO32,0)*100)-(0.0))/((8.0)-(0.0))))+0.2*MIN(1,MAX(0,((IF(ISNUMBER(AP32),AP32,0))-(25.0))/((5.0)-(25.0))))) | BU32: =100*(0.35*MIN(1,MAX(0,((ABS(BF32))-(0.3))/((0.05)-(0.3))))+0.3*MIN(1,MAX(0,((BG32)-(0.0))/((0.3)-(0.0))))+0.25*MIN(1,MAX(0,((BH32)-(0.4))/((0.7)-(0.4))))+0.1*IF(BJ32>=2,1,0.5)) | BV32: =0.25*BR32+0.25*BS32+0.2*BT32+0.3*BU32 | BW32: C4 上升三角／重心偏上
